Workbook
Name A: #REF!
Name Button_1: "FAX_COVER_SHEET_COMPANIES_List"
Name Excel_BuiltIn_Database: #REF!
Name Excel_BuiltIn_Print_Area: #REF!
Name fe: #REF!
Name m: #REF!
Name n: #REF!
Name Print_Area_MI: #REF!
Name vijay: '[1]AXIS 9-18 MS'!$B$306
Name XCBa: #REF!

Sheet Dashboard
A1: Budget Dashboard - Project # - Week #
A5: Revision Date: | B5: =TODAY() -> 46044 | D5: Baseline Cost | E5: =Budget!D43 -> 1.0468431e+08 | J5: Current Cost | L5: =Budget!D44 -> 1.006261e+08 | U5: Remaining/Overrun Cost | Z5: =Budget!D45 -> -4058205.9
A126: Row Labels | B126: Sum of Saving Amount
A127: 8 | B127: 479225.96
A128: 16 | B128: 398136.06
A129: 20 | B129: 317154.67
A130: 12 | B130: 238683.36
A131: 10 | B131: 83423.184
A132: Grand Total | B132: 1516623.2
A136: Row Labels | B136: Sum of Basic Rate Amount | C136: Sum of Purchase Rate Amount
A137: 1st Purchase | B137: 336000 | C137: 321093.9
A138: 2nd Purchase | B138: 196000 | C138: 177734.55
A139: 3rd Purchase | B139: 392000 | C139: 335169.45
A140: 4th Purchase | B140: 336000 | C140: 277118.7
A141: Grand Total | B141: 1260000 | C141: 1111116.6

Sheet Tracking
A1: Revised on - 16-02-2023 | B1: Project Budget with Cash-Flow
A2: Month | B2: 45931 | C2: 45962 | D2: 45992 | E2: 46023 | F2: 46054 | G2: 46082 | H2: 46113 | I2: 46143 | J2: 46174 | K2: 46204 | L2: 46235 | M2: 46266 | N2: 46296 | O2: 46327 | P2: 46357 | Q2: 46388 | R2: 46419 | S2: 46447 | T2: 46478 | U2: 46508
A3: Planned Budget (EXCLUDING GST) | B3: ='Cash Flow - Forecast'!F26 -> 6485619.2 | C3: ='Cash Flow - Forecast'!G26 -> 8564401.2 | D3: ='Cash Flow - Forecast'!H26 -> 5975619.2 | E3: ='Cash Flow - Forecast'!I26 -> 5975619.2 | F3: ='Cash Flow - Forecast'!J26 -> 5975619.2 | G3: ='Cash Flow - Forecast'!K26 -> 5975619.2 | H3: ='Cash Flow - Forecast'!L26 -> 5975619.2 | I3: ='Cash Flow - Forecast'!M26 -> 5975619.2 | ... R3: ='Cash Flow - Forecast'!V26 -> 5975619.2
A4: YY | B4: Work Done - Cost Status
A5: Prgress Percentage(As per Schedule) | B5: 0.9 | C5: 0.9 | D5: 1 | E5: 0.9 | F5: =F24/F3 -> 0 | G5: =G24/G3 -> 0 | H5: =H24/H3 -> 0 | I5: =I24/I3 -> 0 | J5: =J24/J3 -> 0 | K5: =K24/K3 -> 0 | L5: =L24/L3 -> 0 | M5: =M24/M3 -> 0 | ... U5: =U24/U3 -> #DIV/0!
A6: Work Description | B6: MONTH
B7: 45931 | C7: 45962 | D7: 45992 | E7: 46023 | F7: 46054 | G7: 46082 | H7: 46113 | I7: 46143 | J7: 46174 | K7: 46204 | L7: 46235 | M7: 46266 | N7: 46296 | O7: 46327 | P7: 46357 | Q7: 46388 | R7: 46419 | S7: 46447 | T7: 46478 | U7: 46508
A8: Project Development Consultancy | B8: 100000 | C8: 100000 | D8: 100000 | E8: 100000
A9: Civil Works | B9: 3000000 | C9: 3000000 | D9: 3000000 | E9: 3000000
A10: Anti Termite Service | B10: =E66 -> 0 | C10: 35532 | D10: =E68 -> 0 | E10: =F68 -> 0
A11: Road development | B11: =E75 -> 0 | C11: =E76 -> 0 | D11: 200000 | E11: 200000
A12: Borewell | B12: =E76 -> 0 | C12: 1000000 | D12: =E70 -> 0 | E12: =F70 -> 0
A13: External Electrification ( power connection cost ) | B13: 300000 | C13: 200000 | D13: 200000 | E13: 200000
A14: Temporary Power Connection | B14: 0 | C14: 0 | D14: 0 | E14: 0
A15: UG Tank | B15: 50000 | C15: 100000 | D15: 100000 | E15: 100000
A16: External Drainage network & STP | B16: 50000 | C16: 100000 | D16: 100000 | E16: 100000
A17: Soil filling (within Plot area) | B17: 1000000 | C17: 1000000 | D17: 63250 | E17: 0
A18: Compound wall (Precast) | B18: 0 | C18: 50000 | D18: 80000 | E18: 80000
A19: Electrical Package | B19: 300000 | C19: 300000 | D19: 300000 | E19: 300000
A20: Plumbing Package | B20: 500000 | C20: 500000 | D20: 500000 | E20: 500000
A21: Furniture Package | B21: 300000 | C21: 300000 | D21: 300000 | E21: 300000
A22: Aluminum Package | B22: 50000 | C22: 50000 | D22: 50000 | E22: 50000
A23: Fire Package | B23: 10000 | C23: 10000 | D23: 10000 | E23: 10000
A24: Actual Work Done (EXCLUDING GST) | B24: =SUM(B8:B22) -> 5650000 | C24: =SUM(C8:C22) -> 6735532 | D24: =SUM(D8:D22) -> 4993250 | E24: =SUM(E8:E22) -> 4930000 | F24: =SUM(F8:F22) -> 0 | G24: =SUM(G8:G22) -> 0 | H24: =SUM(H8:H22) -> 0 | I24: =SUM(I8:I22) -> 0 | ... U24: =SUM(U8:U22) -> 0
A25: Earned Value | B25: =B3*B5 -> 5837057.3 | C25: =C3*C5 -> 7707961.1 | D25: =D3*D5 -> 5975619.2 | E25: =E3*E5 -> 5378057.3 | F25: =F3*F5 -> 0 | G25: =G3*G5 -> 0 | H25: =H3*H5 -> 0 | I25: =I3*I5 -> 0 | ... U25: =U3*U5 -> #DIV/0!
A26: CPI | B26: =B25/B24 -> 1.0331075 | C26: =C25/C24 -> 1.144373 | D26: =D25/D24 -> 1.1967394 | E26: =E25/E24 -> 1.0908838 | V26: =AVERAGE(B26:U26) -> 1.1162759
A27: XX - YY | B27: Difference (Planned Vs Actual)
A28: Month | B28: 45931 | C28: 45962 | D28: 45992 | E28: 46023 | F28: 46054 | G28: 46082 | H28: 46113 | I28: 46143 | J28: 46174 | K28: 46204 | L28: 46235 | M28: 46266 | N28: 46296 | O28: 46327 | P28: 46357 | Q28: 46388 | R28: 46419 | S28: 46447 | T28: 46478 | U28: 46508
A29: Difference | B29: =B3-B24 -> 835619.23 | C29: =C3-C24 -> 1828869.2 | D29: =D3-D24 -> 982369.23 | E29: =E3-E24 -> 1045619.2 | F29: =F3-F24 -> 5975619.2 | G29: =G3-G24 -> 5975619.2 | H29: =H3-H24 -> 5975619.2 | I29: =I3-I24 -> 5975619.2
A31: Invoice Month | B31: Civil Construction Works
B32: RA BILL | F32: Deduction | I32: Hold | K32: Taxes | M32: COP for Amount
B33: Vendor | C33: RA Bill | D33: Type of Work | E33: Work Done Amount | F33: Retention (5%/10% of work done cost) | G33: Advance (6.25% on Prorata basis) | H33: Others | I33: Amount | J33: Release | K33: SGST@9% | L33: CGST@9%
A34: 45931 | B34: M/S Bhavna Infra | C34: ADVANCE | D34: Mobilization | E34: =B9 -> 3000000 | F34: =E34*5% -> 150000 | G34: 0 | H34: 0 | I34: 0 | J34: 0 | K34: =E34*9% -> 270000 | L34: =E34*9% -> 270000 | M34: =E34-F34-G34-H34-I34+J34+K34+L34 -> 3390000
A35: 45962 | B35: M/S Bhavna Infra | C35: RA 01 | D35: Dormatory | E35: =C9 -> 3000000 | F35: =E35*5% -> 150000 | G35: =E34*6.25% -> 187500 | H35: 0 | I35: 0 | J35: 0 | K35: =E35*9% -> 270000 | L35: =E35*9% -> 270000 | M35: =E35-F35-G35-H35-I35+J35+K35+L35 -> 3202500
A36: 45992 | B36: M/S Bhavna Infra | C36: RA 02 | D36: KB-02 Works | E36: =D9 -> 3000000 | F36: =E36*5% -> 150000 | G36: =E35*6.25% -> 187500 | H36: 0 | I36: 0 | J36: 0 | K36: =E36*9% -> 270000 | L36: =E36*9% -> 270000 | M36: =E36-F36-G36-H36-I36+J36+K36+L36 -> 3202500
A37: 46023 | B37: M/S Bhavna Infra | C37: RA 03 | D37: Temporary Road and Culvert Works | E37: =E9 -> 3000000 | F37: =E37*5% -> 150000 | G37: =E36*6.25% -> 187500 | H37: 0 | I37: 0 | J37: 0 | K37: =E37*9% -> 270000 | L37: =E37*9% -> 270000 | M37: =E37-F37-G37-H37-I37+J37+K37+L37 -> 3202500
A38: 46054
A39: 46082
A40: 46113
A41: 46143
...

Sheet Cash Flow Chart - INR
A2: Month | B2: 45931 | C2: 45962 | D2: 45992 | E2: 46023 | F2: 46054 | G2: 46082 | H2: 46113 | I2: 46143 | J2: 46174 | K2: 46204 | L2: 46235 | M2: 46266 | N2: 46296 | O2: 46327 | P2: 46357 | Q2: 46388 | R2: 46419 | S2: Total
A3: Planned Budget (EXCLUDING GST) | B3: =Tracking!B3 -> 6485619.2 | C3: =Tracking!C3 -> 8564401.2 | D3: =Tracking!D3 -> 5975619.2 | E3: =Tracking!E3 -> 5975619.2 | F3: =Tracking!F3 -> 5975619.2 | G3: =Tracking!G3 -> 5975619.2 | H3: =Tracking!H3 -> 5975619.2 | I3: =Tracking!I3 -> 5975619.2 | ... R3: =Tracking!R3 -> 5975619.2 | S3: =SUM(B3:R3) -> 1.0468431e+08
A4: Planned Budget (EXCLUDING GST) Cumulative | C4: =B3+C3 -> 15050020 | D4: =C4+D3 -> 21025640 | E4: =D4+E3 -> 27001259 | F4: =E4+F3 -> 32976878 | G4: =F4+G3 -> 38952497 | H4: =G4+H3 -> 44928117 | I4: =H4+I3 -> 50903736 | J4: =I4+J3 -> 56879355 | K4: =J4+K3 -> 62854974 | ... R4: =Q4+R3 -> 1.0468431e+08
A5: Actual Work Done (EXCLUDING GST) | B5: =Tracking!B24 -> 5650000 | C5: =Tracking!C24 -> 6735532 | D5: =Tracking!D24 -> 4993250 | E5: =Tracking!E24 -> 4930000 | F5: =Tracking!F24 -> 0 | G5: =Tracking!G24 -> 0 | H5: =Tracking!H24 -> 0 | I5: =Tracking!I24 -> 0 | J5: =Tracking!J24 -> 0 | K5: =Tracking!L24 -> 0 | L5: =Tracking!M24 -> 0 | M5: =Tracking!N24 -> 0 | N5: =Tracking!O24 -> 0 | O5: =Tracking!P24 -> 0 | P5: =Tracking!Q24 -> 0 | Q5: =Tracking!R24 -> 0 | R5: =Tracking!S24 -> 0 | S5: =SUM(B5:R5) -> 22308782
A6: Actual Work Done (EXCLUDING GST) Cumulative | C6: =B5+C5 -> 12385532 | D6: =C6+D5 -> 17378782 | E6: =D6+E5 -> 22308782 | S6: =SUM(B6:R6) -> 52073096
H7: =H4-H6 -> 44928117

Sheet Cash Flow - Forecast
B6: TENTATIVE CASH FLOW IN (INR)
E7: Q3-2022 | F7: Q4-2025 | I7: Q1-2026 | L7: Q2-2026 | O7: Q3-2026 | R7: Q4-2026 | U7: Q1-2027
B8: Sr. No. | C8: Structure | E8: 44805 | F8: 45931 | G8: 45962 | H8: 45992 | I8: 46023 | J8: 46054 | K8: 46082 | L8: 46113 | M8: 46143 | N8: 46174 | O8: 46204 | P8: 46235 | Q8: 46266 | R8: 46296 | S8: 46327 | T8: 46357 | U8: 46388 | V8: 46419 | W8: 45373 | X8: Total
Y9: =D9-X9 -> 0
B10: 1 | C10: Project Development Consultancy | D10: =Budget!E8 -> 2400000 | F10: =$D$10/17 -> 141176.47 | G10: =$D$10/17 -> 141176.47 | H10: =$D$10/17 -> 141176.47 | I10: =$D$10/17 -> 141176.47 | J10: =$D$10/17 -> 141176.47 | K10: =$D$10/17 -> 141176.47 | L10: =$D$10/17 -> 141176.47 | M10: =$D$10/17 -> 141176.47 | ... V10: =$D$10/17 -> 141176.47 | X10: =SUM(F10:V10) -> 2400000
B11: 2 | C11: Civil Works | D11: =Budget!E12 -> 57100727 | F11: =$D11/17 -> 3358866.3 | G11: =$D11/17 -> 3358866.3 | H11: =$D11/17 -> 3358866.3 | I11: =$D11/17 -> 3358866.3 | J11: =$D11/17 -> 3358866.3 | K11: =$D11/17 -> 3358866.3 | L11: =$D11/17 -> 3358866.3 | M11: =$D11/17 -> 3358866.3 | ... W11: =$D11/17 -> 3358866.3 | X11: =SUM(F11:V11) -> 57100727 | Y11: =D11-X11 -> 0
B12: =B11+1 -> 3 | C12: Anti Termite Service | D12: =Budget!E13 -> 35532 | F12: 10000 | G12: 25532 | W12: =$D12/17 -> 2090.1176 | X12: =SUM(F12:V12) -> 35532 | Y12: =D12-X12 -> 0
B13: =B12+1 -> 4 | C13: Road development | D13: =Budget!E14 -> 3600000 | F13: =$D13/17 -> 211764.71 | G13: =$D13/17 -> 211764.71 | H13: =$D13/17 -> 211764.71 | I13: =$D13/17 -> 211764.71 | J13: =$D13/17 -> 211764.71 | K13: =$D13/17 -> 211764.71 | L13: =$D13/17 -> 211764.71 | M13: =$D13/17 -> 211764.71 | ... W13: =$D13/17 -> 211764.71 | X13: =SUM(F13:V13) -> 3600000 | Y13: =D13-X13 -> 0
B14: 3 | C14: Borewell | D14: =Budget!E15 -> 1000000 | F14: 500000 | G14: 500000 | W14: =$D14/17 -> 58823.529 | X14: =SUM(F14:V14) -> 1000000
B15: 4 | C15: External Electrification ( power connection cost ) | D15: =Budget!E16 -> 5000000 | F15: =$D15/17 -> 294117.65 | G15: =$D15/17 -> 294117.65 | H15: =$D15/17 -> 294117.65 | I15: =$D15/17 -> 294117.65 | J15: =$D15/17 -> 294117.65 | K15: =$D15/17 -> 294117.65 | L15: =$D15/17 -> 294117.65 | M15: =$D15/17 -> 294117.65 | ... W15: =$D15/17 -> 294117.65 | X15: =SUM(F15:V15) -> 5000000
B16: =B15+1 -> 5 | C16: Temporary Power Connection | D16: =Budget!E17 -> 0 | F16: =$D16/17 -> 0 | G16: =$D16/17 -> 0 | H16: =$D16/17 -> 0 | I16: =$D16/17 -> 0 | J16: =$D16/17 -> 0 | K16: =$D16/17 -> 0 | L16: =$D16/17 -> 0 | M16: =$D16/17 -> 0 | ... W16: =$D16/17 -> 0 | X16: =SUM(F16:V16) -> 0
B17: =B16+1 -> 6 | C17: UG Tank | D17: =Budget!E18 -> 6000000 | F17: =$D17/17 -> 352941.18 | G17: =$D17/17 -> 352941.18 | H17: =$D17/17 -> 352941.18 | I17: =$D17/17 -> 352941.18 | J17: =$D17/17 -> 352941.18 | K17: =$D17/17 -> 352941.18 | L17: =$D17/17 -> 352941.18 | M17: =$D17/17 -> 352941.18 | ... W17: =$D17/17 -> 352941.18 | X17: =SUM(F17:V17) -> 6000000
B18: 5 | C18: External Drainage network & STP | D18: =Budget!E19 -> 5000000 | F18: =$D18/17 -> 294117.65 | G18: =$D18/17 -> 294117.65 | H18: =$D18/17 -> 294117.65 | I18: =$D18/17 -> 294117.65 | J18: =$D18/17 -> 294117.65 | K18: =$D18/17 -> 294117.65 | L18: =$D18/17 -> 294117.65 | M18: =$D18/17 -> 294117.65 | ... W18: =$D18/17 -> 294117.65 | X18: =SUM(F18:V18) -> 5000000
B19: 6 | C19: Soil filling (within Plot area) | D19: =Budget!E20 -> 2063250 | F19: 0 | G19: 2063250 | W19: =$D19/17 -> 121367.65 | X19: =SUM(F19:V19) -> 2063250
B20: =B19+1 -> 7 | C20: Compound wall (Precast) | D20: =Budget!E21 -> 1449000 | F20: =$D20/17 -> 85235.294 | G20: =$D20/17 -> 85235.294 | H20: =$D20/17 -> 85235.294 | I20: =$D20/17 -> 85235.294 | J20: =$D20/17 -> 85235.294 | K20: =$D20/17 -> 85235.294 | L20: =$D20/17 -> 85235.294 | M20: =$D20/17 -> 85235.294 | ... W20: =$D20/17 -> 85235.294 | X20: =SUM(F20:V20) -> 1449000
B21: =B20+1 -> 8 | C21: Electrical Package | D21: =Budget!E22 -> 5258950 | F21: =$D21/17 -> 309350 | G21: =$D21/17 -> 309350 | H21: =$D21/17 -> 309350 | I21: =$D21/17 -> 309350 | J21: =$D21/17 -> 309350 | K21: =$D21/17 -> 309350 | L21: =$D21/17 -> 309350 | M21: =$D21/17 -> 309350 | ... W21: =$D21/17 -> 309350 | X21: =SUM(F21:V21) -> 5258950
B22: 7 | C22: Plumbing Package | D22: =Budget!E23 -> 5258950 | F22: =$D22/17 -> 309350 | G22: =$D22/17 -> 309350 | H22: =$D22/17 -> 309350 | I22: =$D22/17 -> 309350 | J22: =$D22/17 -> 309350 | K22: =$D22/17 -> 309350 | L22: =$D22/17 -> 309350 | M22: =$D22/17 -> 309350 | ... W22: =$D22/17 -> 309350 | X22: =SUM(F22:V22) -> 5258950
B23: 8 | C23: Furniture Package | D23: =Budget!E24 -> 9146000 | F23: =$D23/17 -> 538000 | G23: =$D23/17 -> 538000 | H23: =$D23/17 -> 538000 | I23: =$D23/17 -> 538000 | J23: =$D23/17 -> 538000 | K23: =$D23/17 -> 538000 | L23: =$D23/17 -> 538000 | M23: =$D23/17 -> 538000 | ... W23: =$D23/17 -> 538000 | X23: =SUM(F23:V23) -> 9146000
B24: =B23+1 -> 9 | C24: Aluminum Package | D24: =Budget!E25 -> 1143250 | F24: =$D24/17 -> 67250 | G24: =$D24/17 -> 67250 | H24: =$D24/17 -> 67250 | I24: =$D24/17 -> 67250 | J24: =$D24/17 -> 67250 | K24: =$D24/17 -> 67250 | L24: =$D24/17 -> 67250 | M24: =$D24/17 -> 67250 | ... W24: =$D24/17 -> 67250 | X24: =SUM(F24:V24) -> 1143250
B25: =B24+1 -> 10 | C25: Fire Package | D25: =Budget!E26 -> 228650 | F25: =$D25/17 -> 13450 | G25: =$D25/17 -> 13450 | H25: =$D25/17 -> 13450 | I25: =$D25/17 -> 13450 | J25: =$D25/17 -> 13450 | K25: =$D25/17 -> 13450 | L25: =$D25/17 -> 13450 | M25: =$D25/17 -> 13450 | ... W25: =$D25/17 -> 13450 | X25: =SUM(F25:V25) -> 228650
B26: AMOUNT IN INR | D26: =SUM(D9:D25) -> 1.0468431e+08 | E26: 0 | F26: =SUM(F9:F25) -> 6485619.2 | G26: =SUM(G9:G25) -> 8564401.2 | H26: =SUM(H9:H25) -> 5975619.2 | I26: =SUM(I9:I25) -> 5975619.2 | J26: =SUM(J9:J25) -> 5975619.2 | K26: =SUM(K9:K25) -> 5975619.2 | L26: =SUM(L9:L25) -> 5975619.2 | M26: =SUM(M9:M25) -> 5975619.2 | ... V26: =SUM(V9:V25) -> 5975619.2 | X26: =SUM(F26:W26) -> 1.0468431e+08 | Y26: =SUM(F26:W26) -> 1.0468431e+08
C27: Note: Above amounts are excluding of contingency
C28: =#REF! -> #REF!
E36: 790000000
E37: 549000000

Sheet Budget
B5: Budget WBS | E5: Budgeted Amount | F5: Work Order Amount | G5: Certifed Amount | H5: FORECASTED / NON TENDERED ITEMS | K5: Basic Rate Diffrence ( BRD ) | O5: Total
B6: Sr No | C6: Description | D6: Name of Stackholder | E6: Amount | F6: Actual WO Amount (Basic ) | G6: Certified Amount ( Basic ) | H6: Fore Casted ( Based on GFC ) | J6: Non Tendered Items | K6: Steel ( Till Date ) | M6: Cement ( Till Date ) | O6: Gross Total Amount ( Projected )
H7: Addition | I7: Reduction | K7: Excess | L7: Saving | M7: Excess | N7: Saving
B8: 1 | C8: Project Development Consultancy | D8: SPDC | E8: 2400000 | F8: =215000*8 -> 1720000 | G8: 722795.1 | H8: 0 | I8: 0 | J8: 0 | O8: =+F8+H8-I8+J8+K8-L8+M8-N8 -> 1720000
B9: 2 | C9: Project Consultant | D9: AK Consultant | F9: 740000 | G9: 250000 | H9: 0 | I9: 0 | J9: 0 | O9: =+F9+H9-I9+J9+K9-L9+M9-N9 -> 740000
B10: 2.1 | C10: Project Consultant | D10: Vishwas Patel | F10: 750000 | G10: 750000 | H10: 0 | I10: 0 | J10: 0 | O10: =+F10+H10-I10+J10+K10-L10+M10-N10 -> 750000
B11: 3 | C11: Project Package | O11: =+F11+H11-I11+J11+K11-L11+M11-N11 -> 0
B12: 3.1 | C12: Construction cost for Dormitory blocks | D12: M/s Bhavna Infra | E12: 57100727 | F12: 57673579 | G12: =14557976+2592839+2639623+693242 -> 20483680 | H12: =[2]Monitoring!P72 -> 5521220.2 | I12: =+[2]Monitoring!Q72 -> 13474471 | J12: =+[2]Monitoring!M72 -> 1592674.5 | K12: ='[2]STEEL RATE DIFFRENCE'!K39 -> 0 | L12: ='[2]STEEL RATE DIFFRENCE'!L39 -> 1516623.2 | M12: ='[2]CEMENT RATE DIFFRENCE'!J10 -> 0 | N12: ='[2]CEMENT RATE DIFFRENCE'!K10 -> 148883.4 | O12: =+F12+H12-I12+J12+K12-L12+M12-N12 -> 49647496
B13: 3.1.1 | C13: Anti-termite service | D13: M/s Surti Pest-Control | E13: 35532 | F13: 35532 | O13: =+F13+H13-I13+J13+K13-L13+M13-N13 -> 35532
B14: 3.2 | C14: Road development | E14: 3600000 | G14: 0 | H14: 0 | I14: 0 | J14: 0 | O14: 3600000
B15: 3.3 | C15: Borewell | E15: 1000000 | F15: 1790460 | G15: 895230 | H15: 0 | I15: 0 | J15: 0 | O15: =+F15+H15-I15+J15+K15-L15+M15-N15 -> 1790460
B16: 3.4 | C16: External Electrification ( power connection cost ) | E16: 5000000 | G16: 0 | H16: 0 | I16: 0 | J16: 0 | O16: 4649950
B17: 3.4.1 | C17: Temporary Power Connection | D17: M/s. Indian Electricals | F17: 350050 | G17: 333900 | H17: 0 | I17: 0 | J17: 0 | O17: =+F17+H17-I17+J17+K17-L17+M17-N17 -> 350050
B18: 3.5 | C18: UG Tank | E18: 6000000 | G18: 0 | H18: 0 | I18: 0 | J18: 0 | O18: 6000000
B19: 3.6 | C19: External Drainage network & STP | E19: 5000000 | G19: 0 | H19: 0 | I19: 0 | J19: 0 | O19: 5000000
B20: 3.7 | C20: Soil filling (within Plot area) | E20: 2063250 | G20: 0 | H20: 0 | I20: 0 | J20: 0 | O20: 2063250
B21: 3.8 | C21: Compound wall (Precast) | E21: 1449000 | G21: 0 | H21: 0 | I21: 0 | J21: 0 | O21: 1449000
B22: 4 | C22: Electrical Package | D22: Pearl Electricals | E22: 5258950 | F22: 7053515 | G22: 0 | H22: 0 | I22: 0 | J22: 0 | O22: =+F22+H22-I22+J22+K22-L22+M22-N22 -> 7053515
B23: 5 | C23: Plumbing Package | E23: 5258950 | G23: 0 | H23: 0 | I23: 0 | J23: 0 | O23: 5258950
B24: 6 | C24: Furniture Package | E24: 9146000 | G24: 0 | H24: 0 | I24: 0 | J24: 0 | O24: 9146000
B25: 7 | C25: Aluminum Package | E25: 1143250 | G25: 0 | H25: 0 | I25: 0 | J25: 0 | O25: 1143250
B26: 8 | C26: Fire Package | E26: 228650 | G26: 0 | H26: 0 | I26: 0 | J26: 0 | O26: 228650
B27: Total Net Project Cost : | E27: =SUM(E8:E26) -> 1.0468431e+08 | F27: =SUM(F8:F26) -> 70113136 | G27: =SUM(G8:G26) -> 23435605 | H27: =SUM(H8:H26) -> 5521220.2 | I27: =SUM(I8:I26) -> 13474471 | J27: =SUM(J8:J26) -> 1592674.5 | K27: =SUM(K8:K26) -> 0 | L27: =SUM(L8:L26) -> 1516623.2 | ... O27: =SUM(O8:O26) -> 1.006261e+08
B28: GST 18 % : | E28: =+E27*18% -> 18843176 | F28: =+F27*18% -> 12620364 | G28: =+G27*18% -> 4218408.9 | H28: =+H27*18% -> 993819.63 | I28: =+I27*18% -> 2425404.8 | J28: =+J27*18% -> 286681.4 | K28: =+K27*18% -> 0 | L28: =+L27*18% -> 272992.18 | ... O28: =+O27*18% -> 18112699
B29: Total Project Cost : | E29: =+E27+E28 -> 1.2352748e+08 | F29: =+F27+F28 -> 82733500 | G29: =+G27+G28 -> 27654014 | H29: =+H27+H28 -> 6515039.8 | I29: =+I27+I28 -> 15899876 | J29: =+J27+J28 -> 1879355.9 | K29: =+K27+K28 -> 0 | L29: =+L27+L28 -> 1789615.4 | ... O29: =+O27+O28 -> 1.187388e+08
B30: Expected Over Budget/ Reaminaing in Project Compare to Budget Value : | E30: =IF(O27>E27,"Over Amount From Budget ( Basic Amount ) : "&ROUNDUP(O27-E27,0),IF(O27<E27,"Reamaining Amount From Budget ( Basic Amount ) : "&ROUNDUP(O27-E27,0),"")) -> Reamaining Amount From Budget ( Basic Amount ) : -4058206
C39: Total Cost | D39: =E27 -> 1.0468431e+08
C40: Actual WO Amount | D40: =F27 -> 70113136
C41: Total Certified Amount | D41: =G27 -> 23435605
C43: Baseline Cost | D43: =E27 -> 1.0468431e+08
C44: Current Budget | D44: =O27 -> 1.006261e+08
C45: Cost Saving | D45: =D44-D43 -> -4058205.9

Sheet Monitoring
A1: ITEM NO. | B1: Item of Work | C1: UOM | D1: RATE | E1: BOQ Qty | F1: Extra Itmes Qty | G1: GFC Qty | H1: Achived QTY | I1: Excess Qty ( BOQ Vs GFC ) | J1: Saving Qty ( BOQ Vs GFC ) | K1: Certifed Qty ( Inoice ) | L1: BOQ Cost | M1: Extra Item Cost | N1: GFC Cost | O1: Achived Cost | P1: Excess ( BOQ Vs GFC ) Cost | Q1: Saving ( BOQ Vs GFC ) Cost | R1: Certified Invoice Cost | S1: % of Progress against BOQ | T1: % of Progress against GFC | U1: % of Progress against Achived | V1: % of Progress against Certified Qty | W1: Earned Value ( EV) agaisnt BOQ cost | X1: Earned Value ( EV) agaisnt GFC cost | Y1: Earned Value ( EV) agaisnt Certifed Invoice cost | Z1: Actual Cost (AC) | AA1: CPI ( Cost Perfromance Index ) | AB1: CPI Status | AC1: ETC ( Against BOQ ) | AD1: ETC ( Against GFC ) | AE1: ETC ( Against Certified Invoice ) ) | AF1: EAC | AG1: VAC | AH1: Variance ( BOQ vs GFC) | AI1: Variance ( GFC vs Achived) | AJ1: Variance ( GFC vs Certified Invoice) | AK1: Cost Over turn (BOQ Vs Variance ) | AL1: Cost Over turn (GFC Vs Variance ) | AM1: Cost Over turn (GFC Vs Certifed Invoice )
E2: Qty | L2: Cost | S2: Progress | W2: Earned Value | Z2: Cost Tracking & Monitor | AC2: Estimate to Complete | AF2: Estimate at Completion | AG2: Variance at Completion | AH2: Variations | AK2: Cost Over run
A3: 1 | B3: Excavation in all types of soil viz., sand, clay, gravel, Clayton, mud, slush other than rock for foundation of walls, columns, cable trenches, equipment foundation, etc. as per the Drawing, including shorting, dewatering subsoil water/Rain water wherever required and disposing off surplus materials (after utilization of back filling) selected earth within the site (Maximum lead 500mtr) at locations as directed by the engineer-in-charge including Back filling in foundation with approved materials inclusive of spreading in layers 150 mm thick, consolidating each layer by ramming, watering, Compacting the same with Vibro roller or in space constraints vibrating plate compactor etc. complete. (Minimum 1.60 gms / Cu.cm.) ( PCC area will be measured and paid for excavation & Backfilling )
A4: 2 | B4: -do 0.0 mt to 1.5 mt | C4: Cmt | D4: 178 | E4: 1750 | F4: 0 | G4: ='[2]DORMITORY MB'!H38 -> 924.84451 | H4: =11.8+913.05 -> 924.85 | I4: =IF(E4=0,G4,IF(AND(G4>E4,E4>0),G4-E4,0)) -> 0 | J4: =IF(G4=0,E4,IF(E4>=G4,E4-G4,0)) -> 825.15549 | L4: =E4*$D4 -> 311500 | M4: =F4*$D4 -> 0 | N4: =G4*$D4 -> 164622.32 | O4: =H4*$D4 -> 164623.3 | P4: =I4*$D4 -> 0 | Q4: =J4*$D4 -> 146877.68 | S4: =(H4/E4)*100 -> 52.848571 | T4: =(H4/G4)*100 -> 100.00059 | U4: =H4/E4 -> 0.52848571 | W4: =S4/100*L4 -> 164623.3 | X4: =T4/100*N4 -> 164623.3 | Y4: =V4/100*O4 -> 0 | Z4: =O4 -> 164623.3 | AA4: =IFERROR(W4/Z4,"") -> 1 | AB4: =IF(AA4=0,"No Work",IF(AA4<1,"Cost Overrun",IF(AA4=1,"On Budget",IF(AA4>1,"Under Budget","-")))) -> On Budget | AC4: =IFERROR((L4-W4)/AA4, "") -> 146876.7 | AD4: =IFERROR((N4-X4)/AA4, "") -> -0.97722 | AE4: =IFERROR((O4-Y4)/AB4, "") | AF4: =Z4+AC4 -> 311500 | AG4: =L4-AF4 -> 0 | AH4: =L4-N4 -> 146877.68 | AI4: =N4-O4 -> -0.97722 | AK4: =IFERROR(AH4/L4, "") -> 0.47151742 | AL4: =IFERROR(AI4/N4, "") -> -5.936133e-06 | AM4: =IFERROR(AJ4/O4, "") -> 0
A5: 3 | B5: -do 1.5 mt to 3.0 mt | C5: Cmt | D5: 268 | E5: 1625 | F5: 0 | G5: ='[2]DORMITORY MB'!H51 -> 913.05 | H5: 913.05 | I5: =IF(E5=0,G5,IF(AND(G5>E5,E5>0),G5-E5,0)) -> 0 | J5: =IF(G5=0,E5,IF(E5>=G5,E5-G5,0)) -> 711.95 | L5: =E5*$D5 -> 435500 | M5: =F5*$D5 -> 0 | N5: =G5*$D5 -> 244697.4 | O5: =H5*$D5 -> 244697.4 | P5: =I5*$D5 -> 0 | Q5: =J5*$D5 -> 190802.6 | S5: =(H5/E5)*100 -> 56.187692 | T5: =(H5/G5)*100 -> 100 | U5: =H5/E5 -> 0.56187692 | W5: =S5/100*L5 -> 244697.4 | X5: =T5/100*N5 -> 244697.4 | Y5: =V5/100*O5 -> 0 | Z5: =O5 -> 244697.4 | AA5: =IFERROR(W5/Z5,"") -> 1 | AB5: =IF(AA5=0,"No Work",IF(AA5<1,"Cost Overrun",IF(AA5=1,"On Budget",IF(AA5>1,"Under Budget","-")))) -> On Budget | AC5: =IFERROR((L5-W5)/AA5, "") -> 190802.6 | AD5: =IFERROR((N5-X5)/AA5, "") -> 0 | AE5: =IFERROR((O5-Y5)/AB5, "") | AF5: =Z5+AC5 -> 435500 | AG5: =L5-AF5 -> 0 | AH5: =L5-N5 -> 190802.6 | AI5: =N5-O5 -> 0 | AK5: =IFERROR(AH5/L5, "") -> 0.43812308 | AL5: =IFERROR(AI5/N5, "") -> 0 | AM5: =IFERROR(AJ5/O5, "") -> 0
A6: 4 | B6: -do 3.0 mt to 4.5 mt | C6: Cmt | D6: 375 | E6: 550 | F6: 0 | G6: 0 | H6: 0 | I6: =IF(E6=0,G6,IF(AND(G6>E6,E6>0),G6-E6,0)) -> 0 | J6: =IF(G6=0,E6,IF(E6>=G6,E6-G6,0)) -> 550 | L6: =E6*$D6 -> 206250 | M6: =F6*$D6 -> 0 | N6: =G6*$D6 -> 0 | O6: =H6*$D6 -> 0 | P6: =I6*$D6 -> 0 | Q6: =J6*$D6 -> 206250 | S6: =(H6/E6)*100 -> 0 | U6: =H6/E6 -> 0
A7: 5 | B7: Filling in plinth with approved materials like yellow earth/murrum in layers of 150 mm thickness, consolidating each layer by ramming and watering and rolling with vibro roller for a compaction to the modified proctor density of 95 percent of approved borrow pit. (Minimum 1.60 gms / Cu.cm.) - Approved Good quality Earth brought from Outside | C7: Cmt | D7: 495 | E7: 110 | F7: 0 | G7: 0 | H7: 0 | I7: =IF(E7=0,G7,IF(AND(G7>E7,E7>0),G7-E7,0)) -> 0 | J7: =IF(G7=0,E7,IF(E7>=G7,E7-G7,0)) -> 110 | L7: =E7*$D7 -> 54450 | M7: =F7*$D7 -> 0 | N7: =G7*$D7 -> 0 | O7: =H7*$D7 -> 0 | P7: =I7*$D7 -> 0 | Q7: =J7*$D7 -> 54450 | S7: =(H7/E7)*100 -> 0 | U7: =H7/E7 -> 0
A8: 6 | B8: 'Filling in plinth/plot with approved materials like yellow earth/murrum in layers of 150 mm thickness, consolidating each layer by ramming and watering and rolling with vibro roller for a compaction to the modified proctor density of 95 percent of approved borrow pit. (Minimum 1.60 gms / Cu.cm.) Selected earth obtained from available plote area - cutting and filling | C8: Cmt | D8: 200 | E8: 10000 | F8: 0 | G8: ='[2]DORMITORY MB'!H75 -> 1123.219 | H8: 1123.22 | I8: =IF(E8=0,G8,IF(AND(G8>E8,E8>0),G8-E8,0)) -> 0 | J8: =IF(G8=0,E8,IF(E8>=G8,E8-G8,0)) -> 8876.781 | L8: =E8*$D8 -> 2000000 | M8: =F8*$D8 -> 0 | N8: =G8*$D8 -> 224643.8 | O8: =H8*$D8 -> 224644 | P8: =I8*$D8 -> 0 | Q8: =J8*$D8 -> 1775356.2 | S8: =(H8/E8)*100 -> 11.2322 | T8: =(H8/G8)*100 -> 100.00009 | U8: =H8/E8 -> 0.112322
A9: 7 | B9: Providing and laying of avg 0.23 mm thick rubble soling using avg 90 mm thick rubble , including Compacting and filling the interstices with good quality approved earth/stone dust as binding material, spreading, watering, and consolidation of binding materials as directed by the Engineer-in charge | C9: Cmt | D9: 2000 | E9: 195.5 | F9: 0 | G9: ='[2]DORMITORY MB'!H108 -> 173.80939 | H9: 173.81 | I9: =IF(E9=0,G9,IF(AND(G9>E9,E9>0),G9-E9,0)) -> 0 | J9: =IF(G9=0,E9,IF(E9>=G9,E9-G9,0)) -> 21.69061 | L9: =E9*$D9 -> 391000 | M9: =F9*$D9 -> 0 | N9: =G9*$D9 -> 347618.78 | O9: =H9*$D9 -> 347620 | P9: =I9*$D9 -> 0 | Q9: =J9*$D9 -> 43381.22 | S9: =(H9/E9)*100 -> 88.905371 | T9: =(H9/G9)*100 -> 100.00035 | U9: =H9/E9 -> 0.88905371
A10: 8 | B10: Providing, mixing and laying plain cement concrete with avg 20-40 mm nominal size graded aggregates of approved quality as a levelling course under the column foundation, wall foundation, cable trenches, other trenches, machinery foundations, raft foundations, pipe supports, plinth beam, as floor sub base, etc. including ramming, levelling, curing etc. complete at any level (i.e. up to any depth or height from ground level). Please consider the cost of form work if required any. - M10 | C10: Cmt | D10: 3925 | E10: 265 | F10: 0 | G10: ='[2]DORMITORY MB'!H194 -> 223.55048 | H10: 223.55 | I10: =IF(E10=0,G10,IF(AND(G10>E10,E10>0),G10-E10,0)) -> 0 | J10: =IF(G10=0,E10,IF(E10>=G10,E10-G10,0)) -> 41.449515 | L10: =E10*$D10 -> 1040125 | M10: =F10*$D10 -> 0 | N10: =G10*$D10 -> 877435.65 | O10: =H10*$D10 -> 877433.75 | P10: =I10*$D10 -> 0 | Q10: =J10*$D10 -> 162689.35 | S10: =(H10/E10)*100 -> 84.358491 | T10: =(H10/G10)*100 -> 99.999783 | U10: =H10/E10 -> 0.84358491 | W10: =S10/100*L10 -> 877433.75 | X10: =T10/100*N10 -> 877433.75 | Y10: =V10/100*O10 -> 0 | Z10: =O10 -> 877433.75 | AA10: =IFERROR(W10/Z10,"") -> 1 | AB10: =IF(AA10=0,"No Work",IF(AA10<1,"Cost Overrun",IF(AA10=1,"On Budget",IF(AA10>1,"Under Budget","-")))) -> On Budget | AC10: =IFERROR((L10-W10)/AA10, "") -> 162691.25 | AD10: =IFERROR((N10-X10)/AA10, "") -> 1.903625 | AE10: =IFERROR((O10-Y10)/AB10, "") | AF10: =Z10+AC10 -> 1040125 | AG10: =L10-AF10 -> 0 | AH10: =L10-N10 -> 162689.35 | AI10: =N10-O10 -> 1.903625 | AK10: =IFERROR(AH10/L10, "") -> 0.15641326 | AL10: =IFERROR(AI10/N10, "") -> 2.1695323e-06 | AM10: =IFERROR(AJ10/O10, "") -> 0
A11: 9 | B11: Providing, mixing, Batching, Transporting through Transit Mixers, Pumping and laying plain / Reinforced cement concrete M:25 with 20 mm and downsized aggregate in all type of works such as foundation and superstructures, footings, pile caps, raft beams, columns, runners, coping beam, walls, slabs, lintels, tie-beams, canopies, staircase, fins, ledge, etc. in any pattern & shapes all including making openings, leaving sleeves in pedestals, columns, beams, slabs,pocket etc. complete as per the drawing and specification excluding the cost of formwork. and excluding the cost of Reinforcement. NOTE: Minimum Cement content 350Kgs/Cum. For Moderate condition -up to PL | C11: Cmt | D11: 5350 | E11: 380 | F11: 0 | G11: ='[2]DORMITORY MB'!H328 -> 519.00077 | H11: =503.11+5+5.03 -> 513.14 | I11: =IF(E11=0,G11,IF(AND(G11>E11,E11>0),G11-E11,0)) -> 139.00077 | J11: =IF(G11=0,E11,IF(E11>=G11,E11-G11,0)) -> 0 | L11: =E11*$D11 -> 2033000 | M11: =F11*$D11 -> 0 | N11: =G11*$D11 -> 2776654.1 | O11: =H11*$D11 -> 2745299 | P11: =I11*$D11 -> 743654.11 | Q11: =J11*$D11 -> 0 | S11: =(H11/E11)*100 -> 135.03684 | T11: =(H11/G11)*100 -> 98.870759 | U11: =H11/E11 -> 1.3503684 | W11: =S11/100*L11 -> 2745299 | X11: =T11/100*N11 -> 2745299 | Y11: =V11/100*O11 -> 0 | Z11: =O11 -> 2745299 | AA11: =IFERROR(W11/Z11,"") -> 1 | AB11: =IF(AA11=0,"No Work",IF(AA11<1,"Cost Overrun",IF(AA11=1,"On Budget",IF(AA11>1,"Under Budget","-")))) -> On Budget | AC11: =IFERROR((L11-W11)/AA11, "") -> -712299 | AD11: =IFERROR((N11-X11)/AA11, "") -> 31355.113 | AE11: =IFERROR((O11-Y11)/AB11, "") | AF11: =Z11+AC11 -> 2033000 | AG11: =L11-AF11 -> 0 | AH11: =L11-N11 -> -743654.11 | AI11: =N11-O11 -> 31355.113 | AK11: =IFERROR(AH11/L11, "") -> -0.3657915 | AL11: =IFERROR(AI11/N11, "") -> 0.011292409 | AM11: =IFERROR(AJ11/O11, "") -> 0
A12: 10 | B12: -do PL to G.F. Slab | C12: Cmt | D12: 5400 | E12: 210 | F12: 0 | G12: ='[2]DORMITORY MB'!H403 -> 208.2771 | H12: =1+205.07+0.5 -> 206.57 | I12: =IF(E12=0,G12,IF(AND(G12>E12,E12>0),G12-E12,0)) -> 0 | J12: =IF(G12=0,E12,IF(E12>=G12,E12-G12,0)) -> 1.722897 | L12: =E12*$D12 -> 1134000 | M12: =F12*$D12 -> 0 | N12: =G12*$D12 -> 1124696.4 | O12: =H12*$D12 -> 1115478 | P12: =I12*$D12 -> 0 | Q12: =J12*$D12 -> 9303.6438 | S12: =(H12/E12)*100 -> 98.366667 | T12: =(H12/G12)*100 -> 99.180369 | U12: =H12/E12 -> 0.98366667
A13: 11 | B13: -do G.F. to F.F. Slab | C13: Cmt | D13: 5550 | E13: 210 | F13: 0 | G13: ='[2]DORMITORY MB'!H478 -> 208.2771 | H13: 189.56 | I13: =IF(E13=0,G13,IF(AND(G13>E13,E13>0),G13-E13,0)) -> 0 | J13: =IF(G13=0,E13,IF(E13>=G13,E13-G13,0)) -> 1.722897 | L13: =E13*$D13 -> 1165500 | M13: =F13*$D13 -> 0 | N13: =G13*$D13 -> 1155937.9 | O13: =H13*$D13 -> 1052058 | P13: =I13*$D13 -> 0 | Q13: =J13*$D13 -> 9562.0783 | S13: =(H13/E13)*100 -> 90.266667 | T13: =(H13/G13)*100 -> 91.013365 | U13: =H13/E13 -> 0.90266667
A14: 12 | B14: -do F.F. to S.F. Slab | C14: Cmt | D14: 5700 | E14: 210 | F14: 0 | G14: ='[2]DORMITORY MB'!H553 -> 208.2771 | H14: 172.28 | I14: =IF(E14=0,G14,IF(AND(G14>E14,E14>0),G14-E14,0)) -> 0 | J14: =IF(G14=0,E14,IF(E14>=G14,E14-G14,0)) -> 1.722897 | L14: =E14*$D14 -> 1197000 | M14: =F14*$D14 -> 0 | N14: =G14*$D14 -> 1187179.5 | O14: =H14*$D14 -> 981996 | P14: =I14*$D14 -> 0 | Q14: =J14*$D14 -> 9820.5129 | S14: =(H14/E14)*100 -> 82.038095 | T14: =(H14/G14)*100 -> 82.716726 | U14: =H14/E14 -> 0.82038095
A15: 13 | B15: -do S.F. to T.F. Slab | C15: Cmt | D15: 5800 | E15: 210 | F15: 0 | G15: ='[2]DORMITORY MB'!H628 -> 208.2771 | H15: 22.68 | I15: =IF(E15=0,G15,IF(AND(G15>E15,E15>0),G15-E15,0)) -> 0 | J15: =IF(G15=0,E15,IF(E15>=G15,E15-G15,0)) -> 1.722897 | L15: =E15*$D15 -> 1218000 | M15: =F15*$D15 -> 0 | N15: =G15*$D15 -> 1208007.2 | O15: =H15*$D15 -> 131544 | P15: =I15*$D15 -> 0 | Q15: =J15*$D15 -> 9992.8026 | S15: =(H15/E15)*100 -> 10.8 | T15: =(H15/G15)*100 -> 10.889339 | U15: =H15/E15 -> 0.108
A16: 14 | B16: -do T.F. to F.F. Slab | C16: Cmt | D16: 5900 | E16: 210 | F16: 0 | G16: ='[2]DORMITORY MB'!H703 -> 208.2771 | H16: 0 | I16: =IF(E16=0,G16,IF(AND(G16>E16,E16>0),G16-E16,0)) -> 0 | J16: =IF(G16=0,E16,IF(E16>=G16,E16-G16,0)) -> 1.722897 | L16: =E16*$D16 -> 1239000 | M16: =F16*$D16 -> 0 | N16: =G16*$D16 -> 1228834.9 | O16: =H16*$D16 -> 0 | P16: =I16*$D16 -> 0 | Q16: =J16*$D16 -> 10165.092 | S16: =(H16/E16)*100 -> 0 | T16: =(H16/G16)*100 -> 0 | U16: =H16/E16 -> 0
A17: 15 | B17: Providing, cutting, bending, binding, laying, transporting and fixing in position at up to any levels (depth & height) reinforcement bars for all concrete works including 16 gauge annealed M.S. wire, spacer blocks of C.M. 1:2 with embedded binding wire of suitable length, protective coat of neat cement slurry to be applied as per Engineer-in-charge etc. complete. Bar bending schedule to be prepared by contractor. Any variation in reinforcement will be adjusted as per B.B.S. (Bar bending schedule) subject to approval and joint record by Engineer-in-Charge.- FE 500 TMT | C17: M.T. | D17: 69100 | E17: 153.03325 | F17: 0 | G17: ='[2]DORMITORY BBS'!U1965 -> 177.44495 | H17: 153.05 | I17: =IF(E17=0,G17,IF(AND(G17>E17,E17>0),G17-E17,0)) -> 24.411703 | J17: =IF(G17=0,E17,IF(E17>=G17,E17-G17,0)) -> 0 | L17: =E17*$D17 -> 10574597 | M17: =F17*$D17 -> 0 | N17: =G17*$D17 -> 12261446 | O17: =H17*$D17 -> 10575755 | P17: =I17*$D17 -> 1686848.6 | Q17: =J17*$D17 -> 0 | S17: =(H17/E17)*100 -> 100.01095 | T17: =(H17/G17)*100 -> 86.252103 | U17: =H17/E17 -> 1.0001095 | W17: =S17/100*L17 -> 10575755 | X17: =T17/100*N17 -> 10575755 | Y17: =V17/100*O17 -> 0 | Z17: =O17 -> 10575755 | AA17: =IFERROR(W17/Z17,"") -> 1 | AB17: =IF(AA17=0,"No Work",IF(AA17<1,"Cost Overrun",IF(AA17=1,"On Budget",IF(AA17>1,"Under Budget","-")))) -> On Budget | AC17: =IFERROR((L17-W17)/AA17, "") -> -1157.7035 | AD17: =IFERROR((N17-X17)/AA17, "") -> 1685690.9 | AE17: =IFERROR((O17-Y17)/AB17, "") | AF17: =Z17+AC17 -> 10574597 | AG17: =L17-AF17 -> 0 | AH17: =L17-N17 -> -1686848.6 | AI17: =N17-O17 -> 1685690.9 | AK17: =IFERROR(AH17/L17, "") -> -0.15951895 | AL17: =IFERROR(AI17/N17, "") -> 0.13747897 | AM17: =IFERROR(AJ17/O17, "") -> 0
A18: 16 | B18: Providing & fixing in position and removing any pattern and shape of good quality plastic coated high density shuttering plywood/MS formwork for all plain / reinforced concrete works including necessary centering and shuttering, applying approved shuttering oil, etc. complete as directed. No extra to be paid for curved, circular shuttering and staging for direct height if required for any level. | C18: Smt | D18: 415 | E18: 1075 | F18: 0 | G18: ='[2]DORMITORY MB'!H827 -> 1651.2538 | H18: 1651.25 | I18: =IF(E18=0,G18,IF(AND(G18>E18,E18>0),G18-E18,0)) -> 576.25375 | J18: =IF(G18=0,E18,IF(E18>=G18,E18-G18,0)) -> 0 | L18: =E18*$D18 -> 446125 | M18: =F18*$D18 -> 0 | N18: =G18*$D18 -> 685270.31 | O18: =H18*$D18 -> 685268.75 | P18: =I18*$D18 -> 239145.31 | Q18: =J18*$D18 -> 0 | S18: =(H18/E18)*100 -> 153.60465 | T18: =(H18/G18)*100 -> 99.999773 | U18: =H18/E18 -> 1.5360465 | W18: =S18/100*L18 -> 685268.75 | X18: =T18/100*N18 -> 685268.75 | Y18: =V18/100*O18 -> 0 | Z18: =O18 -> 685268.75 | AA18: =IFERROR(W18/Z18,"") -> 1 | AB18: =IF(AA18=0,"No Work",IF(AA18<1,"Cost Overrun",IF(AA18=1,"On Budget",IF(AA18>1,"Under Budget","-")))) -> On Budget | AC18: =IFERROR((L18-W18)/AA18, "") -> -239143.75 | AD18: =IFERROR((N18-X18)/AA18, "") -> 1.55625 | AE18: =IFERROR((O18-Y18)/AB18, "") | AF18: =Z18+AC18 -> 446125 | AG18: =L18-AF18 -> 0 | AH18: =L18-N18 -> -239145.31 | AI18: =N18-O18 -> 1.55625 | AK18: =IFERROR(AH18/L18, "") -> -0.53605 | AL18: =IFERROR(AI18/N18, "") -> 2.2710017e-06 | AM18: =IFERROR(AJ18/O18, "") -> 0
A19: 17 | B19: -do PL to G.F. Slab | C19: Smt | D19: 430 | E19: 1680 | F19: 0 | G19: ='[2]DORMITORY MB'!H985 -> 1933.9838 | H19: =13+1867.76+25 -> 1905.76 | I19: =IF(E19=0,G19,IF(AND(G19>E19,E19>0),G19-E19,0)) -> 253.9838 | J19: =IF(G19=0,E19,IF(E19>=G19,E19-G19,0)) -> 0 | L19: =E19*$D19 -> 722400 | M19: =F19*$D19 -> 0 | N19: =G19*$D19 -> 831613.03 | O19: =H19*$D19 -> 819476.8 | P19: =I19*$D19 -> 109213.03 | Q19: =J19*$D19 -> 0 | S19: =(H19/E19)*100 -> 113.4381 | T19: =(H19/G19)*100 -> 98.540639 | U19: =H19/E19 -> 1.134381
A20: 18 | B20: -do G.F. to F.F. Slab | C20: Smt | D20: =D19+25 -> 455 | E20: 1680 | F20: 0 | G20: ='[2]DORMITORY MB'!H1141 -> 1933.9838 | H20: =1680.26+55.32 -> 1735.58 | I20: =IF(E20=0,G20,IF(AND(G20>E20,E20>0),G20-E20,0)) -> 253.9838 | J20: =IF(G20=0,E20,IF(E20>=G20,E20-G20,0)) -> 0 | L20: =E20*$D20 -> 764400 | M20: =F20*$D20 -> 0 | N20: =G20*$D20 -> 879962.63 | O20: =H20*$D20 -> 789688.9 | P20: =I20*$D20 -> 115562.63 | Q20: =J20*$D20 -> 0 | S20: =(H20/E20)*100 -> 103.30833 | T20: =(H20/G20)*100 -> 89.741186 | U20: =H20/E20 -> 1.0330833
A21: 19 | B21: -do F.F. to S.F. Slab | C21: Smt | D21: =455+25 -> 480 | E21: 1680 | F21: 0 | G21: ='[2]DORMITORY MB'!H1297 -> 1933.9838 | H21: 1389.23 | I21: =IF(E21=0,G21,IF(AND(G21>E21,E21>0),G21-E21,0)) -> 253.9838 | J21: =IF(G21=0,E21,IF(E21>=G21,E21-G21,0)) -> 0 | L21: =E21*$D21 -> 806400 | M21: =F21*$D21 -> 0 | N21: =G21*$D21 -> 928312.22 | O21: =H21*$D21 -> 666830.4 | P21: =I21*$D21 -> 121912.22 | Q21: =J21*$D21 -> 0 | S21: =(H21/E21)*100 -> 82.692262 | T21: =(H21/G21)*100 -> 71.832556 | U21: =H21/E21 -> 0.82692262
A22: 20 | B22: -do S.F. to T.F. Slab | C22: Smt | D22: =D21+25 -> 505 | E22: 1680 | F22: 0 | G22: ='[2]DORMITORY MB'!H1453 -> 1933.9838 | H22: 846.42 | I22: =IF(E22=0,G22,IF(AND(G22>E22,E22>0),G22-E22,0)) -> 253.9838 | J22: =IF(G22=0,E22,IF(E22>=G22,E22-G22,0)) -> 0 | L22: =E22*$D22 -> 848400 | M22: =F22*$D22 -> 0 | N22: =G22*$D22 -> 976661.82 | O22: =H22*$D22 -> 427442.1 | P22: =I22*$D22 -> 128261.82 | Q22: =J22*$D22 -> 0 | S22: =(H22/E22)*100 -> 50.382143 | T22: =(H22/G22)*100 -> 43.76562 | U22: =H22/E22 -> 0.50382143
A23: 21 | B23: -do T.F. to F.F. Slab | C23: Smt | D23: =D22+25 -> 530 | E23: 1680 | F23: 0 | G23: ='[2]DORMITORY MB'!H1609 -> 1933.9838 | H23: 0 | I23: =IF(E23=0,G23,IF(AND(G23>E23,E23>0),G23-E23,0)) -> 253.9838 | J23: =IF(G23=0,E23,IF(E23>=G23,E23-G23,0)) -> 0 | L23: =E23*$D23 -> 890400 | M23: =F23*$D23 -> 0 | N23: =G23*$D23 -> 1025011.4 | O23: =H23*$D23 -> 0 | P23: =I23*$D23 -> 134611.41 | Q23: =J23*$D23 -> 0 | S23: =(H23/E23)*100 -> 0 | T23: =(H23/G23)*100 -> 0 | U23: =H23/E23 -> 0
A24: 22 | B24: Providing and laying first class brick masonry works in C.M. 1:6 for foundation up to any depth from ground level and plinth up to any height from ground level including scaffolding, watering, racking out joints, etc. complete in all respect. (Minimum compressive strength of the brick shall be 50 kg./Sq.Cm.) - do up to PL | C24: Cmt | D24: 5790 | E24: 130 | F24: 0 | G24: ='[2]DORMITORY MB'!H1675 -> 102.46166 | H24: 100.38 | I24: =IF(E24=0,G24,IF(AND(G24>E24,E24>0),G24-E24,0)) -> 0 | J24: =IF(G24=0,E24,IF(E24>=G24,E24-G24,0)) -> 27.538343 | L24: =E24*$D24 -> 752700 | M24: =F24*$D24 -> 0 | N24: =G24*$D24 -> 593252.99 | O24: =H24*$D24 -> 581200.2 | P24: =I24*$D24 -> 0 | Q24: =J24*$D24 -> 159447.01 | S24: =(H24/E24)*100 -> 77.215385 | T24: =(H24/G24)*100 -> 97.968355 | U24: =H24/E24 -> 0.77215385
A25: 23 | B25: -do PL to G.F. Slab | C25: Cmt | D25: 5790 | E25: 80 | F25: 0 | G25: ='[2]DORMITORY MB'!H1696 -> 73.479825 | H25: 43.86 | I25: =IF(E25=0,G25,IF(AND(G25>E25,E25>0),G25-E25,0)) -> 0 | J25: =IF(G25=0,E25,IF(E25>=G25,E25-G25,0)) -> 6.520175 | L25: =E25*$D25 -> 463200 | M25: =F25*$D25 -> 0 | N25: =G25*$D25 -> 425448.19 | O25: =H25*$D25 -> 253949.4 | P25: =I25*$D25 -> 0 | Q25: =J25*$D25 -> 37751.813 | S25: =(H25/E25)*100 -> 54.825 | T25: =(H25/G25)*100 -> 59.689854 | U25: =H25/E25 -> 0.54825
A26: 24 | B26: -do G.F. to F.F. Slab | C26: Cmt | D26: 5940 | E26: 80 | F26: 0 | G26: ='[2]DORMITORY MB'!H1715 -> 73.479825 | H26: 28.63 | I26: =IF(E26=0,G26,IF(AND(G26>E26,E26>0),G26-E26,0)) -> 0 | J26: =IF(G26=0,E26,IF(E26>=G26,E26-G26,0)) -> 6.520175 | L26: =E26*$D26 -> 475200 | M26: =F26*$D26 -> 0 | N26: =G26*$D26 -> 436470.16 | O26: =H26*$D26 -> 170062.2 | P26: =I26*$D26 -> 0 | Q26: =J26*$D26 -> 38729.839 | S26: =(H26/E26)*100 -> 35.7875 | T26: =(H26/G26)*100 -> 38.963076 | U26: =H26/E26 -> 0.357875
A27: 25 | B27: -do F.F. to S.F. Slab | C27: Cmt | D27: 6090 | E27: 80 | F27: 0 | G27: ='[2]DORMITORY MB'!H1733 -> 73.479825 | H27: 0 | I27: =IF(E27=0,G27,IF(AND(G27>E27,E27>0),G27-E27,0)) -> 0 | J27: =IF(G27=0,E27,IF(E27>=G27,E27-G27,0)) -> 6.520175 | L27: =E27*$D27 -> 487200 | M27: =F27*$D27 -> 0 | N27: =G27*$D27 -> 447492.13 | O27: =H27*$D27 -> 0 | P27: =I27*$D27 -> 0 | Q27: =J27*$D27 -> 39707.866 | S27: =(H27/E27)*100 -> 0 | T27: =(H27/G27)*100 -> 0 | U27: =H27/E27 -> 0
A28: 26 | B28: -do S.F. to T.F. Slab | C28: Cmt | D28: 6240 | E28: 80 | F28: 0 | G28: ='[2]DORMITORY MB'!H1751 -> 73.479825 | H28: 0 | I28: =IF(E28=0,G28,IF(AND(G28>E28,E28>0),G28-E28,0)) -> 0 | J28: =IF(G28=0,E28,IF(E28>=G28,E28-G28,0)) -> 6.520175 | L28: =E28*$D28 -> 499200 | M28: =F28*$D28 -> 0 | N28: =G28*$D28 -> 458514.11 | O28: =H28*$D28 -> 0 | P28: =I28*$D28 -> 0 | Q28: =J28*$D28 -> 40685.892 | S28: =(H28/E28)*100 -> 0 | T28: =(H28/G28)*100 -> 0 | U28: =H28/E28 -> 0
A29: 27 | B29: -do T.F. to F.F. Slab | C29: Cmt | D29: 6390 | E29: 80 | F29: 0 | G29: ='[2]DORMITORY MB'!H1775 -> 92.819145 | H29: 0 | I29: =IF(E29=0,G29,IF(AND(G29>E29,E29>0),G29-E29,0)) -> 12.819145 | J29: =IF(G29=0,E29,IF(E29>=G29,E29-G29,0)) -> 0 | L29: =E29*$D29 -> 511200 | M29: =F29*$D29 -> 0 | N29: =G29*$D29 -> 593114.34 | O29: =H29*$D29 -> 0 | P29: =I29*$D29 -> 81914.337 | Q29: =J29*$D29 -> 0 | S29: =(H29/E29)*100 -> 0 | T29: =(H29/G29)*100 -> 0 | U29: =H29/E29 -> 0
A30: 28 | B30: Providing and laying brick masonry work for a 115 mm thick partition wall in C.M. 1:4 at all depth & heights including laying horizontally 2 nos. 8 mm. Dia. Reinforcement BARS at every 4th course including scaffolding, curing, etc. complete in all respect. (Reinforcement Bars to be paidseparately). (Minimum compressive strength of the brick shall be 50 kg. /Sq.Cm).- do up to GF | C30: Smt | D30: 785 | E30: 1170 | F30: 0 | G30: ='[2]DORMITORY MB'!H1796 -> 767.8539 | H30: 356.26 | I30: =IF(E30=0,G30,IF(AND(G30>E30,E30>0),G30-E30,0)) -> 0 | J30: =IF(G30=0,E30,IF(E30>=G30,E30-G30,0)) -> 402.1461 | L30: =E30*$D30 -> 918450 | M30: =F30*$D30 -> 0 | N30: =G30*$D30 -> 602765.31 | O30: =H30*$D30 -> 279664.1 | P30: =I30*$D30 -> 0 | Q30: =J30*$D30 -> 315684.69 | S30: =(H30/E30)*100 -> 30.449573 | T30: =(H30/G30)*100 -> 46.396847 | U30: =H30/E30 -> 0.30449573
A31: 29 | B31: -do G.F. to F.F. Slab | C31: Smt | D31: 805 | E31: 1170 | F31: 0 | G31: ='[2]DORMITORY MB'!H1817 -> 767.8539 | H31: 174.55 | I31: =IF(E31=0,G31,IF(AND(G31>E31,E31>0),G31-E31,0)) -> 0 | J31: =IF(G31=0,E31,IF(E31>=G31,E31-G31,0)) -> 402.1461 | L31: =E31*$D31 -> 941850 | M31: =F31*$D31 -> 0 | N31: =G31*$D31 -> 618122.39 | O31: =H31*$D31 -> 140512.75 | P31: =I31*$D31 -> 0 | Q31: =J31*$D31 -> 323727.61 | S31: =(H31/E31)*100 -> 14.918803 | T31: =(H31/G31)*100 -> 22.732189 | U31: =H31/E31 -> 0.14918803
A32: 30 | B32: -do F.F. to S.F. Slab | C32: Smt | D32: 825 | E32: 1170 | F32: 0 | G32: ='[2]DORMITORY MB'!H1838 -> 767.8539 | H32: 0 | I32: =IF(E32=0,G32,IF(AND(G32>E32,E32>0),G32-E32,0)) -> 0 | J32: =IF(G32=0,E32,IF(E32>=G32,E32-G32,0)) -> 402.1461 | L32: =E32*$D32 -> 965250 | M32: =F32*$D32 -> 0 | N32: =G32*$D32 -> 633479.47 | O32: =H32*$D32 -> 0 | P32: =I32*$D32 -> 0 | Q32: =J32*$D32 -> 331770.53 | S32: =(H32/E32)*100 -> 0 | T32: =(H32/G32)*100 -> 0 | U32: =H32/E32 -> 0
A33: 31 | B33: -do S.F. to T.F. Slab | C33: Smt | D33: 845 | E33: 1170 | F33: 0 | G33: ='[2]DORMITORY MB'!H1859 -> 767.8539 | H33: 0 | I33: =IF(E33=0,G33,IF(AND(G33>E33,E33>0),G33-E33,0)) -> 0 | J33: =IF(G33=0,E33,IF(E33>=G33,E33-G33,0)) -> 402.1461 | L33: =E33*$D33 -> 988650 | M33: =F33*$D33 -> 0 | N33: =G33*$D33 -> 648836.55 | O33: =H33*$D33 -> 0 | P33: =I33*$D33 -> 0 | Q33: =J33*$D33 -> 339813.45 | S33: =(H33/E33)*100 -> 0 | T33: =(H33/G33)*100 -> 0 | U33: =H33/E33 -> 0
A34: 32 | B34: -do T.F. to F.F. Slab | C34: Smt | D34: =845+20 -> 865 | E34: 1170 | F34: 0 | G34: ='[2]DORMITORY MB'!H1880 -> 767.8539 | H34: 0 | I34: =IF(E34=0,G34,IF(AND(G34>E34,E34>0),G34-E34,0)) -> 0 | J34: =IF(G34=0,E34,IF(E34>=G34,E34-G34,0)) -> 402.1461 | L34: =E34*$D34 -> 1012050 | M34: =F34*$D34 -> 0 | N34: =G34*$D34 -> 664193.62 | O34: =H34*$D34 -> 0 | P34: =I34*$D34 -> 0 | Q34: =J34*$D34 -> 347856.38 | S34: =(H34/E34)*100 -> 0 | T34: =(H34/G34)*100 -> 0 | U34: =H34/E34 -> 0
A35: 33 | B35: -do F.F. to Terrace | C35: Smt | D35: =865+20 -> 885 | E35: 215 | F35: 0 | G35: ='[2]DORMITORY MB'!H1900 -> 328.67 | H35: 0 | I35: =IF(E35=0,G35,IF(AND(G35>E35,E35>0),G35-E35,0)) -> 113.67 | J35: =IF(G35=0,E35,IF(E35>=G35,E35-G35,0)) -> 0 | L35: =E35*$D35 -> 190275 | M35: =F35*$D35 -> 0 | N35: =G35*$D35 -> 290872.95 | O35: =H35*$D35 -> 0 | P35: =I35*$D35 -> 100597.95 | Q35: =J35*$D35 -> 0 | S35: =(H35/E35)*100 -> 0 | T35: =(H35/G35)*100 -> 0 | U35: =H35/E35 -> 0
A36: 34 | B36: Providing and laying 12 mm thick cement plaster to all surfaces of brick masonry, and R.C.C. in C.M. 1:4 finished smooth with cement punning including scaffolding, racking of joints, racking of RCC surface, curing, etc. complete including providing and fixing G.I. chicken wire mesh either side of joint of the junction of R.C.C. / P.C.C. and masonry, Bonding chemical etc. as directed by Engineer-in-Charge. The item is inclusive of grooves up to 12 x 12mm, drip moulds (50 mm wide x 12 mm thick), bands of any width etc. complete.- do up to PL | C36: Smt | D36: 270 | E36: 140 | F36: 0 | G36: 0 | H36: 0 | I36: =IF(E36=0,G36,IF(AND(G36>E36,E36>0),G36-E36,0)) -> 0 | J36: =IF(G36=0,E36,IF(E36>=G36,E36-G36,0)) -> 140 | L36: =E36*$D36 -> 37800 | M36: =F36*$D36 -> 0 | N36: =G36*$D36 -> 0 | O36: =H36*$D36 -> 0 | P36: =I36*$D36 -> 0 | Q36: =J36*$D36 -> 37800
A37: 35 | B37: -do PL to G.F. Slab | C37: Smt | D37: 285 | E37: 3325 | F37: 0 | G37: ='[2]DORMITORY MB'!H1931 -> 1733.7925 | H37: 663 | I37: =IF(E37=0,G37,IF(AND(G37>E37,E37>0),G37-E37,0)) -> 0 | J37: =IF(G37=0,E37,IF(E37>=G37,E37-G37,0)) -> 1591.2075 | L37: =E37*$D37 -> 947625 | M37: =F37*$D37 -> 0 | N37: =G37*$D37 -> 494130.86 | O37: =H37*$D37 -> 188955 | P37: =I37*$D37 -> 0 | Q37: =J37*$D37 -> 453494.14 | S37: =(H37/E37)*100 -> 19.93985 | T37: =(H37/G37)*100 -> 38.23987 | U37: =H37/E37 -> 0.1993985
A38: 36 | B38: -do G.F. to F.F. Slab | C38: Smt | D38: =D37+20 -> 305 | E38: 3325 | F38: 0 | G38: ='[2]DORMITORY MB'!H1962 -> 1733.7925 | H38: 0 | I38: =IF(E38=0,G38,IF(AND(G38>E38,E38>0),G38-E38,0)) -> 0 | J38: =IF(G38=0,E38,IF(E38>=G38,E38-G38,0)) -> 1591.2075 | L38: =E38*$D38 -> 1014125 | M38: =F38*$D38 -> 0 | N38: =G38*$D38 -> 528806.71 | O38: =H38*$D38 -> 0 | P38: =I38*$D38 -> 0 | Q38: =J38*$D38 -> 485318.29 | S38: =(H38/E38)*100 -> 0 | T38: =(H38/G38)*100 -> 0 | U38: =H38/E38 -> 0
A39: 37 | B39: -do F.F. to S.F. Slab | C39: Smt | D39: =D38+20 -> 325 | E39: 3325 | F39: 0 | G39: ='[2]DORMITORY MB'!H1993 -> 1733.7925 | H39: 0 | I39: =IF(E39=0,G39,IF(AND(G39>E39,E39>0),G39-E39,0)) -> 0 | J39: =IF(G39=0,E39,IF(E39>=G39,E39-G39,0)) -> 1591.2075 | L39: =E39*$D39 -> 1080625 | M39: =F39*$D39 -> 0 | N39: =G39*$D39 -> 563482.56 | O39: =H39*$D39 -> 0 | P39: =I39*$D39 -> 0 | Q39: =J39*$D39 -> 517142.44 | S39: =(H39/E39)*100 -> 0 | T39: =(H39/G39)*100 -> 0 | U39: =H39/E39 -> 0
A40: 38 | B40: -do S.F. to T.F. Slab | C40: Smt | D40: =D39+20 -> 345 | E40: 3325 | F40: 0 | G40: ='[2]DORMITORY MB'!H2024 -> 1733.7925 | H40: 0 | I40: =IF(E40=0,G40,IF(AND(G40>E40,E40>0),G40-E40,0)) -> 0 | J40: =IF(G40=0,E40,IF(E40>=G40,E40-G40,0)) -> 1591.2075 | L40: =E40*$D40 -> 1147125 | M40: =F40*$D40 -> 0 | N40: =G40*$D40 -> 598158.41 | O40: =H40*$D40 -> 0 | P40: =I40*$D40 -> 0 | Q40: =J40*$D40 -> 548966.59 | S40: =(H40/E40)*100 -> 0 | T40: =(H40/G40)*100 -> 0 | U40: =H40/E40 -> 0
...

Sheet STEEL RATE DIFFRENCE
A1: Sr.No | B1: Description | C1: Vendor Name | D1: Purchase No | E1: Steel Purchase Details
E2: Dia Of Bar | F2: Qty. | G2: Basic Rate | H2: Purchase Rate | I2: Basic Rate Amount | J2: Purchase Rate Amount | K2: Excess Amount | L2: Saving Amount
A3: 1 | B3: TMT Bars Fe500 | C3: Vasupujya Enterprise | D3: 1st Purchase | E3: 8 | F3: 4.02 | G3: 53000 | H3: 46593.22 | I3: =F3*G3 -> 213060 | J3: =F3*H3 -> 187304.74 | K3: =IF(H3>G3,(H3-G3)*F3,0) -> 0 | L3: =IF(G3>H3,(G3-H3)*F3,0) -> 25755.256
A4: 2 | E4: 10 | F4: 4.02 | G4: 53000 | H4: 45067.8 | I4: =F4*G4 -> 213060 | J4: =F4*H4 -> 181172.56 | K4: =IF(H4>G4,(H4-G4)*F4,0) -> 0 | L4: =IF(G4>H4,(G4-H4)*F4,0) -> 31887.444
A5: 3 | E5: 12 | F5: 3.02 | G5: 53000 | H5: 44050.85 | I5: =F5*G5 -> 160060 | J5: =F5*H5 -> 133033.57 | K5: =IF(H5>G5,(H5-G5)*F5,0) -> 0 | L5: =IF(G5>H5,(G5-H5)*F5,0) -> 27026.433
A6: 4 | E6: 16 | F6: 1.93 | G6: 53000 | H6: 44050.85 | I6: =F6*G6 -> 102290 | J6: =F6*H6 -> 85018.14 | K6: =IF(H6>G6,(H6-G6)*F6,0) -> 0 | L6: =IF(G6>H6,(G6-H6)*F6,0) -> 17271.86
A7: 5 | E7: 20 | F7: 11.05 | G7: 53000 | H7: 44050.85 | I7: =F7*G7 -> 585650 | J7: =F7*H7 -> 486761.89 | K7: =IF(H7>G7,(H7-G7)*F7,0) -> 0 | L7: =IF(G7>H7,(G7-H7)*F7,0) -> 98888.108
A8: 6 | B8: TMT Bars Fe500 | C8: Steel Solution | D8: 2nd Purchase | E8: 8 | F8: 1.01 | G8: 53000 | H8: 47203 | I8: =F8*G8 -> 53530 | J8: =F8*H8 -> 47675.03 | K8: =IF(H8>G8,(H8-G8)*F8,0) -> 0 | L8: =IF(G8>H8,(G8-H8)*F8,0) -> 5854.97
A9: 7 | E9: 10 | F9: 1.9 | G9: 53000 | H9: 45678 | I9: =F9*G9 -> 100700 | J9: =F9*H9 -> 86788.2 | K9: =IF(H9>G9,(H9-G9)*F9,0) -> 0 | L9: =IF(G9>H9,(G9-H9)*F9,0) -> 13911.8
A10: 8 | E10: 12 | F10: 1.97 | G10: 53000 | H10: 44661 | I10: =F10*G10 -> 104410 | J10: =F10*H10 -> 87982.17 | K10: =IF(H10>G10,(H10-G10)*F10,0) -> 0 | L10: =IF(G10>H10,(G10-H10)*F10,0) -> 16427.83
A11: 9 | E11: 16 | F11: 5.02 | G11: 53000 | H11: 44661 | I11: =F11*G11 -> 266060 | J11: =F11*H11 -> 224198.22 | K11: =IF(H11>G11,(H11-G11)*F11,0) -> 0 | L11: =IF(G11>H11,(G11-H11)*F11,0) -> 41861.78
A12: 10 | B12: TMT Bars Fe550 | C12: Vasupujya Enterprise | D12: 3rd Purchase | E12: 8 | F12: 3.63 | G12: 53000 | H12: 46560 | I12: =F12*G12 -> 192390 | J12: =F12*H12 -> 169012.8 | K12: =IF(H12>G12,(H12-G12)*F12,0) -> 0 | L12: =IF(G12>H12,(G12-H12)*F12,0) -> 23377.2
A13: 11 | E13: 10 | F13: 1.07 | G13: 53000 | H13: 45030 | I13: =F13*G13 -> 56710 | J13: =F13*H13 -> 48182.1 | K13: =IF(H13>G13,(H13-G13)*F13,0) -> 0 | L13: =IF(G13>H13,(G13-H13)*F13,0) -> 8527.9
A14: 12 | E14: 12 | F14: 4.51 | G14: 53000 | H14: 44020 | I14: =F14*G14 -> 239030 | J14: =F14*H14 -> 198530.2 | K14: =IF(H14>G14,(H14-G14)*F14,0) -> 0 | L14: =IF(G14>H14,(G14-H14)*F14,0) -> 40499.8
A15: 13 | E15: 16 | F15: 3.44 | G15: 53000 | H15: 44020 | I15: =F15*G15 -> 182320 | J15: =F15*H15 -> 151428.8 | K15: =IF(H15>G15,(H15-G15)*F15,0) -> 0 | L15: =IF(G15>H15,(G15-H15)*F15,0) -> 30891.2
A16: 10 | B16: TMT Bars Fe550 | C16: Steel House | D16: 4th Purchase | E16: 8 | F16: 2.5 | G16: 53000 | H16: 46272 | I16: =F16*G16 -> 132500 | J16: =F16*H16 -> 115680 | K16: =IF(H16>G16,(H16-G16)*F16,0) -> 0 | L16: =IF(G16>H16,(G16-H16)*F16,0) -> 16820
A17: 11 | E17: 10 | F17: 0.52 | G17: 53000 | H17: 44916 | I17: =F17*G17 -> 27560 | J17: =F17*H17 -> 23356.32 | K17: =IF(H17>G17,(H17-G17)*F17,0) -> 0 | L17: =IF(G17>H17,(G17-H17)*F17,0) -> 4203.68
A18: 12 | E18: 16 | F18: 5.21 | G18: 53000 | H18: 44068 | I18: =F18*G18 -> 276130 | J18: =F18*H18 -> 229594.28 | K18: =IF(H18>G18,(H18-G18)*F18,0) -> 0 | L18: =IF(G18>H18,(G18-H18)*F18,0) -> 46535.72
A19: 13 | E19: 20 | F19: 4.93 | G19: 53000 | H19: 44068 | I19: =F19*G19 -> 261290 | J19: =F19*H19 -> 217255.24 | K19: =IF(H19>G19,(H19-G19)*F19,0) -> 0 | L19: =IF(G19>H19,(G19-H19)*F19,0) -> 44034.76
A20: 14 | B20: TMT Bars Fe550 | C20: Steel House | D20: 5th Purchase | E20: 8 | F20: 12.09 | G20: 53000 | H20: 45423 | I20: =F20*G20 -> 640770 | J20: =F20*H20 -> 549164.07 | K20: =IF(H20>G20,(H20-G20)*F20,0) -> 0 | L20: =IF(G20>H20,(G20-H20)*F20,0) -> 91605.93
A21: 15 | E21: 10 | F21: 0.22 | G21: 53000 | H21: 44237 | I21: =F21*G21 -> 11660 | J21: =F21*H21 -> 9732.14 | K21: =IF(H21>G21,(H21-G21)*F21,0) -> 0 | L21: =IF(G21>H21,(G21-H21)*F21,0) -> 1927.86
A22: 16 | E22: 12 | F22: 3.65 | G22: 53000 | H22: 43390 | I22: =F22*G22 -> 193450 | J22: =F22*H22 -> 158373.5 | K22: =IF(H22>G22,(H22-G22)*F22,0) -> 0 | L22: =IF(G22>H22,(G22-H22)*F22,0) -> 35076.5
A23: 17 | E23: 16 | F23: 5.81 | G23: 53000 | H23: 43390 | I23: =F23*G23 -> 307930 | J23: =F23*H23 -> 252095.9 | K23: =IF(H23>G23,(H23-G23)*F23,0) -> 0 | L23: =IF(G23>H23,(G23-H23)*F23,0) -> 55834.1
A24: 18 | E24: 20 | F24: 7.02 | G24: 53000 | H24: 43220 | I24: =F24*G24 -> 372060 | J24: =F24*H24 -> 303404.4 | K24: =IF(H24>G24,(H24-G24)*F24,0) -> 0 | L24: =IF(G24>H24,(G24-H24)*F24,0) -> 68655.6
A25: 14 | B25: TMT Bars Fe550 | C25: Vasupujya Enterprise | D25: 6th Purchase | E25: 8 | F25: 12.86 | G25: 53000 | H25: 44070 | I25: =F25*G25 -> 681580 | J25: =F25*H25 -> 566740.2 | K25: =IF(H25>G25,(H25-G25)*F25,0) -> 0 | L25: =IF(G25>H25,(G25-H25)*F25,0) -> 114839.8
A26: 15 | E26: 10 | F26: 1 | G26: 53000 | H26: 42880 | I26: =F26*G26 -> 53000 | J26: =F26*H26 -> 42880 | K26: =IF(H26>G26,(H26-G26)*F26,0) -> 0 | L26: =IF(G26>H26,(G26-H26)*F26,0) -> 10120
A27: 16 | E27: 12 | F27: 3.52 | G27: 53000 | H27: 42030 | I27: =F27*G27 -> 186560 | J27: =F27*H27 -> 147945.6 | K27: =IF(H27>G27,(H27-G27)*F27,0) -> 0 | L27: =IF(G27>H27,(G27-H27)*F27,0) -> 38614.4
A28: 17 | E28: 16 | F28: 6.21 | G28: 53000 | H28: 42030 | I28: =F28*G28 -> 329130 | J28: =F28*H28 -> 261006.3 | K28: =IF(H28>G28,(H28-G28)*F28,0) -> 0 | L28: =IF(G28>H28,(G28-H28)*F28,0) -> 68123.7
A29: 18 | E29: 20 | F29: 6.75 | G29: 53000 | H29: 41700 | I29: =F29*G29 -> 357750 | J29: =F29*H29 -> 281475 | K29: =IF(H29>G29,(H29-G29)*F29,0) -> 0 | L29: =IF(G29>H29,(G29-H29)*F29,0) -> 76275
A30: 19 | B30: TMT Bars Fe550 | C30: Steel House | D30: 7th Purchase | E30: 8 | F30: 16.16 | G30: 53000 | H30: 44830 | I30: =F30*G30 -> 856480 | J30: =F30*H30 -> 724452.8 | K30: =IF(H30>G30,(H30-G30)*F30,0) -> 0 | L30: =IF(G30>H30,(G30-H30)*F30,0) -> 132027.2
A31: 20 | E31: 10 | F31: 0.95 | G31: 53000 | H31: 43640 | I31: =F31*G31 -> 50350 | J31: =F31*H31 -> 41458 | K31: =IF(H31>G31,(H31-G31)*F31,0) -> 0 | L31: =IF(G31>H31,(G31-H31)*F31,0) -> 8892
A32: 21 | E32: 12 | F32: 4.61 | G32: 53000 | H32: 42800 | I32: =F32*G32 -> 244330 | J32: =F32*H32 -> 197308 | K32: =IF(H32>G32,(H32-G32)*F32,0) -> 0 | L32: =IF(G32>H32,(G32-H32)*F32,0) -> 47022
A33: 22 | E33: 16 | F33: 7.74 | G33: 53000 | H33: 42800 | I33: =F33*G33 -> 410220 | J33: =F33*H33 -> 331272 | K33: =IF(H33>G33,(H33-G33)*F33,0) -> 0 | L33: =IF(G33>H33,(G33-H33)*F33,0) -> 78948
A34: 23 | E34: 20 | F34: 2.78 | G34: 53000 | H34: 42460 | I34: =F34*G34 -> 147340 | J34: =F34*H34 -> 118038.8 | K34: =IF(H34>G34,(H34-G34)*F34,0) -> 0 | L34: =IF(G34>H34,(G34-H34)*F34,0) -> 29301.2
A35: 24 | B35: TMT Bars Fe550 | C35: Vasupujya Enterprise | D35: 8th Purchase | E35: 8 | F35: 10.51 | G35: 53000 | H35: 46440 | I35: =F35*G35 -> 557030 | J35: =F35*H35 -> 488084.4 | K35: =IF(H35>G35,(H35-G35)*F35,0) -> 0 | L35: =IF(G35>H35,(G35-H35)*F35,0) -> 68945.6
A36: 25 | E36: 10 | F36: 0.51 | G36: 53000 | H36: 45250 | I36: =F36*G36 -> 27030 | J36: =F36*H36 -> 23077.5 | K36: =IF(H36>G36,(H36-G36)*F36,0) -> 0 | L36: =IF(G36>H36,(G36-H36)*F36,0) -> 3952.5
A37: 26 | E37: 12 | F37: 3.96 | G37: 53000 | H37: 44410 | I37: =F37*G37 -> 209880 | J37: =F37*H37 -> 175863.6 | K37: =IF(H37>G37,(H37-G37)*F37,0) -> 0 | L37: =IF(G37>H37,(G37-H37)*F37,0) -> 34016.4
A38: 27 | E38: 16 | F38: 6.83 | G38: 53000 | H38: 44410 | I38: =F38*G38 -> 361990 | J38: =F38*H38 -> 303320.3 | K38: =IF(H38>G38,(H38-G38)*F38,0) -> 0 | L38: =IF(G38>H38,(G38-H38)*F38,0) -> 58669.7
A39: Total : - | F39: =SUM(F3:F38) -> 172.93 | I39: =SUM(I3:I38) -> 9165290 | J39: =SUM(J3:J38) -> 7648666.8 | K39: =SUM(K3:K15) -> 0 | L39: =SUM(L3:L38) -> 1516623.2 | M39: =L39/100000 -> 15.166232
A42: Total Saving | B42: =L39 -> 1516623.2

Sheet CEMENT RATE DIFFRENCE
A1: Sr.No | B1: Description | C1: Vendor Name | E1: Cement Purchase Details
D2: Purchase No | E2: Qty. | F2: Basic Rate | G2: Purchase Rate | H2: Basic Rate Amount | I2: Purchase Rate Amount | J2: Excess Amount | K2: Saving Amount
A3: 1 | B3: Cement Bags | C3: UltraTech Cement Limited | D3: 1st Purchase | E3: 600 | F3: 280 | G3: =161718.9/600 -> 269.5315 | H3: =E3*F3 -> 168000 | I3: =E3*G3 -> 161718.9 | J3: =IF(G3>F3,(G3-F3)*E3,0) -> 0 | K3: =IF(F3>G3,(F3-G3)*E3,0) -> 6281.1
A4: 2 | B4: Cement Bags | C4: UltraTech Cement Limited | D4: 1st Purchase | E4: 600 | F4: 280 | G4: =159375/600 -> 265.625 | H4: =E4*F4 -> 168000 | I4: =E4*G4 -> 159375 | J4: =IF(G4>F4,(G4-F4)*E4,0) -> 0 | K4: =IF(F4>G4,(F4-G4)*E4,0) -> 8625
A5: 3 | B5: Cement Bags | C5: UltraTech Cement Limited | D5: 2nd Purchase | E5: 700 | F5: 280 | G5: 253.9065 | H5: =E5*F5 -> 196000 | I5: =E5*G5 -> 177734.55 | J5: =IF(G5>F5,(G5-F5)*E5,0) -> 0 | K5: =IF(F5>G5,(F5-G5)*E5,0) -> 18265.45
A6: 4 | B6: Cement Bags | C6: UltraTech Cement Limited | D6: 3rd Purchase | E6: 700 | F6: 280 | G6: =169067.85/700 -> 241.5255 | H6: =E6*F6 -> 196000 | I6: =E6*G6 -> 169067.85 | J6: =IF(G6>F6,(G6-F6)*E6,0) -> 0 | K6: =IF(F6>G6,(F6-G6)*E6,0) -> 26932.15
A7: 5 | B7: Cement Bags | C7: UltraTech Cement Limited | D7: 3rd Purchase | E7: 700 | F7: 280 | G7: =166101.6/700 -> 237.288 | H7: =E7*F7 -> 196000 | I7: =E7*G7 -> 166101.6 | J7: =IF(G7>F7,(G7-F7)*E7,0) -> 0 | K7: =IF(F7>G7,(F7-G7)*E7,0) -> 29898.4
A8: 6 | B8: Cement Bags | C8: UltraTech Cement Limited | D8: 4th Purchase | E8: 600 | F8: 280 | G8: =139830.6/600 -> 233.051 | H8: =E8*F8 -> 168000 | I8: =E8*G8 -> 139830.6 | J8: =IF(G8>F8,(G8-F8)*E8,0) -> 0 | K8: =IF(F8>G8,(F8-G8)*E8,0) -> 28169.4
A9: 7 | B9: Cement Bags | C9: UltraTech Cement Limited | D9: 4th Purchase | E9: 600 | F9: 280 | G9: =137288.1/600 -> 228.8135 | H9: =E9*F9 -> 168000 | I9: =E9*G9 -> 137288.1 | J9: =IF(G9>F9,(G9-F9)*E9,0) -> 0 | K9: =IF(F9>G9,(F9-G9)*E9,0) -> 30711.9
A10: Total : - | E10: =SUM(E3:E9) -> 4500 | H10: =SUM(H3:H9) -> 1260000 | I10: =SUM(I3:I9) -> 1111116.6 | J10: =SUM(J3:J7) -> 0 | K10: =SUM(K3:K9) -> 148883.4 | L10: =K10/100000 -> 1.488834
