Workbook
Name Actual: (PeriodInActual*(#REF!>0))*PeriodInPlan
Name Actual: (PeriodInActual*(#REF!>0))*PeriodInPlan
Name ActualBeyond: PeriodInActual*(#REF!>0)
Name ActualBeyond: PeriodInActual*(#REF!>0)
Name fcc: '[1]Additional Calc.'!$B$18
Name fsc: '[1]Additional Calc.'!$B$17
Name Mul: '[1]Additional Calc.'!$B$15
Name PercentComplete: PercentCompleteBeyond*PeriodInPlan
Name PercentComplete: PercentCompleteBeyond*PeriodInPlan
Name PercentCompleteBeyond: (#REF!=MEDIAN(#REF!,#REF!,#REF!+#REF!)*(#REF!>0))*((#REF!<(INT(#REF!+#REF!*#REF!)))+(#REF!=#REF!))*(#REF!>0)
Name period_selected: #REF!
Name PeriodInActual: #REF!=MEDIAN(#REF!,#REF!,#REF!+#REF!-1)
Name PeriodInPlan: #REF!=MEDIAN(#REF!,#REF!,#REF!+#REF!-1)
Name Plan: PeriodInPlan*(#REF!>0)
Name Plan: PeriodInPlan*(#REF!>0)
Name Ptl: '[1]Additional Calc.'!$B$16
Name TaxTV: 10%
Name TaxXL: 5%
Name TitleRegion..BO60: #REF!

Sheet Dashboard
A1: Planned Vs. Actual Report - Project # - Week 13
A6: Project Timeline | G6: Planned Vs. Actual Manpower Top 3 Manpower Shortage Categories this week | S6: Planned Vs. Actual Cashflow
A8: Project Start Date | D8: 45809 | G8: Sr. No. | I8: Category | M8: Reason for Shortage
A9: Planned End Date | D9: 46203 | G9: 1 | I9: =_xlfn.XLOOKUP(G9,'Weekly Manpower'!$G$4:$G$14,'Weekly Manpower'!$B$4:$B$14,0) -> Reinforcement work | M9: Unavailibility of Manpower
A10: Current Date | D10: =TODAY() -> 46053 | G10: 2 | I10: =_xlfn.XLOOKUP(G10,'Weekly Manpower'!$G$4:$G$14,'Weekly Manpower'!$B$4:$B$14,0) -> Plumbing | M10: Vendor not responding
A11: Project Progress | D11: =(D10-D8)/(D9-D8) -> 0.61928934 | G11: 3 | I11: =_xlfn.XLOOKUP(G11,'Weekly Manpower'!$G$4:$G$14,'Weekly Manpower'!$B$4:$B$14,0) -> Tiles Work | M11: Unavailibility of Manpower
A30: Planned Vs. Actual Quantity
Q52: Past Vs. Current Progress
Q54: Last Week Status | Y54: Current Week Status

Sheet Weekly Manpower
B3: Type of Manpower | C3: Required Manpower for week | D3: Available | E3: Shortage | F3: % Shortage | G3: Rank | AI3: Safety NCR | AL3: Unsafe Act | AO3: Condition
B4: Reinforcement work | C4: =C63 -> 120 | D4: =C52 -> 65 | E4: =C4-D4 -> 55 | F4: =E4/C4 -> 0.45833333 | G4: =RANK(F4,$F$4:$F$14) -> 1 | AI4: Total | AJ4: Open | AK4: Close | AL4: Total | AM4: Open | AN4: Close | AO4: Total | AP4: Open | AQ4: Close
B5: Carpenter | C5: =D63 -> 125 | D5: =D52 -> 100 | E5: =C5-D5 -> 25 | F5: =E5/C5 -> 0.2 | G5: =RANK(F5,$F$4:$F$14) -> 9 | AI5: 2 | AJ5: 1 | AK5: 2 | AL5: 10 | AM5: 0 | AN5: 10 | AO5: 10 | AP5: 1 | AQ5: 9
B6: Mason | C6: =E63 -> 105 | D6: =E52 -> 79 | E6: =C6-D6 -> 26 | F6: =E6/C6 -> 0.24761905 | G6: =RANK(F6,$F$4:$F$14) -> 8
B7: Helper | C7: =F63 -> 116 | D7: =F52 -> 83 | E7: =C7-D7 -> 33 | F7: =E7/C7 -> 0.28448276 | G7: =RANK(F7,$F$4:$F$14) -> 7
B8: Unskilled Worker | C8: =G63 -> 315 | D8: =G52 -> 203 | E8: =C8-D8 -> 112 | F8: =E8/C8 -> 0.35555556 | G8: =RANK(F8,$F$4:$F$14) -> 4 | AI8: NCR | AL8: Site Observation | AO8: Site Instructions
B9: Drivers | C9: =H63 -> 13 | D9: =H52 -> 13 | E9: =C9-D9 -> 0 | F9: =E9/C9 -> 0 | G9: =RANK(F9,$F$4:$F$14) -> 10 | AI9: Total | AJ9: Open | AK9: Close | AL9: Total | AM9: Open | AN9: Close | AO9: Total | AP9: Open | AQ9: Close
B10: Staff | C10: =I63 -> 33 | D10: =I52 -> 33 | E10: =C10-D10 -> 0 | F10: =E10/C10 -> 0 | G10: =RANK(F10,$F$4:$F$14) -> 10 | AI10: 1 | AJ10: 0 | AK10: 1 | AL10: 38 | AM10: 2 | AN10: 36 | AO10: 41 | AP10: 2 | AQ10: 39
B11: Plumbing | C11: =J63 -> 10 | D11: =J52 -> 6 | E11: =C11-D11 -> 4 | F11: =E11/C11 -> 0.4 | G11: =RANK(F11,$F$4:$F$14) -> 2
B12: Tiles Work | C12: =K63 -> 48 | D12: =K52 -> 30 | E12: =C12-D12 -> 18 | F12: =E12/C12 -> 0.375 | G12: =RANK(F12,$F$4:$F$14) -> 3
B13: Painter | C13: =L63 -> 21 | D13: =L52 -> 15 | E13: =C13-D13 -> 6 | F13: =E13/C13 -> 0.28571429 | G13: =RANK(F13,$F$4:$F$14) -> 6
B14: Electric Work | C14: =M63 -> 32 | D14: =M52 -> 22 | E14: =C14-D14 -> 10 | F14: =E14/C14 -> 0.3125 | G14: =RANK(F14,$F$4:$F$14) -> 5
B15: Total of Above | C15: =SUM(C4:C14) -> 938 | D15: =SUM(D4:D14) -> 649 | E15: =SUM(E4:E14) -> 289
B36: Available | O36: Available
B37: Date | C37: Rein. work | D37: Carpenter | E37: Mason | F37: Helper | G37: Unskilled | H37: Drivers | I37: staff | J37: Plumbing | K37: Tiles | L37: Painter | M37: Ele. | O37: Date | P37: Rein. work | Q37: Carpenter | R37: Mason | S37: Helper | T37: Unskilled | U37: Drivers | V37: staff
B38: 46002 | C38: 12 | D38: 10 | E38: 12 | F38: 14 | G38: 28 | H38: 1 | I38: 5 | J38: 2 | K38: 5 | L38: 2 | M38: 3 | O38: 45953 | P38: 0 | Q38: 5 | R38: 0 | S38: 3 | T38: 1 | U38: 0 | V38: 0
B39: Night | C39: 0 | D39: 0 | E39: 0 | F39: 0 | G39: 0 | H39: 0 | I39: 0 | J39: 0 | K39: 0 | L39: 0 | M39: 0 | O39: Night | P39: 0 | Q39: 0 | R39: 0 | S39: 0 | T39: 0 | U39: 0 | V39: 0
B40: 46003 | C40: 10 | D40: 7 | E40: 11 | F40: 8 | G40: 29 | H40: 1 | I40: 5 | J40: 2 | K40: 5 | L40: 2 | M40: 5 | O40: 45954 | P40: 0 | Q40: 5 | R40: 0 | S40: 3 | T40: 1 | U40: 0 | V40: 1
B41: Night | C41: 0 | D41: 0 | E41: 0 | F41: 0 | G41: 0 | H41: 0 | I41: 0 | J41: 0 | K41: 0 | L41: 0 | M41: 0 | O41: Night | P41: 0 | Q41: 0 | R41: 0 | S41: 0 | T41: 0 | U41: 0 | V41: 0
B42: 46004 | C42: 3 | D42: 14 | E42: 12 | F42: 8 | G42: 29 | H42: 1 | I42: 5 | J42: 2 | K42: 5 | L42: 2 | M42: 2 | O42: 45955 | P42: 0 | Q42: 10 | R42: 0 | S42: 8 | T42: 14 | U42: 1 | V42: 2
B43: Night | C43: 0 | D43: 0 | E43: 0 | F43: 0 | G43: 0 | H43: 0 | I43: 0 | J43: 0 | K43: 0 | L43: 0 | M43: 0 | O43: Night | P43: 0 | Q43: 0 | R43: 0 | S43: 0 | T43: 0 | U43: 0 | V43: 0
B44: 46005 | C44: 2 | D44: 14 | E44: 12 | F44: 7 | G44: 28 | H44: 1 | I44: 3 | J44: 0 | K44: 3 | L44: 3 | M44: 2 | O44: 45956 | P44: 0 | Q44: 10 | R44: 0 | S44: 8 | T44: 5 | U44: 1 | V44: 0
B45: Night | C45: 0 | D45: 0 | E45: 0 | F45: 0 | G45: 0 | H45: 0 | I45: 0 | J45: 0 | K45: 0 | L45: 0 | M45: 0 | O45: Night | P45: 0 | Q45: 0 | R45: 0 | S45: 0 | T45: 0 | U45: 0 | V45: 0
B46: 46006 | C46: 14 | D46: 25 | E46: 12 | F46: 11 | G46: 28 | H46: 1 | I46: 5 | J46: 0 | K46: 3 | L46: 3 | M46: 3 | O46: 45957 | P46: 0 | Q46: 5 | R46: 0 | S46: 4 | T46: 3 | U46: 1 | V46: 4
B47: Night | C47: 0 | D47: 0 | E47: 0 | F47: 0 | G47: 0 | H47: 0 | I47: 0 | J47: 0 | K47: 0 | L47: 0 | M47: 0 | O47: Night | P47: 0 | Q47: 0 | R47: 0 | S47: 0 | T47: 0 | U47: 0 | V47: 0
B48: 46007 | C48: 14 | D48: 15 | E48: 10 | F48: 16 | G48: 30 | H48: 4 | I48: 6 | J48: 0 | K48: 3 | L48: 3 | M48: 3 | O48: 45958 | P48: 3 | Q48: 5 | R48: 1 | S48: 8 | T48: 3 | U48: 1 | V48: 6
B49: Night | C49: 0 | D49: 0 | E49: 0 | F49: 0 | G49: 0 | H49: 0 | I49: 0 | J49: 0 | K49: 0 | L49: 0 | M49: 0 | O49: Night | P49: 0 | Q49: 0 | R49: 0 | S49: 0 | T49: 0 | U49: 0 | V49: 0
B50: 46008 | C50: 10 | D50: 15 | E50: 10 | F50: 19 | G50: 31 | H50: 4 | I50: 4 | J50: 0 | K50: 6 | L50: 0 | M50: 4 | O50: 45959 | P50: 3 | Q50: 5 | R50: 1 | S50: 8 | T50: 12 | U50: 1 | V50: 5
B51: Night | C51: 0 | D51: 0 | E51: 0 | F51: 0 | G51: 0 | H51: 0 | I51: 0 | J51: 0 | K51: 0 | L51: 0 | M51: 0 | O51: Night | P51: 0 | Q51: 0 | R51: 0 | S51: 0 | T51: 0 | U51: 0 | V51: 0
B52: Total | C52: =SUM(C38:C51) -> 65 | D52: =SUM(D38:D51) -> 100 | E52: =SUM(E38:E51) -> 79 | F52: =SUM(F38:F51) -> 83 | G52: =SUM(G38:G51) -> 203 | H52: =SUM(H38:H51) -> 13 | I52: =SUM(I38:I51) -> 33 | J52: =SUM(J38:J51) -> 6 | ... M52: =SUM(M38:M51) -> 22 | O52: Total | P52: =SUM(P38:P51) -> 6 | Q52: =SUM(Q38:Q51) -> 45 | R52: =SUM(R38:R51) -> 2 | S52: =SUM(S38:S51) -> 42 | T52: =SUM(T38:T51) -> 39 | U52: =SUM(U38:U51) -> 5 | V52: =SUM(V38:V51) -> 18
B54: Required | O54: Required
B55: Date | C55: Rein. work | D55: Carpenter | E55: Mason | F55: Helper | G55: Unskilled | H55: Drivers | I55: staff | J55: Plumbing | K55: Tiles | L55: Painter | M55: Ele | O55: Date | P55: Rein. work | Q55: Carpenter | R55: Mason | S55: Helper | T55: Unskilled | U55: Drivers | V55: staff
B56: 45995 | C56: 20 | D56: 15 | E56: 15 | F56: 15 | G56: 45 | H56: 1 | I56: 5 | J56: 2 | K56: 5 | L56: 3 | M56: 4 | O56: 45953 | P56: 10 | Q56: 8 | R56: 2 | S56: 4 | T56: 6 | U56: 5 | V56: 6
B57: 45996 | C57: 15 | D57: 15 | E57: 15 | F57: 16 | G57: 45 | H57: 1 | I57: 5 | J57: 2 | K57: 5 | L57: 3 | M57: 4 | O57: 45954 | P57: 10 | Q57: 8 | R57: 2 | S57: 4 | T57: 6 | U57: 4 | V57: 5
B58: 45997 | C58: 15 | D58: 15 | E58: 15 | F58: 15 | G58: 45 | H58: 1 | I58: 5 | J58: 2 | K58: 6 | L58: 3 | M58: 4 | O58: 45955 | P58: 10 | Q58: 8 | R58: 2 | S58: 4 | T58: 6 | U58: 4 | V58: 5
B59: 45998 | C59: 15 | D59: 20 | E59: 15 | F59: 16 | G59: 45 | H59: 1 | I59: 3 | J59: 2 | K59: 8 | L59: 3 | M59: 4 | O59: 45956 | P59: 10 | Q59: 8 | R59: 2 | S59: 4 | T59: 6 | U59: 4 | V59: 5
B60: 45999 | C60: 15 | D60: 20 | E60: 15 | F60: 18 | G60: 45 | H60: 1 | I60: 5 | J60: 2 | K60: 8 | L60: 3 | M60: 4 | O60: 45957 | P60: 10 | Q60: 8 | R60: 2 | S60: 4 | T60: 6 | U60: 2 | V60: 6
B61: 46000 | C61: 20 | D61: 20 | E61: 15 | F61: 18 | G61: 45 | H61: 4 | I61: 6 | J61: 0 | K61: 8 | L61: 3 | M61: 6 | O61: 45958 | P61: 10 | Q61: 8 | R61: 2 | S61: 4 | T61: 6 | U61: 2 | V61: 7
B62: 46001 | C62: 20 | D62: 20 | E62: 15 | F62: 18 | G62: 45 | H62: 4 | I62: 4 | J62: 0 | K62: 8 | L62: 3 | M62: 6 | O62: 45959 | P62: 10 | Q62: 8 | R62: 2 | S62: 4 | T62: 6 | U62: 2 | V62: 6
B63: Total | C63: =SUM(C56:C62) -> 120 | D63: =SUM(D56:D62) -> 125 | E63: =SUM(E56:E62) -> 105 | F63: =SUM(F56:F62) -> 116 | G63: =SUM(G56:G62) -> 315 | H63: =SUM(H56:H62) -> 13 | I63: =SUM(I56:I62) -> 33 | J63: =SUM(J56:J62) -> 10 | ... M63: =SUM(M56:M62) -> 32 | O63: Total | P63: =SUM(P56:P62) -> 70 | Q63: =SUM(Q56:Q62) -> 56 | R63: =SUM(R56:R62) -> 14 | S63: =SUM(S56:S62) -> 28 | T63: =SUM(T56:T62) -> 42 | U63: 5 | V63: =SUM(V56:V62) -> 40

Sheet Project Cashflow 
B3: Month | D3: Budgeted work | E3: Planned Work | F3: Actual Work
B4: August | C4: RA 01 | E4: 5000000 | F4: 1063955
B5: September | C5: RA 02 | E5: 7200000 | F5: 7797193
B6: October | C6: RA 03 | E6: 5000000 | F6: 168333
B7: November | C7: RA 04 | E7: 7500000 | F7: =1387400+988771 -> 2376171
B8: December | C8: RA 05 | E8: 8000000 | F8: =5179149+5925704 -> 11104853
B9: January | C9: RA 06 | E9: 9000000
B10: February | C10: RA 07 | E10: 8000000
B11: March | C11: RA 08 | E11: 8000000
E12: =SUM(E4:E11) -> 57700000
B18: Month | E18: January
B19: Planned
B20: Actual

Sheet Planned Vs Actual 
A3: Planned Vs Actual Previous Week to Current Week (Date: 11-12-2025 to 17-12-2025)
A5: Description | G5: Qty Planed | N5: Against GFC | O5: Agianst Weekly Planed | Q5: Cumlative | R5: Cumlative
A6: Sr.No. | B6: Tower | C6: Activity | D6: Planned Start Date by Contractor | E6: Planned End Date by Contractor | F6: Unit | G6: As per BOQ total Quantity | H6: Total GFC Qty | I6: Executed qty till 15-10-2025 | J6: Balance Qty. | K6: Weekly planned Qty. | L6: Weekly actual Qty. | M6: Cumulative Qty. | N6: % Balance Qty ( Remaining ) Against GFC Qty | O6: % Planned Against Balance Qty | P6: % Achieved Against Actual Qty | Q6: % Completed (Total against the GFC ) | R6: % Completed (Total against the GFC )
A7: 1 | B7: Upto Plinth | C7: Excavation | D7: 46002 | E7: 46008 | F7: CUM | G7: 3925 | H7: 1826 | I7: 1826.2 | J7: =H7-I7 -> -0.2 | K7: 0 | L7: 0 | M7: =L7+I7 -> 1826.2 | N7: =J7/H7 -> -0.00010952903 | O7: 0 | P7: 0 | Q7: Delay | R7: =M7/H7 -> 1.0001095
A8: 2 | C8: Footing PCC | D8: 46002 | E8: 46008 | F8: CUM | G8: 265 | H8: 91.31 | I8: 91.31 | J8: =H8-I8 -> 0 | K8: 0 | L8: 0 | M8: =L8+I8 -> 91.31 | N8: =J8/H8 -> 0 | O8: 0 | P8: 0 | Q8: On time | R8: =M8/H8 -> 1
A9: 3 | C9: Yellow Soil Filling | D9: 46002 | E9: 46008 | F9: CUM | G9: 10000 | H9: 1123.22 | I9: 1123.22 | J9: =H9-I9 -> 0 | K9: 0 | L9: 0 | M9: =L9+I9 -> 1123.22 | N9: =J9/H9 -> 0 | O9: 0 | P9: 0 | R9: =M9/H9 -> 1
A10: 4 | C10: Rubble Soling | D10: 46002 | E10: 46008 | F10: CUM | G10: 195.5 | H10: 173.81 | I10: 173.81 | J10: =H10-I10 -> 0 | K10: 0 | L10: 0 | M10: =L10+I10 -> 173.81 | N10: =J10/H10 -> 0 | O10: 0 | P10: 0 | R10: =M10/H10 -> 1
A11: 5 | C11: Footing Shuttering | D11: 46002 | E11: 46008 | F11: SMT | G11: 1075 | H11: 441.908 | I11: 441.91 | J11: =H11-I11 -> -0.002 | K11: 0 | L11: 0 | M11: =L11+I11 -> 441.91 | N11: =J11/H11 -> -4.5258289e-06 | O11: 0 | P11: 0 | R11: =M11/H11 -> 1.0000045 | XFD11: =SUM(A11:XFC11) -> 94416.726
A12: 6 | C12: Footing RCC | D12: 46002 | E12: 46008 | F12: CUM | G12: 380 | H12: 292.764 | I12: 292.76 | J12: =H12-I12 -> 0.004 | K12: 0 | L12: 0 | M12: =L12+I12 -> 292.76 | N12: =J12/H12 -> 1.3662882e-05 | O12: 0 | P12: 0 | Q12: On time | R12: =M12/H12 -> 0.99998634
A13: 7 | C13: Padestal Upto Plinth Top Shuttering | D13: 46002 | E13: 46008 | F13: SMT | G13: 1075 | H13: 664 | I13: 664 | J13: =H13-I13 -> 0 | K13: 0 | L13: 0 | M13: =L13+I13 -> 664 | N13: =J13/H13 -> 0 | O13: 0 | P13: 0 | R13: =M13/H13 -> 1
A14: 8 | C14: Padestal Upto Plinth Top RCC | D14: 46002 | E14: 46008 | F14: CUM | G14: 380 | H14: 62.65 | I14: 62.65 | J14: =H14-I14 -> 0 | K14: 0 | L14: 0 | M14: =L14+I14 -> 62.65 | N14: =J14/H14 -> 0 | O14: 0 | P14: 0 | R14: =M14/H14 -> 1
A15: 9 | C15: GB Excavation | D15: 46002 | E15: 46008 | F15: CUM | G15: 3925 | H15: 11.795 | I15: 11.795 | J15: =H15-I15 -> 0 | K15: 0 | L15: 0 | M15: =L15+I15 -> 11.795 | N15: =J15/H15 -> 0 | O15: 0 | P15: 0 | R15: =M15/H15 -> 1
A16: 10 | C16: GB PCC | D16: 46002 | E16: 46008 | F16: CUM | G16: 265 | H16: 7.944 | I16: 7.944 | J16: =H16-I16 -> 0 | K16: 0 | L16: 0 | M16: =L16+I16 -> 7.944 | N16: =J16/H16 -> 0 | O16: 0 | P16: 0 | R16: =M16/H16 -> 1
A17: 11 | C17: GB Shuttering | D17: 46002 | E17: 46008 | F17: SMT | G17: 1075 | H17: 142.938 | I17: 142.85 | J17: =H17-I17 -> 0.088 | K17: 0 | L17: 0 | M17: =L17+I17 -> 142.85 | N17: =J17/H17 -> 0.00061565154 | O17: 0 | P17: 0 | R17: =M17/H17 -> 0.99938435
A18: 12 | C18: GB RCC | D18: 46002 | E18: 46008 | F18: CUM | G18: 380 | H18: 23.994 | I18: 23.98 | J18: =H18-I18 -> 0.014 | K18: 0 | L18: 0 | M18: =L18+I18 -> 23.98 | N18: =J18/H18 -> 0.0005834792 | O18: 0 | P18: 0 | R18: =M18/H18 -> 0.99941652
A19: 13 | C19: Masonry Above GB | D19: 46002 | E19: 46008 | F19: CUM | G19: 130 | H19: 86.294 | I19: 86.294 | J19: =H19-I19 -> 0 | K19: 0 | L19: 0 | M19: =L19+I19 -> 86.294 | N19: =J19/H19 -> 0 | O19: 0 | P19: 0 | R19: =M19/H19 -> 1
A20: 14 | C20: Plinth Beam PCC | D20: 46002 | E20: 46008 | F20: CUM | G20: 265 | H20: 18.07 | I20: 18.07 | J20: =H20-I20 -> 0 | K20: 0 | L20: 0 | M20: =L20+I20 -> 18.07 | N20: =J20/H20 -> 0 | O20: 0 | P20: 0 | R20: =M20/H20 -> 1
A21: 15 | C21: Plinth Beam Shuttering | D21: 46002 | E21: 46008 | F21: SMT | G21: 1075 | H21: 387.1 | I21: 387.1 | J21: =H21-I21 -> 0 | K21: 0 | L21: 0 | M21: =L21+I21 -> 387.1 | N21: =J21/H21 -> 0 | O21: 0 | P21: 0 | R21: =M21/H21 -> 1
A22: 16 | C22: Plinth Beam RCC | D22: 46002 | E22: 46008 | F22: CUM | G22: 380 | H22: 45.72 | I22: 45.72 | J22: =H22-I22 -> 0 | K22: 0 | L22: 0 | M22: =L22+I22 -> 45.72 | N22: =J22/H22 -> 0 | O22: 0 | P22: 0 | R22: =M22/H22 -> 1
A23: 17 | C23: Plinth Plaster | D23: 46002 | E23: 46008 | F23: SMT | G23: 5235 | H23: 92.29 | I23: 59.5 | J23: =H23-I23 -> 32.79 | K23: =J23 -> 32.79 | L23: 15 | M23: =L23+I23 -> 74.5 | N23: =J23/H23 -> 0.3552931 | O23: =K23/J23 -> 1 | P23: =L23/J23 -> 0.45745654 | R23: =M23/H23 -> 0.80723805
A24: 18 | C24: Masonry above PB | D24: 46002 | E24: 46008 | F24: CUM | G24: 130 | H24: 16.168 | I24: 16.17 | J24: =H24-I24 -> -0.002 | K24: 0 | L24: 0 | M24: =L24+I24 -> 16.17 | N24: =J24/H24 -> -0.00012370114 | O24: 0 | P24: 0 | R24: =M24/H24 -> 1.0001237
A25: 19 | C25: Floor PCC | D25: 46002 | E25: 46008 | F25: CUM | G25: 265 | H25: 86.9 | I25: 86.9 | J25: =H25-I25 -> 0 | K25: 0 | L25: 0 | M25: =L25+I25 -> 86.9 | N25: =J25/H25 -> 0 | O25: 0 | P25: 0 | R25: =M25/H25 -> 1
A26: 20 | C26: Floor RCC Shuttering | D26: 46002 | E26: 46008 | F26: SMT | G26: 1075 | H26: 15.3 | I26: 15.3 | J26: =H26-I26 -> 0 | K26: =J26 -> 0 | L26: =K26 -> 0 | M26: =L26+I26 -> 15.3 | N26: =J26/H26 -> 0 | O26: 0 | P26: 0 | R26: =M26/H26 -> 1
A27: 21 | C27: Floor RCC | D27: 46002 | E27: 46008 | F27: CUM | G27: 380 | H27: 88.03 | I27: 88.03 | J27: =H27-I27 -> 0 | K27: =J27 -> 0 | L27: =K27 -> 0 | M27: =L27+I27 -> 88.03 | N27: =J27/H27 -> 0 | O27: 0 | P27: 0 | R27: =M27/H27 -> 1
A28: Avreage Achivement : - | O28: =+AVERAGE(O7:O27) -> 0.047619048 | P28: =+AVERAGE(P7:P27) -> 0.021783645 | Q28: =+AVERAGE(Q7:Q25) -> #DIV/0! | R28: =+AVERAGE(R7:R27) -> 0.99077443
A29: 22 | B29: Ground Floor | C29: Plinth to GF slab column shuttering | D29: 46002 | E29: 46008 | F29: SQM | G29: 1680 | H29: 427.55 | I29: 427.554 | J29: =H29-I29 -> -0.004 | K29: 0 | L29: 0 | M29: =L29+I29 -> 427.554 | N29: =J29/H29 -> -9.3556309e-06 | O29: =K29/J29 -> 0 | P29: =L29/J29 -> 0 | R29: =M29/H29 -> 1.0000094
A30: 23 | C30: GF beam shuttering | D30: 46002 | E30: 46008 | F30: SQM | H30: 700.59 | I30: 700.59 | J30: =H30-I30 -> 0 | K30: 0 | L30: 0 | M30: =L30+I30 -> 700.59 | N30: =J30/H30 -> 0 | O30: 0 | P30: 0 | R30: =M30/H30 -> 1
A31: 24 | C31: GF Slab shuttering | D31: 46002 | E31: 46008 | F31: SQM | H31: 664.26 | I31: 664.23 | J31: =H31-I31 -> 0.03 | K31: 0 | L31: 0 | M31: =L31+I31 -> 664.23 | N31: =J31/H31 -> 4.5163039e-05 | O31: 0 | P31: 0 | R31: =M31/H31 -> 0.99995484
A32: 25 | C32: GF staircase shuttering | D32: 46002 | E32: 46008 | F32: SQM | H32: 57.39 | I32: 57.39 | J32: =H32-I32 -> 0 | K32: 0 | L32: 0 | M32: =L32+I32 -> 57.39 | N32: =J32/H32 -> 0 | O32: 0 | P32: 0 | R32: =M32/H32 -> 1
A33: 26 | C33: GF lintel shuttering | D33: 46002 | E33: 46008 | F33: SQM | H33: 67.99 | I33: 56 | J33: =H33-I33 -> 11.99 | K33: 0 | L33: 0 | M33: =L33+I33 -> 56 | N33: =J33/H33 -> 0.17634946 | O33: =K33/J33 -> 0 | P33: =L33/J33 -> 0 | R33: =M33/H33 -> 0.82365054
A34: 27 | C34: Plinth to GF slab column concrete | D34: 46002 | E34: 46008 | F34: CUM | G34: 210 | H34: 32.822 | I34: 32.82 | J34: =H34-I34 -> 0.002 | K34: 0 | L34: 0 | M34: =L34+I34 -> 32.82 | N34: =J34/H34 -> 6.0934739e-05 | O34: =K34/J34 -> 0 | P34: =L34/J34 -> 0 | R34: =M34/H34 -> 0.99993907
A35: 28 | C35: GF beam Concrete | D35: 46002 | E35: 46008 | F35: CUM | H35: 61.76 | I35: 61.75 | J35: =H35-I35 -> 0.01 | K35: 0 | L35: 0 | M35: =L35+I35 -> 61.75 | N35: =J35/H35 -> 0.0001619171 | O35: =K35/J35 -> 0 | P35: =L35/J35 -> 0 | R35: =M35/H35 -> 0.99983808
A36: 29 | C36: GF Slab Concrete | D36: 46002 | E36: 46008 | F36: CUM | H36: 101.99 | I36: 101.98 | J36: =H36-I36 -> 0.01 | K36: 0 | L36: 0 | M36: =L36+I36 -> 101.98 | N36: =J36/H36 -> 9.8048828e-05 | O36: =K36/J36 -> 0 | P36: =L36/J36 -> 0 | R36: =M36/H36 -> 0.99990195
A37: 30 | C37: GF staircase concrete | D37: 46002 | E37: 46008 | F37: CUM | H37: 8.53 | I37: 8.52 | J37: =H37-I37 -> 0.01 | K37: 0 | L37: 0 | M37: =L37+I37 -> 8.52 | N37: =J37/H37 -> 0.0011723329 | O37: =K37/J37 -> 0 | P37: =L37/J37 -> 0 | R37: =M37/H37 -> 0.99882767
A38: 31 | C38: GF lintel Concrete | D38: 46002 | E38: 46008 | F38: CUM | H38: 3.91 | I38: 2 | J38: =H38-I38 -> 1.91 | K38: 0 | L38: 0 | M38: =L38+I38 -> 2 | N38: =J38/H38 -> 0.48849105 | O38: =K38/J38 -> 0 | P38: =L38/J38 -> 0 | R38: =M38/H38 -> 0.51150895
A39: 32 | C39: Brick masonary GF (230 mm) | D39: 46002 | E39: 46008 | F39: CUM | G39: 80 | H39: 73.48 | I39: 36.86 | J39: =H39-I39 -> 36.62 | K39: 20 | L39: 7 | M39: =L39+I39 -> 43.86 | N39: =J39/H39 -> 0.4983669 | O39: =K39/J39 -> 0.54614965 | P39: =L39/J39 -> 0.19115238 | R39: =M39/H39 -> 0.59689711
A40: 33 | C40: Brick masonary GF (115 mm) | D40: 46002 | E40: 46008 | F40: SMT | G40: 1170 | H40: 768 | I40: 346.26 | J40: =H40-I40 -> 421.74 | K40: 100 | L40: 10 | M40: =L40+I40 -> 356.26 | N40: =J40/H40 -> 0.54914063 | O40: =K40/J40 -> 0.23711291 | P40: =L40/J40 -> 0.023711291 | R40: =M40/H40 -> 0.46388021
A41: 34 | C41: Internal Plaster | D41: 46002 | E41: 46008 | F41: SMT | G41: 1591.21 | H41: 1733.79 | I41: 362 | J41: =H41-I41 -> 1371.79 | K41: 600 | L41: 301 | M41: =L41+I41 -> 663 | N41: =J41/H41 -> 0.79120885 | O41: =K41/J41 -> 0.43738473 | P41: =L41/J41 -> 0.21942134 | R41: =M41/H41 -> 0.38239925
A42: 35 | C42: Flooring | D42: 46002 | E42: 46008 | F42: SMT | G42: 830 | H42: 841.16 | I42: 0 | J42: =H42-I42 -> 841.16 | K42: 100 | L42: 55.15 | M42: =L42+I42 -> 55.15 | N42: =J42/H42 -> 1 | O42: =K42/J42 -> 0.11888345 | P42: =L42/J42 -> 0.065564221 | R42: =M42/H42 -> 0.065564221
A43: 36 | C43: Skirting | D43: 46002 | E43: 46008 | F43: RMT | G43: 1865 | H43: 1859.2 | I43: 0 | J43: =H43-I43 -> 1859.2 | K43: 100 | L43: 45 | M43: =L43+I43 -> 45 | N43: =J43/H43 -> 1 | O43: =K43/J43 -> 0.053786575 | P43: =L43/J43 -> 0.024203959 | R43: =M43/H43 -> 0.024203959
...

Sheet As per drawing status
A1: Weekly Executed Plan
A3: Sr.No. | B3: Tower | C3: Activity | D3: Unit | E3: As per BOQ total Quantity | F3: As per GFC total Quantity | G3: Weekly planned Qty. | H3: Weekly actual Qty. | I3: Total Achieved Qty.
A4: 1 | B4: Worker Dormitory | C4: Footing Excavation | D4: CUM | E4: ='Planned Vs Actual '!G7 -> 3925 | F4: ='Planned Vs Actual '!H7 -> 1826 | G4: ='Planned Vs Actual '!K7 -> 0 | H4: ='Planned Vs Actual '!L7 -> 0 | I4: ='Planned Vs Actual '!M7 -> 1826.2
A5: 2 | B5: Worker Dormitory | C5: GB Excavation | D5: CUM | F5: ='Planned Vs Actual '!H15 -> 11.795 | G5: ='Planned Vs Actual '!K15 -> 0 | H5: ='Planned Vs Actual '!L15 -> 0 | I5: ='Planned Vs Actual '!M15 -> 11.795
A6: 3 | B6: Worker Dormitory | C6: Yellow Soil Filling | D6: CUM | E6: ='Planned Vs Actual '!G9 -> 10000 | F6: ='Planned Vs Actual '!H9 -> 1123.22 | G6: ='Planned Vs Actual '!K9 -> 0 | H6: ='Planned Vs Actual '!L9 -> 0 | I6: ='Planned Vs Actual '!M9 -> 1123.22
A7: 4 | B7: Worker Dormitory | C7: ='Planned Vs Actual '!C10 -> Rubble Soling | D7: CUM | E7: ='Planned Vs Actual '!G10 -> 195.5 | F7: ='Planned Vs Actual '!H10 -> 173.81 | G7: ='Planned Vs Actual '!K10 -> 0 | H7: ='Planned Vs Actual '!L10 -> 0 | I7: ='Planned Vs Actual '!M10 -> 173.81
A8: 5 | B8: Worker Dormitory | C8: Footing PCC | D8: CUM | E8: ='Planned Vs Actual '!G8 -> 265 | F8: ='Planned Vs Actual '!H8 -> 91.31 | G8: ='Planned Vs Actual '!K8 -> 0 | H8: ='Planned Vs Actual '!L8 -> 0 | I8: ='Planned Vs Actual '!M8 -> 91.31
A9: 6 | B9: Worker Dormitory | C9: GB PCC | D9: CUM | F9: ='Planned Vs Actual '!H16 -> 7.944 | G9: ='Planned Vs Actual '!K16 -> 0 | H9: ='Planned Vs Actual '!L16 -> 0 | I9: ='Planned Vs Actual '!M16 -> 7.944
A10: 7 | B10: Worker Dormitory | C10: ='Planned Vs Actual '!C25 -> Floor PCC | D10: ='Planned Vs Actual '!F25 -> CUM | F10: ='Planned Vs Actual '!H25 -> 86.9 | G10: ='Planned Vs Actual '!K25 -> 0 | H10: ='Planned Vs Actual '!L25 -> 0 | I10: ='Planned Vs Actual '!M25 -> 86.9
A11: 8 | B11: Worker Dormitory | C11: ='Planned Vs Actual '!C20 -> Plinth Beam PCC | D11: ='Planned Vs Actual '!F18 -> CUM | F11: ='Planned Vs Actual '!H20 -> 18.07 | G11: ='Planned Vs Actual '!K20 -> 0 | H11: ='Planned Vs Actual '!L20 -> 0 | I11: ='Planned Vs Actual '!M20 -> 18.07
A12: 9 | B12: Worker Dormitory | C12: Footing RCC | D12: CUM | E12: ='Planned Vs Actual '!G12 -> 380 | F12: ='Planned Vs Actual '!H12 -> 292.764 | G12: ='Planned Vs Actual '!K12 -> 0 | H12: ='Planned Vs Actual '!L12 -> 0 | I12: ='Planned Vs Actual '!M12 -> 292.76
A13: 10 | B13: Worker Dormitory | C13: Pedestal RCC | D13: CUM | F13: ='Planned Vs Actual '!H14 -> 62.65 | G13: ='Planned Vs Actual '!K14 -> 0 | H13: ='Planned Vs Actual '!L14 -> 0 | I13: ='Planned Vs Actual '!M14 -> 62.65
A14: 11 | B14: Worker Dormitory | C14: ='Planned Vs Actual '!C18 -> GB RCC | D14: CUM | F14: ='Planned Vs Actual '!H18 -> 23.994 | G14: ='Planned Vs Actual '!K18 -> 0 | H14: ='Planned Vs Actual '!L18 -> 0 | I14: ='Planned Vs Actual '!M18 -> 23.98
A15: 12 | B15: Worker Dormitory | C15: ='Planned Vs Actual '!C22 -> Plinth Beam RCC | D15: CUM | F15: ='Planned Vs Actual '!H22 -> 45.72 | G15: ='Planned Vs Actual '!K22 -> 0 | H15: ='Planned Vs Actual '!L22 -> 0 | I15: ='Planned Vs Actual '!M22 -> 45.72
A16: 13 | B16: Worker Dormitory | C16: ='Planned Vs Actual '!C27 -> Floor RCC | D16: CUM | F16: ='Planned Vs Actual '!H27 -> 88.03 | G16: ='Planned Vs Actual '!J27 -> 0 | H16: ='Planned Vs Actual '!L27 -> 0 | I16: ='Planned Vs Actual '!M27 -> 88.03
A17: 14 | B17: Worker Dormitory | C17: ='Planned Vs Actual '!C19 -> Masonry Above GB | D17: CUM | E17: ='Planned Vs Actual '!G19 -> 130 | F17: ='Planned Vs Actual '!H19 -> 86.294 | G17: ='Planned Vs Actual '!K19 -> 0 | H17: ='Planned Vs Actual '!L19 -> 0 | I17: ='Planned Vs Actual '!M19 -> 86.294
A18: 15 | B18: Worker Dormitory | C18: ='Planned Vs Actual '!C24 -> Masonry above PB | D18: CUM | F18: ='Planned Vs Actual '!H24 -> 16.168 | G18: ='Planned Vs Actual '!J24 -> -0.002 | H18: ='Planned Vs Actual '!L24 -> 0 | I18: ='Planned Vs Actual '!M24 -> 16.17
A19: 16 | B19: Worker Dormitory | C19: ='Planned Vs Actual '!C23 -> Plinth Plaster | D19: ='Planned Vs Actual '!F23 -> SMT | E19: ='Planned Vs Actual '!G23 -> 5235 | F19: ='Planned Vs Actual '!H23 -> 92.29 | G19: ='Planned Vs Actual '!K23 -> 32.79 | H19: ='Planned Vs Actual '!L23 -> 15 | I19: ='Planned Vs Actual '!M23 -> 74.5
A20: 17 | B20: Worker Dormitory | C20: ='Planned Vs Actual '!C11 -> Footing Shuttering | D20: ='Planned Vs Actual '!F11 -> SMT | E20: ='Planned Vs Actual '!G11 -> 1075 | F20: ='Planned Vs Actual '!H11 -> 441.908 | G20: ='Planned Vs Actual '!K11 -> 0 | H20: ='Planned Vs Actual '!L11 -> 0 | I20: ='Planned Vs Actual '!L11 -> 0
A21: 18 | B21: Worker Dormitory | C21: ='Planned Vs Actual '!C13 -> Padestal Upto Plinth Top Shuttering | D21: SMT | F21: ='Planned Vs Actual '!H13 -> 664 | G21: ='Planned Vs Actual '!K13 -> 0 | H21: ='Planned Vs Actual '!L13 -> 0 | I21: ='Planned Vs Actual '!M13 -> 664
A22: 19 | B22: Worker Dormitory | C22: ='Planned Vs Actual '!C17 -> GB Shuttering | D22: SMT | F22: ='Planned Vs Actual '!H17 -> 142.938 | G22: ='Planned Vs Actual '!K17 -> 0 | H22: ='Planned Vs Actual '!L17 -> 0 | I22: ='Planned Vs Actual '!M17 -> 142.85
A23: 20 | B23: Worker Dormitory | C23: ='Planned Vs Actual '!C21 -> Plinth Beam Shuttering | D23: SMT | F23: ='Planned Vs Actual '!H21 -> 387.1 | G23: ='Planned Vs Actual '!K21 -> 0 | H23: ='Planned Vs Actual '!L21 -> 0 | I23: ='Planned Vs Actual '!M21 -> 387.1
A24: 21 | B24: Worker Dormitory | C24: ='Planned Vs Actual '!C26 -> Floor RCC Shuttering | D24: SMT | F24: ='Planned Vs Actual '!H26 -> 15.3 | G24: ='Planned Vs Actual '!K26 -> 0 | H24: ='Planned Vs Actual '!L26 -> 0 | I24: ='Planned Vs Actual '!M26 -> 15.3
A25: 22 | B25: Worker Dormitory | C25: ='Planned Vs Actual '!C29 -> Plinth to GF slab column shuttering | D25: ='Planned Vs Actual '!F29 -> SQM | E25: 1680 | F25: ='Planned Vs Actual '!H29 -> 427.55 | G25: ='Planned Vs Actual '!K29 -> 0 | H25: ='Planned Vs Actual '!L29 -> 0 | I25: ='Planned Vs Actual '!M29 -> 427.554
A26: 23 | B26: Worker Dormitory | C26: ='Planned Vs Actual '!C30 -> GF beam shuttering | D26: ='Planned Vs Actual '!F30 -> SQM | F26: ='Planned Vs Actual '!H30 -> 700.59 | G26: ='Planned Vs Actual '!K30 -> 0 | H26: ='Planned Vs Actual '!L30 -> 0 | I26: ='Planned Vs Actual '!M30 -> 700.59
A27: 24 | B27: Worker Dormitory | C27: ='Planned Vs Actual '!C31 -> GF Slab shuttering | D27: ='Planned Vs Actual '!F31 -> SQM | F27: ='Planned Vs Actual '!H31 -> 664.26 | G27: ='Planned Vs Actual '!K31 -> 0 | H27: ='Planned Vs Actual '!L31 -> 0 | I27: ='Planned Vs Actual '!M31 -> 664.23
A28: 25 | B28: Worker Dormitory | C28: ='Planned Vs Actual '!C32 -> GF staircase shuttering | D28: ='Planned Vs Actual '!F32 -> SQM | F28: ='Planned Vs Actual '!H32 -> 57.39 | G28: ='Planned Vs Actual '!K32 -> 0 | H28: ='Planned Vs Actual '!L32 -> 0 | I28: ='Planned Vs Actual '!M32 -> 57.39
A29: 26 | B29: Worker Dormitory | C29: ='Planned Vs Actual '!C33 -> GF lintel shuttering | D29: ='Planned Vs Actual '!F33 -> SQM | F29: ='Planned Vs Actual '!H33 -> 67.99 | G29: ='Planned Vs Actual '!K33 -> 0 | H29: ='Planned Vs Actual '!L33 -> 0 | I29: ='Planned Vs Actual '!M33 -> 56
A30: 27 | B30: Worker Dormitory | C30: ='Planned Vs Actual '!C34 -> Plinth to GF slab column concrete | D30: ='Planned Vs Actual '!F34 -> CUM | E30: ='Planned Vs Actual '!G34 -> 210 | F30: ='Planned Vs Actual '!H34 -> 32.822 | G30: ='Planned Vs Actual '!K34 -> 0 | H30: ='Planned Vs Actual '!L34 -> 0 | I30: ='Planned Vs Actual '!M34 -> 32.82
A31: 28 | B31: Worker Dormitory | C31: ='Planned Vs Actual '!C35 -> GF beam Concrete | D31: ='Planned Vs Actual '!F35 -> CUM | F31: ='Planned Vs Actual '!H35 -> 61.76 | G31: ='Planned Vs Actual '!K35 -> 0 | H31: ='Planned Vs Actual '!L35 -> 0 | I31: ='Planned Vs Actual '!M35 -> 61.75
A32: 29 | B32: Worker Dormitory | C32: ='Planned Vs Actual '!C36 -> GF Slab Concrete | D32: ='Planned Vs Actual '!F36 -> CUM | F32: ='Planned Vs Actual '!H36 -> 101.99 | G32: ='Planned Vs Actual '!K36 -> 0 | H32: ='Planned Vs Actual '!L36 -> 0 | I32: ='Planned Vs Actual '!M36 -> 101.98
A33: 30 | B33: Worker Dormitory | C33: ='Planned Vs Actual '!C37 -> GF staircase concrete | D33: ='Planned Vs Actual '!F37 -> CUM | F33: ='Planned Vs Actual '!H37 -> 8.53 | G33: ='Planned Vs Actual '!K37 -> 0 | H33: ='Planned Vs Actual '!L37 -> 0 | I33: ='Planned Vs Actual '!M37 -> 8.52
A34: 31 | B34: Worker Dormitory | C34: ='Planned Vs Actual '!C38 -> GF lintel Concrete | D34: ='Planned Vs Actual '!F38 -> CUM | F34: ='Planned Vs Actual '!H38 -> 3.91 | G34: ='Planned Vs Actual '!K38 -> 0 | H34: ='Planned Vs Actual '!L38 -> 0 | I34: ='Planned Vs Actual '!M38 -> 2
A35: 32 | B35: Worker Dormitory | C35: ='Planned Vs Actual '!C39 -> Brick masonary GF (230 mm) | D35: ='Planned Vs Actual '!F39 -> CUM | E35: ='Planned Vs Actual '!G39 -> 80 | F35: ='Planned Vs Actual '!H39 -> 73.48 | G35: ='Planned Vs Actual '!K39 -> 20 | H35: ='Planned Vs Actual '!L39 -> 7 | I35: ='Planned Vs Actual '!M39 -> 43.86
A36: 33 | B36: Worker Dormitory | C36: ='Planned Vs Actual '!C40 -> Brick masonary GF (115 mm) | D36: ='Planned Vs Actual '!F40 -> SMT | E36: ='Planned Vs Actual '!G40 -> 1170 | F36: ='Planned Vs Actual '!H40 -> 768 | G36: ='Planned Vs Actual '!K40 -> 100 | H36: ='Planned Vs Actual '!L40 -> 10 | I36: ='Planned Vs Actual '!M40 -> 356.26
A37: 34 | B37: Worker Dormitory | C37: ='Planned Vs Actual '!C41 -> Internal Plaster | D37: ='Planned Vs Actual '!F41 -> SMT | E37: ='Planned Vs Actual '!G41 -> 1591.21 | F37: ='Planned Vs Actual '!H41 -> 1733.79 | G37: ='Planned Vs Actual '!K41 -> 600 | H37: ='Planned Vs Actual '!L41 -> 301 | I37: ='Planned Vs Actual '!M41 -> 663
A38: 35 | B38: Worker Dormitory | C38: ='Planned Vs Actual '!C42 -> Flooring | D38: ='Planned Vs Actual '!F42 -> SMT | E38: ='Planned Vs Actual '!G42 -> 830 | F38: ='Planned Vs Actual '!H42 -> 841.16 | G38: ='Planned Vs Actual '!K42 -> 100 | H38: ='Planned Vs Actual '!L42 -> 55.15 | I38: ='Planned Vs Actual '!M42 -> 55.15
A39: 36 | B39: Worker Dormitory | C39: ='Planned Vs Actual '!C43 -> Skirting | D39: ='Planned Vs Actual '!F43 -> RMT | E39: ='Planned Vs Actual '!G43 -> 1865 | F39: ='Planned Vs Actual '!H43 -> 1859.2 | G39: ='Planned Vs Actual '!K43 -> 100 | H39: ='Planned Vs Actual '!L43 -> 45 | I39: ='Planned Vs Actual '!M43 -> 45
A40: 37 | B40: Worker Dormitory | C40: ='Planned Vs Actual '!C45 -> GF to FF slab column shuttering | D40: ='Planned Vs Actual '!F45 -> SQM | E40: ='Planned Vs Actual '!G45 -> 1680 | F40: ='Planned Vs Actual '!H45 -> 439.913 | G40: ='Planned Vs Actual '!K45 -> 100 | H40: ='Planned Vs Actual '!L45 -> 21.32 | I40: ='Planned Vs Actual '!M45 -> 336.32
A41: 38 | B41: Worker Dormitory | C41: ='Planned Vs Actual '!C46 -> FF beam shuttering | D41: ='Planned Vs Actual '!F46 -> SQM | F41: ='Planned Vs Actual '!H46 -> 700.59 | G41: ='Planned Vs Actual '!K46 -> 0 | H41: ='Planned Vs Actual '!L46 -> 0 | I41: ='Planned Vs Actual '!M46 -> 701
...
