Workbook

Sheet summary
A1: BOQ FOR PROPOSED CIVIL & STRUCTURAL WORKS For SUYOG ELECTRICAL LTD. NO 245/33/B, 245/55/B/2, MOJE BODIDARA, TA.VADODARA, GUJARAT, INDIA.
A3: SR NO | B3: SECTION | C3: TITLE | D3: VIKRAM BUILDER | E3: TCC PROJECTS | F3: MAHAVIR CONSTRUCTION
D4: GRAND TOTAL | E4: GRAND TOTAL | F4: GRAND TOTAL
A5: 1 | B5: SECTION : -A | C5: EARTH WORK-SOLING | D5: =BOQ!F43 -> 16486314 | E5: =BOQ!H43 -> 15153396 | F5: =BOQ!J43 -> 18655311
A6: =A5+1 -> 2 | B6: SECTION : -B | C6: CONCRETE AND ALLIED WORK | D6: =BOQ!F127 -> 32102030 | E6: =BOQ!H127 -> 31604081 | F6: =BOQ!J127 -> 33191678
A7: =A6+1 -> 3 | B7: SECTION : -C | C7: MASONARY WORKS | D7: =BOQ!F155 -> 3686641.2 | E7: =BOQ!H155 -> 3904326 | F7: =BOQ!J155 -> 3877929.3
A8: =A7+1 -> 4 | B8: SECTION : -D | C8: FLOORING AND FACIAS. | D8: =BOQ!F214 -> 15539867 | E8: =BOQ!H214 -> 15982748 | F8: =BOQ!J214 -> 17835515
A9: =A8+1 -> 5 | B9: SECTION : -E | C9: PLASTERING , PAINTING , FINISHING | D9: =BOQ!F236 -> 6845605 | E9: =BOQ!H236 -> 7486265 | F9: =BOQ!J236 -> 7366271.1
A10: =A9+1 -> 6 | B10: SECTION : -F | C10: DOORS, WINDOWS AND VENTILATORS | D10: =BOQ!F318 -> 3848426.2 | E10: =BOQ!H318 -> 4262525 | F10: =BOQ!J318 -> 4363147.3
A11: =A10+1 -> 7 | B11: SECTION : -G | C11: STRCUTURAL STEEL WORK | D11: =BOQ!F334 -> 1766069 | E11: =BOQ!H334 -> 2344906.7 | F11: =BOQ!J334 -> 1879476.9
A12: =A11+1 -> 8 | B12: SECTION : -H | C12: ROOFING WORK
A13: =A12+1 -> 9 | B13: SECTION : -I | C13: WATERPROOFING | D13: =BOQ!F355 -> 830167 | E13: =BOQ!H355 -> 568914 | F13: =BOQ!J355 -> 990008.25
A14: =A13+1 -> 10 | B14: SECTION : -J | C14: MISCELLENOUS ITEMS | D14: =BOQ!F425 -> 3179626.2 | E14: =BOQ!H425 -> 2550960 | F14: =BOQ!J425 -> 2756781
A15: =A14+1 -> 11 | B15: SECTION : - K | C15: ROAD & PAVOR | D15: =BOQ!F490 -> 7397626.2 | E15: =BOQ!H490 -> 7172790 | F15: =BOQ!J490 -> 8919361.7
A16: =A15+1 -> 12 | B16: SECTION : - L | C16: PRE-CAST STORM WATER DRAIN
A17: TOTAL AMOUNT OF TENDER ITEMS | D17: =SUM(D5:D16) -> 91682372 | E17: =SUM(E5:E16) -> 91030911 | F17: =SUM(F5:F16) -> 99835480
C19: Percentange Respect to L 1 for Diffrence
C20: L 1 Compare to L 2 | D20: =100%-(($E$17/D17)) -> 0.0071056299
C21: L 1 Compare to L 3 | D21: =100%-(($E$17/F17)) -> 0.088190782

Sheet BOQ
A3: #VALUE!
A5: Sr. No. | B5: Description | C5: QTY. | D5: UNIT | E5: Vikram Builders | G5: TCC Projects | I5: Mahavir Construction
E6: RATE | F6: GRAND TOTAL | G6: RATE | H6: GRAND TOTAL | I6: RATE | J6: GRAND TOTAL
B7: SECTION- A EARTH WORK AND SOLING
A8: A-01 | B8: Cleaning the area by grass cutting, removing vegetations,roots of trees if any, scraping the existing surfaces up to 150mm, removal of all loose materials and other matters, etc. and disposing off the debris beyond the plant boundary as directed by the Engineer. | C8: QRO | D8: SQ.M. | E8: 23.75 | G8: 13 | I8: 13.825
A9: A-01A | B9: Clearing the area by jungle cutting, removing trees / bushes if any from roots, scraping the existing surfaces up to 150mm, removal of all loose materials and other matters, etc. and disposing off the debris beyond the plant boundary as directed by EIC. | C9: QRO | D9: SQ.M. | E9: 76 | G9: 66 | I9: 49.375
A10: A-02 | B10: Earth work excavation for all type of work in all soils like black cotton soil, clay, sand, soft and hard murrum, etc. but other than soft and hard rock including shoring, strutting and dewatering due to any sub soil water, rain water or any reason if required and refilling in foundations with selected excavated earth in 350mm layers, watering and consolidating to 250mm thickness, disposing off surplus excavated materials within the plant boundary at selected places, spreading evenly, leveling, etc. complete as per specifications and as directed. (Payment shall be made for 300mm from R.C.C. face for foundations and 200mm from R.C.C. face for GB) | C10: 0 | E10: 0 | G10: 0 | I10: 0 | J10: =I10*G9 -> 0
B11: a) From average ground level up to 1.50M depth. | C11: 3425 | D11: CUM | E11: 180.5 | F11: =E11*C11 -> 618212.5 | G11: 134 | H11: =IFERROR(G11*C11,"") -> 458950 | I11: 132.325 | J11: =$I11*$C11 -> 453213.12
B12: b) Below 1.5M up to 3M depth | C12: 600 | D12: CUM | E12: 190 | F12: =E12*C12 -> 114000 | G12: 150 | H12: =IFERROR(G12*C12,"") -> 90000 | I12: 145.1625 | J12: =$I12*$C12 -> 87097.5
B13: c) Below 3.0M up to 4.5M depth | C13: 226 | D13: CUM | E13: 256.5 | F13: =E13*C13 -> 57969 | G13: 160 | H13: =IFERROR(G13*C13,"") -> 36160 | I13: 157.0125 | J13: =$I13*$C13 -> 35484.825
B14: d) Below 4.5M up to 6.0M depth | C14: QRO | D14: CUM | E14: 318.25 | G14: 185 | H14: =IFERROR(G14*C14,"") | I14: 182.6875
B15: e) Below 6.0M up to 7.5M depth | C15: QRO | D15: CUM | E15: 389.5 | G15: 201 | H15: =IFERROR(G15*C15,"") | I15: 197.5
A16: A-03 | B16: Filling in plinth & foundation pits with approved materials including spreading in 150mm layers, watering, ramming, compacting with 10MT vibro/static roller or portable compactor wherever applicable as decided by the Engineer, leveling, etc. complete. (Measurements for compacted volume is considered) | C16: 0 | G16: 0 | H16: =IFERROR(G16*C16,"") -> 0
B17: a) With selected earth brought from outside | C17: 4450 | D17: CUM | E17: 413.25 | F17: =E17*C17 -> 1838962.5 | G17: 413 | H17: =IFERROR(G17*C17,"") -> 1837850 | I17: 402.9 | J17: =$I17*$C17 -> 1792905
B18: b) With approved filling sand brought from Outside. | C18: 2995 | D18: CUM | E18: 1268.25 | F18: =E18*C18 -> 3798408.8 | G18: 755 | H18: =IFERROR(G18*C18,"") -> 2261225 | I18: 1463.475 | J18: =$I18*$C18 -> 4383107.6
B19: c) Approved quarry dust filling | C19: QRO | D19: CUM | E19: 1391.75 | G19: 1031 | H19: =IFERROR(G19*C19,"") | I19: 987.5
A20: A-04 | B20: Disposing off surplus excavated materials by carting away, outside of company premises at location decided by contractor and shall be responsibility of contractor | C20: 365 | D20: CUM | E20: 261.25 | F20: =E20*C20 -> 95356.25 | G20: 197 | H20: =IFERROR(G20*C20,"") -> 71905 | I20: 188.6125 | J20: =$I20*$C20 -> 68843.562
A21: A-04A | B21: Disposing off dumped Earth / Debris by carting away, outside of company premises at location decided by contractor and shall be responsibility of contractor | C21: 0 | E21: 0 | F21: =E21*C21 -> 0 | G21: 0 | H21: =IFERROR(G21*C21,"") -> 0 | I21: 0 | J21: =I21*G20 -> 0
B22: a) Measurement of available material by volume | C22: 950 | D22: CUM | E22: 261.25 | F22: =E22*C22 -> 248187.5 | G22: 195 | H22: =IFERROR(G22*C22,"") -> 185250 | I22: 188.6125 | J22: =$I22*$C22 -> 179181.88
B23: b) Measurement of available material by Dumper | C23: QRO | D23: Nos. | E23: 2042.5 | G23: 955 | H23: =IFERROR(G23*C23,"") | I23: 1481.25
A24: A-05 | B24: Providing and laying black trap rubble soling at required level and grade in foundations, in plinth, ramps, etc. including hand packing, filling interstices with quarry / sand, watering and compacting with suitable vibro roller/ Static roller or earth compactor wherever applicable as decided by the Engineer to the consolidated thickness as stated below: | C24: 0 | E24: 0 | F24: =E24*C24 -> 0 | G24: 0 | H24: =IFERROR(G24*C24,"") -> 0 | I24: 0 | J24: =I24*G23 -> 0
B25: i) 230mm thick Soling | C25: QRO | D25: SQ.M | E25: 498.75 | G25: 519 | H25: =IFERROR(G25*C25,"") | I25: 592.5
B26: ii) 150mm thick compacted layer metal packing using 63-90 mm size hand broken stone etc. as directed Engineer in charge/consultant. | C26: 16475 | D26: SQ.M | E26: 266 | F26: =E26*C26 -> 4382350 | G26: 295 | H26: =IFERROR(G26*C26,"") -> 4860125 | I26: 339.7 | J26: =$I26*$C26 -> 5596557.5
B27: iii) 75mm thick compacted layer metal packing using 40-63 mm size hand broken stone etc. as directed Engineer in charge/consultant. | C27: 14882 | D27: SQ.M | E27: 147.25 | F27: =E27*C27 -> 2191374.5 | G27: 168 | H27: =IFERROR(G27*C27,"") -> 2500176 | I27: 172.8125 | J27: =$I27*$C27 -> 2571795.6
A28: A-06 | B28: Auguring(Upto 9m depth) of under ream pile foundation work in all sorts of soil viz. sand, clay, soft & hard murrum for execution of the above work. Contractor has to brought all necessary tools, tackles, equipments, manpower & supervision. Items also include carting of debris/soil, unloading, stacking, use of bentonite, spreading, levelling, compacting, consolidating surplus marterial within company premises, dewatering & one bulb as per design etc. complete as directed | C28: 0 | E28: 0 | F28: =E28*C28 -> 0 | G28: 0 | H28: =IFERROR(G28*C28,"") -> 0 | I28: 0 | J28: =I28*G27 -> 0
B29: (a) For 250mm dia. Pile | C29: QRO | D29: RM | E29: 237.5 | G29: 312 | H29: =IFERROR(G29*C29,"") | I29: 251.8125
B30: (b) For 300mm dia. Pile | C30: 40 | D30: RM | E30: 270.75 | F30: =E30*C30 -> 10830 | G30: 332 | H30: =IFERROR(G30*C30,"") -> 13280 | I30: 315.0125 | J30: =$I30*$C30 -> 12600.5
B31: (c) For 350mm dia. Pile | C31: 3936 | D31: RM | E31: 342 | F31: =E31*C31 -> 1346112 | G31: 382 | H31: =IFERROR(G31*C31,"") -> 1503552 | I31: 472.025 | J31: =$I31*$C31 -> 1857890.4
B32: (d) For 400mm dia. Pile | C32: 334 | D32: RM | E32: 522.5 | F32: =E32*C32 -> 174515 | G32: 436 | H32: =IFERROR(G32*C32,"") -> 145624 | I32: 535.225 | J32: =$I32*$C32 -> 178765.15
B33: (e) For 450mm dia. Pile | C33: 766 | D33: RM | E33: 570 | F33: =E33*C33 -> 436620 | G33: 519 | H33: =IFERROR(G33*C33,"") -> 397554 | I33: 597.4375 | J33: =$I33*$C33 -> 457637.12
B34: (f) For 500mm dia. Pile | C34: QRO | D34: RM | E34: 731.5 | G34: 727 | H34: =IFERROR(G34*C34,"") | I34: 660.6375
A35: A-06 a | B35: Auguring (Upto 12 m depth) of under ream pile foundation work in all sorts of soil viz. sand, clay, soft & hard murrum for execution of the above work. Contractor has to brought all necessary tools, tackles, equipments, manpower & supervision. Items also include carting of debris/soil, unloading, stacking, use of bentonite, spreading, levelling, compacting, consolidating surplus marterial within company premises, dewatering & one bulb as per design etc. complete as directed | E35: 0 | F35: =E35*C35 -> 0 | G35: 0 | H35: =IFERROR(G35*C35,"") -> 0 | I35: 0 | J35: =I35*G34 -> 0
B36: (a) For 400mm dia. Pile | C36: 1492 | D36: RM | E36: 617.5 | F36: =E36*C36 -> 921310 | G36: 435 | H36: =IFERROR(G36*C36,"") -> 649020 | I36: 535.225 | J36: =$I36*$C36 -> 798555.7
B37: (b) For 500mm dia. Pile | C37: 275 | D37: RM | E37: 916.75 | F37: =E37*C37 -> 252106.25 | G37: 519 | H37: =IFERROR(G37*C37,"") -> 142725 | I37: 660.6375 | J37: =$I37*$C37 -> 181675.31
A38: A-07 | B38: -do- as per item no. A-06 but for construction of extra bulb in the pile at any level. The size of the bulb will be as per design. | C38: 0 | E38: 0 | F38: =E38*C38 -> 0 | G38: 0 | H38: =IFERROR(G38*C38,"") -> 0 | I38: 0 | J38: =I38*G37 -> 0
B39: (a) For 250mm dia. Pile | C39: QRO | D39: NO | E39: 237.5 | G39: 307 | H39: =IFERROR(G39*C39,"") | I39: 296.25
B40: (b) For 300mm dia. Pile | C40: QRO | D40: NO | E40: 237.5 | G40: 316 | H40: =IFERROR(G40*C40,"") | I40: 395
B41: (c) For 350mm dia. Pile | C41: QRO | D41: NO | E41: 332.5 | G41: 378 | H41: =IFERROR(G41*C41,"") | I41: 493.75
B42: (d) For 400mm dia. Pile | C42: QRO | D42: NO | E42: 380 | G42: 408 | H42: =IFERROR(G42*C42,"") | I42: 691.25
B43: TOTAL OF SECTION `A` | C43: 0 | E43: 0 | F43: =SUM(F8:F42) -> 16486314 | G43: 0 | H43: =SUM(H8:H42) -> 15153396 | J43: =SUM(J8:J42) -> 18655311
...

Sheet BOQ-CCV 
B1: ESTIMATED BOQ FOR PROPOSED CIVIL & STRUCTURAL WORKS For SUYOG ELECTRICAL LTD. NO 245/33/B,245/55/B/2,MOJE BODIDARA, TA.VADODARA, GUJARAT, INDIA.
A2: Followings are the scope of work: - Shed building Civil and Structural works (Excluding PEB shed) - Approximately 1250 sqm area (G+3) FLOOR
A4: BOQ
A5: Sr. No. | B5: Description | C5: QTY. | D5: UNIT | E5: RATE | F5: AMOUNT
B6: SECTION- A EARTH WORK AND SOLING
A7: A-01 | B7: Cleaning the area by grass cutting, removing vegetations,roots of trees if any, scraping the existing surfaces up to 150mm, removal of all loose materials and other matters, etc. and disposing off the debris beyond the plant boundary as directed by the Engineer. | D7: SQ.M. | E7: 35 | F7: =E7*C7 -> 0
A8: A-01A | B8: Clearing the area by jungle cutting, removing trees / bushes if any from roots, scraping the existing surfaces up to 150mm, removal of all loose materials and other matters, etc. and disposing off the debris beyond the plant boundary as directed by EIC. | D8: SQ.M. | E8: 25 | F8: =E8*C8 -> 0
A9: A-02 | B9: Earth work excavation for all type of work in all soils like black cotton soil, clay, sand, soft and hard murrum, etc. but other than soft and hard rock including shoring, strutting and dewatering due to any sub soil water, rain water or any reason if required and refilling in foundations with selected excavated earth in 350mm layers, watering and consolidating to 250mm thickness, disposing off surplus excavated materials within the plant boundary at selected places, spreading evenly, leveling, etc. complete as per specifications and as directed. (Payment shall be made for 300mm from R.C.C. face for foundations and 200mm from R.C.C. face for GB)
B10: a) From average ground level up to 1.50M depth. | C10: 642 | D10: CUM | E10: 250 | F10: =E10*C10 -> 160500
B11: b) Below 1.5M up to 3M depth | D11: CUM | E11: 285 | F11: =E11*C11 -> 0
B12: c) Below 3.0M up to 4.5M depth | D12: CUM | E12: 350
B13: d) Below 4.5M up to 6.0M depth | D13: CUM | E13: 450
B14: e) Below 6.0M up to 7.5M depth | D14: CUM | E14: 575
A15: A-03 | B15: Filling in plinth & foundation pits with approved materials including spreading in 150mm layers, watering, ramming, compacting with 10MT vibro/static roller or portable compactor wherever applicable as decided by the Engineer, leveling, etc. complete. (Measurements for compacted volume is considered)
B16: a) With selected earth brought from outside | C16: 57 | D16: CUM | E16: 490 | F16: =E16*C16 -> 27930
B17: b) With approved filling sand brought from Outside. | C17: 57 | D17: CUM | E17: 1025 | F17: =E17*C17 -> 58425
B18: c) Approved quarry dust filling | D18: CUM | E18: 1150
A19: A-04 | B19: Disposing off surplus excavated materials by carting away, outside of company premises at location decided by contractor and shall be responsibility of contractor | D19: CUM | E19: 150 | F19: =E19*C19 -> 0
A20: A-04A | B20: Disposing off dumped Earth / Debris by carting away, outside of company premises at location decided by contractor and shall be responsibility of contractor
B21: a) Measurement of available material by volume | D21: CUM | E21: 100 | F21: =E21*C21 -> 0
B22: b) Measurement of available material by Dumper | D22: Nos. | E22: 3500
A23: A-05 | B23: Providing and laying black trap rubble soling at required level and grade in foundations, in plinth, ramps, etc. including hand packing, filling interstices with quarry / sand, watering and compacting with suitable vibro roller/ Static roller or earth compactor wherever applicable as decided by the Engineer to the consolidated thickness as stated below:
B24: i) 230mm thick Soling | D24: SQ.M | E24: 517
B25: ii) 150mm thick compacted layer metal packing using 63-90 mm size hand broken stone etc. as directed Engineer in charge/consultant. | C25: 284 | D25: SQ.M | E25: 310 | F25: =E25*C25 -> 88040
B26: iii) 75mm thick compacted layer metal packing using 40-63 mm size hand broken stone etc. as directed Engineer in charge/consultant. | C26: 284 | D26: SQ.M | E26: 150 | F26: =E26*C26 -> 42600
A27: A-06 | B27: Auguring(Upto 11m depth) of under ream pile foundation work in all sorts of soil viz. sand, clay, soft & hard murrum for execution of the above work. Contractor has to brought all necessary tools, tackles, equipments, manpower & supervision. Items also include carting of debris/soil, unloading, stacking, use of bentonite, spreading, levelling, compacting, consolidating surplus marterial within company premises, dewatering & one bulb as per design etc. complete as directed
B28: (a) For 250mm dia. Pile | D28: RM | E28: 300
B29: (b) For 300mm dia. Pile | D29: RM | E29: 350 | F29: =E29*C29 -> 0
B30: (c) For 350mm dia. Pile | D30: RM | E30: 425 | F30: =E30*C30 -> 0
B31: (d) For 400mm dia. Pile | D31: RM | E31: 495 | F31: =E31*C31 -> 0
B32: (e) For 500mm dia. Pile | C32: 1834 | D32: RM | E32: 500 | F32: =E32*C32 -> 917000
A33: A-07 | B33: -do- as per item no. A-06 but for construction of extra bulb in the pile at any level. The size of the bulb will be as per design.
B34: (a) For 250mm dia. Pile | D34: NO | E34: 300
B35: (b) For 300mm dia. Pile | D35: NO | E35: 400
B36: (c) For 350mm dia. Pile | D36: NO | E36: 450
B37: (d) For 400mm dia. Pile | D37: NO | E37: 500
B38: TOTAL OF SECTION `A` | F38: =SUM(F7:F37) -> 1294495
B39: SECTION - B CONCRETE
A40: B-01 | B40: Providing and laying Plain cement concrete below all R.C.C. member, floors, ramps, chembers etc. with 20mm nominal size graded stone aggregates of approved quality (black trap only) including leveling, compacting, curing and form work if any, etc. complete.
B41: a) Mix 1: 4: 8 | C41: 60 | D41: CUM | E41: 4100 | F41: =E41*C41 -> 246000
...

Sheet BOQ ELE. LAB 
B1: ESTIMATED BOQ FOR PROPOSED ELECTRICAL LAB CIVIL & STRUCTURAL WORKS For SUYOG ELECTRICAL LTD. NO 245/33/B,245/55/B/2,MOJE BODIDARA, TA.VADODARA, GUJARAT, INDIA.
A2: Followings are the scope of work: - Shed building Civil and Structural works (Excluding PEB shed) - Approximately 425sqm area - Machine Foundation - R.C.C. Road - Approximately 3050 sqm - Storm Water drain
A4: BOQ
A5: Sr. No. | B5: Description | C5: QTY. | D5: UNIT | E5: RATE | F5: AMOUNT
B6: SECTION- A EARTH WORK AND SOLING
A7: A-01 | B7: Cleaning the area by grass cutting, removing vegetations,roots of trees if any, scraping the existing surfaces up to 150mm, removal of all loose materials and other matters, etc. and disposing off the debris beyond the plant boundary as directed by the Engineer. | C7: 501 | D7: SQ.M. | E7: 35 | F7: =E7*C7 -> 17535
A8: A-01A | B8: Clearing the area by jungle cutting, removing trees / bushes if any from roots, scraping the existing surfaces up to 150mm, removal of all loose materials and other matters, etc. and disposing off the debris beyond the plant boundary as directed by EIC. | D8: SQ.M. | E8: 25 | F8: =E8*C8 -> 0
A9: A-02 | B9: Earth work excavation for all type of work in all soils like black cotton soil, clay, sand, soft and hard murrum, etc. but other than soft and hard rock including shoring, strutting and dewatering due to any sub soil water, rain water or any reason if required and refilling in foundations with selected excavated earth in 350mm layers, watering and consolidating to 250mm thickness, disposing off surplus excavated materials within the plant boundary at selected places, spreading evenly, leveling, etc. complete as per specifications and as directed. (Payment shall be made for 300mm from R.C.C. face for foundations and 200mm from R.C.C. face for GB)
B10: a) From average ground level up to 1.50M depth. | C10: 136 | D10: CUM | E10: 250 | F10: =E10*C10 -> 34000
B11: b) Below 1.5M up to 3M depth | D11: CUM | E11: 285 | F11: =E11*C11 -> 0
B12: c) Below 3.0M up to 4.5M depth | D12: CUM | E12: 350
B13: d) Below 4.5M up to 6.0M depth | D13: CUM | E13: 450
B14: e) Below 6.0M up to 7.5M depth | D14: CUM | E14: 575
A15: A-03 | B15: Filling in plinth & foundation pits with approved materials including spreading in 150mm layers, watering, ramming, compacting with 10MT vibro/static roller or portable compactor wherever applicable as decided by the Engineer, leveling, etc. complete. (Measurements for compacted volume is considered)
B16: a) With selected earth brought from outside | C16: 95 | D16: CUM | E16: 490 | F16: =E16*C16 -> 46550
B17: b) With approved filling sand brought from Outside. | C17: 90 | D17: CUM | E17: 1025 | F17: =E17*C17 -> 92250
B18: c) Approved quarry dust filling | D18: CUM | E18: 1150
A19: A-04 | B19: Disposing off surplus excavated materials by carting away, outside of company premises at location decided by contractor and shall be responsibility of contractor | D19: CUM | E19: 150 | F19: =E19*C19 -> 0
A20: A-04A | B20: Disposing off dumped Earth / Debris by carting away, outside of company premises at location decided by contractor and shall be responsibility of contractor
B21: a) Measurement of available material by volume | C21: 91 | D21: CUM | E21: 100 | F21: =E21*C21 -> 9100
B22: b) Measurement of available material by Dumper | D22: Nos. | E22: 3500
A23: A-05 | B23: Providing and laying black trap rubble soling at required level and grade in foundations, in plinth, ramps, etc. including hand packing, filling interstices with quarry / sand, watering and compacting with suitable vibro roller/ Static roller or earth compactor wherever applicable as decided by the Engineer to the consolidated thickness as stated below:
B24: i) 230mm thick Soling | D24: SQ.M | E24: 517
B25: ii) 150mm thick compacted layer metal packing using 63-90 mm size hand broken stone etc. as directed Engineer in charge/consultant. | C25: 447 | D25: SQ.M | E25: 310 | F25: =E25*C25 -> 138570
B26: iii) 75mm thick compacted layer metal packing using 40-63 mm size hand broken stone etc. as directed Engineer in charge/consultant. | C26: 447 | D26: SQ.M | E26: 150 | F26: =E26*C26 -> 67050
A27: A-06 | B27: Auguring(Upto 8m depth) of under ream pile foundation work in all sorts of soil viz. sand, clay, soft & hard murrum for execution of the above work. Contractor has to brought all necessary tools, tackles, equipments, manpower & supervision. Items also include carting of debris/soil, unloading, stacking, use of bentonite, spreading, levelling, compacting, consolidating surplus marterial within company premises, dewatering & one bulb as per design etc. complete as directed
B28: (a) For 250mm dia. Pile | D28: RM | E28: 300
B29: (b) For 300mm dia. Pile | D29: RM | E29: 350 | F29: =E29*C29 -> 0
B30: (c) For 350mm dia. Pile | C30: 375 | D30: RM | E30: 425 | F30: =E30*C30 -> 159375
B31: (d) For 400mm dia. Pile | D31: RM | E31: 495 | F31: =E31*C31 -> 0
A32: A-07 | B32: -do- as per item no. A-06 but for construction of extra bulb in the pile at any level. The size of the bulb will be as per design.
B33: (a) For 250mm dia. Pile | D33: NO | E33: 300
B34: (b) For 300mm dia. Pile | D34: NO | E34: 400
B35: (c) For 350mm dia. Pile | D35: NO | E35: 450
B36: (d) For 400mm dia. Pile | D36: NO | E36: 500
B37: TOTAL OF SECTION `A` | F37: =SUM(F7:F36) -> 564430
B38: SECTION - B CONCRETE
A39: B-01 | B39: Providing and laying Plain cement concrete below all R.C.C. member, floors, ramps, chembers etc. with 20mm nominal size graded stone aggregates of approved quality (black trap only) including leveling, compacting, curing and form work if any, etc. complete.
B40: a) Mix 1: 4: 8 | C40: 43 | D40: CUM | E40: 4100 | F40: =E40*C40 -> 176300
B41: b) Mix 1: 3: 6 | D41: CUM | E41: 4175 | F41: =E41*C41 -> 0
...

Sheet BOQ-ADMIN
B1: ESTIMATED BOQ FOR PROPOSED ADMIN CIVIL & STRUCTURAL WORKS For SUYOG ELECTRICAL LTD. NO 245/33/B,245/55/B/2,MOJE BODIDARA, TA.VADODARA, GUJARAT, INDIA.
A2: Followings are the scope of work: - ADMIN building Civil and Structural works (Excluding PEB shed) - Approximately 315 sqm area - Machine Foundation - R.C.C. Road - Approximately 3050 sqm - Storm Water drain
A4: BOQ
A5: Sr. No. | B5: Description | C5: QTY. | D5: UNIT | E5: RATE | F5: AMOUNT
B6: SECTION- A EARTH WORK AND SOLING
A7: A-01 | B7: Cleaning the area by grass cutting, removing vegetations,roots of trees if any, scraping the existing surfaces up to 150mm, removal of all loose materials and other matters, etc. and disposing off the debris beyond the plant boundary as directed by the Engineer. | C7: 378 | D7: SQ.M. | E7: 35 | F7: =E7*C7 -> 13230
A8: A-01A | B8: Clearing the area by jungle cutting, removing trees / bushes if any from roots, scraping the existing surfaces up to 150mm, removal of all loose materials and other matters, etc. and disposing off the debris beyond the plant boundary as directed by EIC. | D8: SQ.M. | E8: 25 | F8: =E8*C8 -> 0
A9: A-02 | B9: Earth work excavation for all type of work in all soils like black cotton soil, clay, sand, soft and hard murrum, etc. but other than soft and hard rock including shoring, strutting and dewatering due to any sub soil water, rain water or any reason if required and refilling in foundations with selected excavated earth in 350mm layers, watering and consolidating to 250mm thickness, disposing off surplus excavated materials within the plant boundary at selected places, spreading evenly, leveling, etc. complete as per specifications and as directed. (Payment shall be made for 300mm from R.C.C. face for foundations and 200mm from R.C.C. face for GB)
B10: a) From average ground level up to 1.50M depth. | C10: 322 | D10: CUM | E10: 250 | F10: =E10*C10 -> 80500
B11: b) Below 1.5M up to 3M depth | D11: CUM | E11: 285 | F11: =E11*C11 -> 0
B12: c) Below 3.0M up to 4.5M depth | D12: CUM | E12: 350
B13: d) Below 4.5M up to 6.0M depth | D13: CUM | E13: 450
B14: e) Below 6.0M up to 7.5M depth | D14: CUM | E14: 575
A15: A-03 | B15: Filling in plinth & foundation pits with approved materials including spreading in 150mm layers, watering, ramming, compacting with 10MT vibro/static roller or portable compactor wherever applicable as decided by the Engineer, leveling, etc. complete. (Measurements for compacted volume is considered)
B16: a) With selected earth brought from outside | C16: 72 | D16: CUM | E16: 490 | F16: =E16*C16 -> 35280
B17: b) With approved filling sand brought from Outside. | C17: 67 | D17: CUM | E17: 1025 | F17: =E17*C17 -> 68675
B18: c) Approved quarry dust filling | D18: CUM | E18: 1150
A19: A-04 | B19: Disposing off surplus excavated materials by carting away, outside of company premises at location decided by contractor and shall be responsibility of contractor | C19: 192 | D19: CUM | E19: 150 | F19: =E19*C19 -> 28800
A20: A-04A | B20: Disposing off dumped Earth / Debris by carting away, outside of company premises at location decided by contractor and shall be responsibility of contractor
B21: a) Measurement of available material by volume | D21: CUM | E21: 100 | F21: =E21*C21 -> 0
B22: b) Measurement of available material by Dumper | D22: Nos. | E22: 3500
A23: A-05 | B23: Providing and laying black trap rubble soling at required level and grade in foundations, in plinth, ramps, etc. including hand packing, filling interstices with quarry / sand, watering and compacting with suitable vibro roller/ Static roller or earth compactor wherever applicable as decided by the Engineer to the consolidated thickness as stated below:
B24: i) 230mm thick Soling | D24: SQ.M | E24: 517
B25: ii) 150mm thick compacted layer metal packing using 63-90 mm size hand broken stone etc. as directed Engineer in charge/consultant. | C25: 378 | D25: SQ.M | E25: 310 | F25: =E25*C25 -> 117180
B26: iii) 75mm thick compacted layer metal packing using 40-63 mm size hand broken stone etc. as directed Engineer in charge/consultant. | C26: 340 | D26: SQ.M | E26: 150 | F26: =E26*C26 -> 51000
A27: A-06 | B27: Auguring(Upto 8m depth) of under ream pile foundation work in all sorts of soil viz. sand, clay, soft & hard murrum for execution of the above work. Contractor has to brought all necessary tools, tackles, equipments, manpower & supervision. Items also include carting of debris/soil, unloading, stacking, use of bentonite, spreading, levelling, compacting, consolidating surplus marterial within company premises, dewatering & one bulb as per design etc. complete as directed
B28: (a) For 250mm dia. Pile | D28: RM | E28: 300
B29: (b) For 300mm dia. Pile | D29: RM | E29: 350 | F29: =E29*C29 -> 0
B30: (c) For 350mm dia. Pile | D30: RM | E30: 425 | F30: =E30*C30 -> 0
B31: (d) For 450 mm dia. Pile | C31: 698 | D31: RM | E31: 495 | F31: =E31*C31 -> 345510
A32: A-07 | B32: -do- as per item no. A-06 but for construction of extra bulb in the pile at any level. The size of the bulb will be as per design.
B33: (a) For 250mm dia. Pile | D33: NO | E33: 300
B34: (b) For 300mm dia. Pile | D34: NO | E34: 400
B35: (c) For 350mm dia. Pile | D35: NO | E35: 450
B36: (d) For 400mm dia. Pile | D36: NO | E36: 500
B37: TOTAL OF SECTION `A` | F37: =SUM(F7:F36) -> 740175
B38: SECTION - B CONCRETE
A39: B-01 | B39: Providing and laying Plain cement concrete below all R.C.C. member, floors, ramps, chembers etc. with 20mm nominal size graded stone aggregates of approved quality (black trap only) including leveling, compacting, curing and form work if any, etc. complete.
B40: a) Mix 1: 4: 8 | C40: 43 | D40: CUM | E40: 4100 | F40: =E40*C40 -> 176300
B41: b) Mix 1: 3: 6 | D41: CUM | E41: 4175 | F41: =E41*C41 -> 0
...

Sheet BOQ -SECURITY
B1: ESTIMATED BOQ FOR PROPOSED SECURITY CIVIL & STRUCTURAL WORKS For SUYOG ELECTRICAL LTD. NO 245/33/B,245/55/B/2,MOJE BODIDARA, TA.VADODARA, GUJARAT, INDIA.
A2: Followings are the scope of work: - Shed building Civil and Structural works (Excluding PEB shed) - Approximately 16sqm area - Machine Foundation - R.C.C. Road - Approximately 3050 sqm - Storm Water drain
A3: BOQ
A4: Sr. No. | B4: Description | C4: QTY. | D4: UNIT | E4: RATE | F4: AMOUNT
B5: SECTION- A EARTH WORK AND SOLING
A6: A-01 | B6: Cleaning the area by grass cutting, removing vegetations,roots of trees if any, scraping the existing surfaces up to 150mm, removal of all loose materials and other matters, etc. and disposing off the debris beyond the plant boundary as directed by the Engineer. | C6: 31 | D6: SQ.M. | E6: 35 | F6: =E6*C6 -> 1085
A7: A-01A | B7: Clearing the area by jungle cutting, removing trees / bushes if any from roots, scraping the existing surfaces up to 150mm, removal of all loose materials and other matters, etc. and disposing off the debris beyond the plant boundary as directed by EIC. | D7: SQ.M. | E7: 25 | F7: =E7*C7 -> 0
A8: A-02 | B8: Earth work excavation for all type of work in all soils like black cotton soil, clay, sand, soft and hard murrum, etc. but other than soft and hard rock including shoring, strutting and dewatering due to any sub soil water, rain water or any reason if required and refilling in foundations with selected excavated earth in 350mm layers, watering and consolidating to 250mm thickness, disposing off surplus excavated materials within the plant boundary at selected places, spreading evenly, leveling, etc. complete as per specifications and as directed. (Payment shall be made for 300mm from R.C.C. face for foundations and 200mm from R.C.C. face for GB)
B9: a) From average ground level up to 1.50M depth. | C9: 5 | D9: CUM | E9: 250 | F9: =E9*C9 -> 1250
B10: b) Below 1.5M up to 3M depth | D10: CUM | E10: 285 | F10: =E10*C10 -> 0
B11: c) Below 3.0M up to 4.5M depth | D11: CUM | E11: 350
B12: d) Below 4.5M up to 6.0M depth | D12: CUM | E12: 450
B13: e) Below 6.0M up to 7.5M depth | D13: CUM | E13: 575
A14: A-03 | B14: Filling in plinth & foundation pits with approved materials including spreading in 150mm layers, watering, ramming, compacting with 10MT vibro/static roller or portable compactor wherever applicable as decided by the Engineer, leveling, etc. complete. (Measurements for compacted volume is considered)
B15: a) With selected earth brought from outside | C15: 5 | D15: CUM | E15: 490 | F15: =E15*C15 -> 2450
B16: b) With approved filling sand brought from Outside. | C16: 4 | D16: CUM | E16: 1025 | F16: =E16*C16 -> 4100
B17: c) Approved quarry dust filling | D17: CUM | E17: 1150
A18: A-04 | B18: Disposing off surplus excavated materials by carting away, outside of company premises at location decided by contractor and shall be responsibility of contractor | C18: 5 | D18: CUM | E18: 150 | F18: =E18*C18 -> 750
A19: A-04A | B19: Disposing off dumped Earth / Debris by carting away, outside of company premises at location decided by contractor and shall be responsibility of contractor
B20: a) Measurement of available material by volume | D20: CUM | E20: 100 | F20: =E20*C20 -> 0
B21: b) Measurement of available material by Dumper | D21: Nos. | E21: 3500
A22: A-05 | B22: Providing and laying black trap rubble soling at required level and grade in foundations, in plinth, ramps, etc. including hand packing, filling interstices with quarry / sand, watering and compacting with suitable vibro roller/ Static roller or earth compactor wherever applicable as decided by the Engineer to the consolidated thickness as stated below:
B23: i) 230mm thick Soling | D23: SQ.M | E23: 517
B24: ii) 150mm thick compacted layer metal packing using 63-90 mm size hand broken stone etc. as directed Engineer in charge/consultant. | C24: 20 | D24: SQ.M | E24: 310 | F24: =E24*C24 -> 6200
B25: iii) 75mm thick compacted layer metal packing using 40-63 mm size hand broken stone etc. as directed Engineer in charge/consultant. | C25: 19 | D25: SQ.M | E25: 150 | F25: =E25*C25 -> 2850
A26: A-06 | B26: Auguring(Upto 8m depth) of under ream pile foundation work in all sorts of soil viz. sand, clay, soft & hard murrum for execution of the above work. Contractor has to brought all necessary tools, tackles, equipments, manpower & supervision. Items also include carting of debris/soil, unloading, stacking, use of bentonite, spreading, levelling, compacting, consolidating surplus marterial within company premises, dewatering & one bulb as per design etc. complete as directed
B27: (a) For 250mm dia. Pile | D27: RM | E27: 300
B28: (b) For 300mm dia. Pile | D28: RM | E28: 350 | F28: =E28*C28 -> 0
B29: (c) For 350mm dia. Pile | C29: 35 | D29: RM | E29: 425 | F29: =E29*C29 -> 14875
B30: (d) For 400mm dia. Pile | D30: RM | E30: 495 | F30: =E30*C30 -> 0
A31: A-07 | B31: -do- as per item no. A-06 but for construction of extra bulb in the pile at any level. The size of the bulb will be as per design.
B32: (a) For 250mm dia. Pile | D32: NO | E32: 300
B33: (b) For 300mm dia. Pile | D33: NO | E33: 400
B34: (c) For 350mm dia. Pile | D34: NO | E34: 450
B35: (d) For 400mm dia. Pile | D35: NO | E35: 500
B36: TOTAL OF SECTION `A` | F36: =SUM(F6:F35) -> 33560
B37: SECTION - B CONCRETE
A38: B-01 | B38: Providing and laying Plain cement concrete below all R.C.C. member, floors, ramps, chembers etc. with 20mm nominal size graded stone aggregates of approved quality (black trap only) including leveling, compacting, curing and form work if any, etc. complete.
B39: a) Mix 1: 4: 8 | C39: 2 | D39: CUM | E39: 4100 | F39: =E39*C39 -> 8200
B40: b) Mix 1: 3: 6 | D40: CUM | E40: 4175 | F40: =E40*C40 -> 0
...

Sheet BOQ -COOLING TOWER 
B1: ESTIMATED BOQ FOR PROPOSED COOLING TOWER CIVIL & STRUCTURAL WORKS For SUYOG ELECTRICAL LTD. NO 245/33/B,245/55/B/2,MOJE BODIDARA, TA.VADODARA, GUJARAT, INDIA.
A2: Followings are the scope of work: - COOLING TOWER Civil and Structural works (Excluding PEB shed) - Approximately 500 TR - 2nos -
A3: BOQ
A4: Sr. No. | B4: Description | C4: QTY. | D4: UNIT | E4: RATE | F4: AMOUNT
B5: SECTION- A EARTH WORK AND SOLING
A6: A-01 | B6: Cleaning the area by grass cutting, removing vegetations,roots of trees if any, scraping the existing surfaces up to 150mm, removal of all loose materials and other matters, etc. and disposing off the debris beyond the plant boundary as directed by the Engineer. | C6: 109 | D6: SQ.M. | E6: 35 | F6: =E6*C6 -> 3815
A7: A-01A | B7: Clearing the area by jungle cutting, removing trees / bushes if any from roots, scraping the existing surfaces up to 150mm, removal of all loose materials and other matters, etc. and disposing off the debris beyond the plant boundary as directed by EIC. | D7: SQ.M. | E7: 25 | F7: =E7*C7 -> 0
A8: A-02 | B8: Earth work excavation for all type of work in all soils like black cotton soil, clay, sand, soft and hard murrum, etc. but other than soft and hard rock including shoring, strutting and dewatering due to any sub soil water, rain water or any reason if required and refilling in foundations with selected excavated earth in 350mm layers, watering and consolidating to 250mm thickness, disposing off surplus excavated materials within the plant boundary at selected places, spreading evenly, leveling, etc. complete as per specifications and as directed. (Payment shall be made for 300mm from R.C.C. face for foundations and 200mm from R.C.C. face for GB)
B9: a) From average ground level up to 1.50M depth. | C9: 14 | D9: CUM | E9: 250 | F9: =E9*C9 -> 3500
B10: b) Below 1.5M up to 3M depth | D10: CUM | E10: 285 | F10: =E10*C10 -> 0
B11: c) Below 3.0M up to 4.5M depth | D11: CUM | E11: 350
B12: d) Below 4.5M up to 6.0M depth | D12: CUM | E12: 450
B13: e) Below 6.0M up to 7.5M depth | D13: CUM | E13: 575
A14: A-03 | B14: Filling in plinth & foundation pits with approved materials including spreading in 150mm layers, watering, ramming, compacting with 10MT vibro/static roller or portable compactor wherever applicable as decided by the Engineer, leveling, etc. complete. (Measurements for compacted volume is considered)
B15: a) With selected earth brought from outside | C15: 16 | D15: CUM | E15: 490 | F15: =E15*C15 -> 7840
B16: b) With approved filling sand brought from Outside. | C16: 16 | D16: CUM | E16: 1025 | F16: =E16*C16 -> 16400
B17: c) Approved quarry dust filling | D17: CUM | E17: 1150
A18: A-04 | B18: Disposing off surplus excavated materials by carting away, outside of company premises at location decided by contractor and shall be responsibility of contractor | D18: CUM | E18: 150 | F18: =E18*C18 -> 0
A19: A-04A | B19: Disposing off dumped Earth / Debris by carting away, outside of company premises at location decided by contractor and shall be responsibility of contractor
B20: a) Measurement of available material by volume | D20: CUM | E20: 100 | F20: =E20*C20 -> 0
B21: b) Measurement of available material by Dumper | D21: Nos. | E21: 3500
A22: A-05 | B22: Providing and laying black trap rubble soling at required level and grade in foundations, in plinth, ramps, etc. including hand packing, filling interstices with quarry / sand, watering and compacting with suitable vibro roller/ Static roller or earth compactor wherever applicable as decided by the Engineer to the consolidated thickness as stated below:
B23: i) 230mm thick Soling | D23: SQ.M | E23: 517
B24: ii) 150mm thick compacted layer metal packing using 63-90 mm size hand broken stone etc. as directed Engineer in charge/consultant. | C24: 76 | D24: SQ.M | E24: 310 | F24: =E24*C24 -> 23560
B25: iii) 75mm thick compacted layer metal packing using 40-63 mm size hand broken stone etc. as directed Engineer in charge/consultant. | C25: 76 | D25: SQ.M | E25: 150 | F25: =E25*C25 -> 11400
A26: A-06 | B26: Auguring(Upto 8m depth) of under ream pile foundation work in all sorts of soil viz. sand, clay, soft & hard murrum for execution of the above work. Contractor has to brought all necessary tools, tackles, equipments, manpower & supervision. Items also include carting of debris/soil, unloading, stacking, use of bentonite, spreading, levelling, compacting, consolidating surplus marterial within company premises, dewatering & one bulb as per design etc. complete as directed
B27: (a) For 250mm dia. Pile | D27: RM | E27: 300
B28: (b) For 300mm dia. Pile | D28: RM | E28: 350 | F28: =E28*C28 -> 0
B29: (c) For 350mm dia. Pile | D29: RM | E29: 425 | F29: =E29*C29 -> 0
B30: (d) For 400mm dia. Pile | D30: RM | E30: 495 | F30: =E30*C30 -> 0
B31: (e) For 450mm dia. Pile | C31: 77 | D31: RM | E31: 500 | F31: =E31*C31 -> 38500
A32: A-07 | B32: -do- as per item no. A-06 but for construction of extra bulb in the pile at any level. The size of the bulb will be as per design.
B33: (a) For 250mm dia. Pile | D33: NO | E33: 300
B34: (b) For 300mm dia. Pile | D34: NO | E34: 400
B35: (c) For 350mm dia. Pile | D35: NO | E35: 450
B36: (d) For 400mm dia. Pile | D36: NO | E36: 500
B37: TOTAL OF SECTION `A` | F37: =SUM(F6:F36) -> 105015
B38: SECTION - B CONCRETE
A39: B-01 | B39: Providing and laying Plain cement concrete below all R.C.C. member, floors, ramps, chembers etc. with 20mm nominal size graded stone aggregates of approved quality (black trap only) including leveling, compacting, curing and form work if any, etc. complete.
B40: a) Mix 1: 4: 8 | C40: 2 | D40: CUM | E40: 4100 | F40: =E40*C40 -> 8200
...

Sheet BOQ -WEIGH BRIDGE 
B1: ESTIMATED BOQ FOR PROPOSED WEIGH BRIDGE CIVIL & STRUCTURAL WORKS For SUYOG ELECTRICAL LTD. NO 245/33/B,245/55/B/2,MOJE BODIDARA, TA.VADODARA, GUJARAT, INDIA.
A2: Followings are the scope of work: - 100 TON WEIGH BRIDGE Civil and Structural works (Excluding PEB shed) - Approximately 100 TON -
A3: BOQ
A4: Sr. No. | B4: Description | C4: QTY. | D4: UNIT | E4: RATE | F4: AMOUNT
B5: SECTION- A EARTH WORK AND SOLING
A6: A-01 | B6: Cleaning the area by grass cutting, removing vegetations,roots of trees if any, scraping the existing surfaces up to 150mm, removal of all loose materials and other matters, etc. and disposing off the debris beyond the plant boundary as directed by the Engineer. | C6: 87 | D6: SQ.M. | E6: 35 | F6: =E6*C6 -> 3045
A7: A-01A | B7: Clearing the area by jungle cutting, removing trees / bushes if any from roots, scraping the existing surfaces up to 150mm, removal of all loose materials and other matters, etc. and disposing off the debris beyond the plant boundary as directed by EIC. | D7: SQ.M. | E7: 25 | F7: =E7*C7 -> 0
A8: A-02 | B8: Earth work excavation for all type of work in all soils like black cotton soil, clay, sand, soft and hard murrum, etc. but other than soft and hard rock including shoring, strutting and dewatering due to any sub soil water, rain water or any reason if required and refilling in foundations with selected excavated earth in 350mm layers, watering and consolidating to 250mm thickness, disposing off surplus excavated materials within the plant boundary at selected places, spreading evenly, leveling, etc. complete as per specifications and as directed. (Payment shall be made for 300mm from R.C.C. face for foundations and 200mm from R.C.C. face for GB)
B9: a) From average ground level up to 1.50M depth. | C9: 168 | D9: CUM | E9: 250 | F9: =E9*C9 -> 42000
B10: b) Below 1.5M up to 3M depth | C10: 42 | D10: CUM | E10: 285 | F10: =E10*C10 -> 11970
B11: c) Below 3.0M up to 4.5M depth | D11: CUM | E11: 350
B12: d) Below 4.5M up to 6.0M depth | D12: CUM | E12: 450
B13: e) Below 6.0M up to 7.5M depth | D13: CUM | E13: 575
A14: A-03 | B14: Filling in plinth & foundation pits with approved materials including spreading in 150mm layers, watering, ramming, compacting with 10MT vibro/static roller or portable compactor wherever applicable as decided by the Engineer, leveling, etc. complete. (Measurements for compacted volume is considered)
B15: a) With selected earth brought from outside | C15: 5 | D15: CUM | E15: 490 | F15: =E15*C15 -> 2450
B16: b) With approved filling sand brought from Outside. | C16: 21 | D16: CUM | E16: 1025 | F16: =E16*C16 -> 21525
B17: c) Approved quarry dust filling | D17: CUM | E17: 1150
A18: A-04 | B18: Disposing off surplus excavated materials by carting away, outside of company premises at location decided by contractor and shall be responsibility of contractor | C18: 187 | D18: CUM | E18: 150 | F18: =E18*C18 -> 28050
A19: A-04A | B19: Disposing off dumped Earth / Debris by carting away, outside of company premises at location decided by contractor and shall be responsibility of contractor
B20: a) Measurement of available material by volume | D20: CUM | E20: 100 | F20: =E20*C20 -> 0
B21: b) Measurement of available material by Dumper | D21: Nos. | E21: 3500
A22: A-05 | B22: Providing and laying black trap rubble soling at required level and grade in foundations, in plinth, ramps, etc. including hand packing, filling interstices with quarry / sand, watering and compacting with suitable vibro roller/ Static roller or earth compactor wherever applicable as decided by the Engineer to the consolidated thickness as stated below:
B23: i) 230mm thick Soling | D23: SQ.M | E23: 517
B24: ii) 150mm thick compacted layer metal packing using 63-90 mm size hand broken stone etc. as directed Engineer in charge/consultant. | C24: 116 | D24: SQ.M | E24: 310 | F24: =E24*C24 -> 35960
B25: iii) 75mm thick compacted layer metal packing using 40-63 mm size hand broken stone etc. as directed Engineer in charge/consultant. | D25: SQ.M | E25: 150 | F25: =E25*C25 -> 0
A26: A-06 | B26: Auguring(Upto 8m depth) of under ream pile foundation work in all sorts of soil viz. sand, clay, soft & hard murrum for execution of the above work. Contractor has to brought all necessary tools, tackles, equipments, manpower & supervision. Items also include carting of debris/soil, unloading, stacking, use of bentonite, spreading, levelling, compacting, consolidating surplus marterial within company premises, dewatering & one bulb as per design etc. complete as directed
B27: (a) For 250mm dia. Pile | D27: RM | E27: 300
B28: (b) For 300mm dia. Pile | D28: RM | E28: 350 | F28: =E28*C28 -> 0
B29: (c) For 350mm dia. Pile | D29: RM | E29: 425 | F29: =E29*C29 -> 0
B30: (d) For 400mm dia. Pile | D30: RM | E30: 495 | F30: =E30*C30 -> 0
A31: A-07 | B31: -do- as per item no. A-06 but for construction of extra bulb in the pile at any level. The size of the bulb will be as per design.
B32: (a) For 250mm dia. Pile | D32: NO | E32: 300
B33: (b) For 300mm dia. Pile | D33: NO | E33: 400
B34: (c) For 350mm dia. Pile | D34: NO | E34: 450
B35: (d) For 400mm dia. Pile | D35: NO | E35: 500
B36: TOTAL OF SECTION `A` | F36: =SUM(F6:F35) -> 145000
B37: SECTION - B CONCRETE
A38: B-01 | B38: Providing and laying Plain cement concrete below all R.C.C. member, floors, ramps, chembers etc. with 20mm nominal size graded stone aggregates of approved quality (black trap only) including leveling, compacting, curing and form work if any, etc. complete.
B39: a) Mix 1: 4: 8 | C39: 10 | D39: CUM | E39: 4100 | F39: =E39*C39 -> 41000
B40: b) Mix 1: 3: 6 | D40: CUM | E40: 4175 | F40: =E40*C40 -> 0
...

Sheet BOQ -U.G TANK WITH PUMP ROOM 
B1: ESTIMATED BOQ FOR PROPOSED U.G TANK WITH PUMP ROOM CIVIL & STRUCTURAL WORKS For SUYOG ELECTRICAL LTD. NO 245/33/B,245/55/B/2,MOJE BODIDARA, TA.VADODARA, GUJARAT, INDIA.
A2: Followings are the scope of work: - 2 LAKH LITTRE +1 LAKH LITTRE WITH MC ROOM Civil and Structural works (Excluding PEB shed) - Approximately 72 SQM TANK + 40 SQM PUMP ROOM -
A3: BOQ
A4: Sr. No. | B4: Description | C4: QTY. | D4: UNIT | E4: RATE | F4: AMOUNT
B5: SECTION- A EARTH WORK AND SOLING
A6: A-01 | B6: Cleaning the area by grass cutting, removing vegetations,roots of trees if any, scraping the existing surfaces up to 150mm, removal of all loose materials and other matters, etc. and disposing off the debris beyond the plant boundary as directed by the Engineer. | C6: 76 | D6: SQ.M. | E6: 35 | F6: =E6*C6 -> 2660
A7: A-01A | B7: Clearing the area by jungle cutting, removing trees / bushes if any from roots, scraping the existing surfaces up to 150mm, removal of all loose materials and other matters, etc. and disposing off the debris beyond the plant boundary as directed by EIC. | D7: SQ.M. | E7: 25 | F7: =E7*C7 -> 0
A8: A-02 | B8: Earth work excavation for all type of work in all soils like black cotton soil, clay, sand, soft and hard murrum, etc. but other than soft and hard rock including shoring, strutting and dewatering due to any sub soil water, rain water or any reason if required and refilling in foundations with selected excavated earth in 350mm layers, watering and consolidating to 250mm thickness, disposing off surplus excavated materials within the plant boundary at selected places, spreading evenly, leveling, etc. complete as per specifications and as directed. (Payment shall be made for 300mm from R.C.C. face for foundations and 200mm from R.C.C. face for GB)
B9: a) From average ground level up to 1.50M depth. | C9: 131 | D9: CUM | E9: 250 | F9: =E9*C9 -> 32750
B10: b) Below 1.5M up to 3M depth | C10: 131 | D10: CUM | E10: 285 | F10: =E10*C10 -> 37335
B11: c) Below 3.0M up to 4.5M depth | C11: 53 | D11: CUM | E11: 350 | F11: =E11*C11 -> 18550
B12: d) Below 4.5M up to 6.0M depth | C12: QRO | D12: CUM | E12: 450
B13: e) Below 6.0M up to 7.5M depth | C13: QRO | D13: CUM | E13: 575
A14: A-03 | B14: Filling in plinth & foundation pits with approved materials including spreading in 150mm layers, watering, ramming, compacting with 10MT vibro/static roller or portable compactor wherever applicable as decided by the Engineer, leveling, etc. complete. (Measurements for compacted volume is considered)
B15: a) With selected earth brought from outside | C15: 16 | D15: CUM | E15: 490 | F15: =E15*C15 -> 7840
B16: b) With approved filling sand brought from Outside. | D16: CUM | E16: 1025 | F16: =E16*C16 -> 0
B17: c) Approved quarry dust filling | D17: CUM | E17: 1150
A18: A-04 | B18: Disposing off surplus excavated materials by carting away, outside of company premises at location decided by contractor and shall be responsibility of contractor | D18: CUM | E18: 150 | F18: =E18*C18 -> 0
A19: A-04A | B19: Disposing off dumped Earth / Debris by carting away, outside of company premises at location decided by contractor and shall be responsibility of contractor
B20: a) Measurement of available material by volume | D20: CUM | E20: 100 | F20: =E20*C20 -> 0
B21: b) Measurement of available material by Dumper | D21: Nos. | E21: 3500
A22: A-05 | B22: Providing and laying black trap rubble soling at required level and grade in foundations, in plinth, ramps, etc. including hand packing, filling interstices with quarry / sand, watering and compacting with suitable vibro roller/ Static roller or earth compactor wherever applicable as decided by the Engineer to the consolidated thickness as stated below:
B23: i) 230mm thick Soling | D23: SQ.M | E23: 517
B24: ii) 150mm thick compacted layer metal packing using 63-90 mm size hand broken stone etc. as directed Engineer in charge/consultant. | C24: 79 | D24: SQ.M | E24: 310 | F24: =E24*C24 -> 24490
B25: iii) 75mm thick compacted layer metal packing using 40-63 mm size hand broken stone etc. as directed Engineer in charge/consultant. | C25: 79 | D25: SQ.M | E25: 150 | F25: =E25*C25 -> 11850
A26: A-06 | B26: Auguring(Upto 8m depth) of under ream pile foundation work in all sorts of soil viz. sand, clay, soft & hard murrum for execution of the above work. Contractor has to brought all necessary tools, tackles, equipments, manpower & supervision. Items also include carting of debris/soil, unloading, stacking, use of bentonite, spreading, levelling, compacting, consolidating surplus marterial within company premises, dewatering & one bulb as per design etc. complete as directed
B27: (a) For 250mm dia. Pile | D27: RM | E27: 300
B28: (b) For 300mm dia. Pile | D28: RM | E28: 350 | F28: =E28*C28 -> 0
B29: (c) For 350mm dia. Pile | D29: RM | E29: 425 | F29: =E29*C29 -> 0
B30: (d) For 400mm dia. Pile | D30: RM | E30: 495 | F30: =E30*C30 -> 0
A31: A-07 | B31: -do- as per item no. A-06 but for construction of extra bulb in the pile at any level. The size of the bulb will be as per design.
B32: (a) For 250mm dia. Pile | D32: NO | E32: 300
B33: (b) For 300mm dia. Pile | D33: NO | E33: 400
B34: (c) For 350mm dia. Pile | D34: NO | E34: 450
B35: (d) For 400mm dia. Pile | D35: NO | E35: 500
B36: TOTAL OF SECTION `A` | F36: =SUM(F6:F35) -> 135475
B37: SECTION - B CONCRETE
A38: B-01 | B38: Providing and laying Plain cement concrete below all R.C.C. member, floors, ramps, chembers etc. with 20mm nominal size graded stone aggregates of approved quality (black trap only) including leveling, compacting, curing and form work if any, etc. complete.
B39: a) Mix 1: 4: 8 | C39: 8 | D39: CUM | E39: 4100 | F39: =E39*C39 -> 32800
B40: b) Mix 1: 3: 6 | D40: CUM | E40: 4175 | F40: =E40*C40 -> 0
...

Sheet BOQ -ENTRANCE GATE 
B1: ESTIMATED BOQ FOR PROPOSED WEIGH BRIDGE CIVIL & STRUCTURAL WORKS For SUYOG ELECTRICAL LTD. NO 245/33/B,245/55/B/2,MOJE BODIDARA, TA.VADODARA, GUJARAT, INDIA.
A2: Followings are the scope of work: - 9.0 M WIDE GATE - | I2: GATE AREA
A3: BOQ
A4: Sr. No. | B4: Description | C4: QTY. | D4: UNIT | E4: RATE | F4: AMOUNT
B5: SECTION- A EARTH WORK AND SOLING
A6: A-01 | B6: Cleaning the area by grass cutting, removing vegetations,roots of trees if any, scraping the existing surfaces up to 150mm, removal of all loose materials and other matters, etc. and disposing off the debris beyond the plant boundary as directed by the Engineer. | C6: 140 | D6: SQ.M. | E6: 35 | F6: =E6*C6 -> 4900
A7: A-01A | B7: Clearing the area by jungle cutting, removing trees / bushes if any from roots, scraping the existing surfaces up to 150mm, removal of all loose materials and other matters, etc. and disposing off the debris beyond the plant boundary as directed by EIC. | D7: SQ.M. | E7: 25 | F7: =E7*C7 -> 0
A8: A-02 | B8: Earth work excavation for all type of work in all soils like black cotton soil, clay, sand, soft and hard murrum, etc. but other than soft and hard rock including shoring, strutting and dewatering due to any sub soil water, rain water or any reason if required and refilling in foundations with selected excavated earth in 350mm layers, watering and consolidating to 250mm thickness, disposing off surplus excavated materials within the plant boundary at selected places, spreading evenly, leveling, etc. complete as per specifications and as directed. (Payment shall be made for 300mm from R.C.C. face for foundations and 200mm from R.C.C. face for GB)
B9: a) From average ground level up to 1.50M depth. | C9: 27 | D9: CUM | E9: 250 | F9: =E9*C9 -> 6750
B10: b) Below 1.5M up to 3M depth | D10: CUM | E10: 285 | F10: =E10*C10 -> 0
B11: c) Below 3.0M up to 4.5M depth | D11: CUM | E11: 350 | F11: =E11*C11 -> 0
B12: d) Below 4.5M up to 6.0M depth | D12: CUM | E12: 450
B13: e) Below 6.0M up to 7.5M depth | D13: CUM | E13: 575
A14: A-03 | B14: Filling in plinth & foundation pits with approved materials including spreading in 150mm layers, watering, ramming, compacting with 10MT vibro/static roller or portable compactor wherever applicable as decided by the Engineer, leveling, etc. complete. (Measurements for compacted volume is considered)
B15: a) With selected earth brought from outside | C15: 3 | D15: CUM | E15: 490 | F15: =E15*C15 -> 1470
B16: b) With approved filling sand brought from Outside. | C16: 2 | D16: CUM | E16: 1025 | F16: =E16*C16 -> 2050
B17: c) Approved quarry dust filling | D17: CUM | E17: 1150
A18: A-04 | B18: Disposing off surplus excavated materials by carting away, outside of company premises at location decided by contractor and shall be responsibility of contractor | C18: 17 | D18: CUM | E18: 150 | F18: =E18*C18 -> 2550
A19: A-04A | B19: Disposing off dumped Earth / Debris by carting away, outside of company premises at location decided by contractor and shall be responsibility of contractor
B20: a) Measurement of available material by volume | D20: CUM | E20: 100 | F20: =E20*C20 -> 0
B21: b) Measurement of available material by Dumper | D21: Nos. | E21: 3500
A22: A-05 | B22: Providing and laying black trap rubble soling at required level and grade in foundations, in plinth, ramps, etc. including hand packing, filling interstices with quarry / sand, watering and compacting with suitable vibro roller/ Static roller or earth compactor wherever applicable as decided by the Engineer to the consolidated thickness as stated below:
B23: i) 230mm thick Soling | D23: SQ.M | E23: 517
B24: ii) 150mm thick compacted layer metal packing using 63-90 mm size hand broken stone etc. as directed Engineer in charge/consultant. | C24: 13 | D24: SQ.M | E24: 310 | F24: =E24*C24 -> 4030
B25: iii) 75mm thick compacted layer metal packing using 40-63 mm size hand broken stone etc. as directed Engineer in charge/consultant. | D25: SQ.M | E25: 150 | F25: =E25*C25 -> 0
A26: A-06 | B26: Auguring(Upto 8m depth) of under ream pile foundation work in all sorts of soil viz. sand, clay, soft & hard murrum for execution of the above work. Contractor has to brought all necessary tools, tackles, equipments, manpower & supervision. Items also include carting of debris/soil, unloading, stacking, use of bentonite, spreading, levelling, compacting, consolidating surplus marterial within company premises, dewatering & one bulb as per design etc. complete as directed
B27: (a) For 250mm dia. Pile | D27: RM | E27: 300
B28: (b) For 300mm dia. Pile | D28: RM | E28: 350 | F28: =E28*C28 -> 0
B29: (c) For 350mm dia. Pile | C29: 84 | D29: RM | E29: 425 | F29: =E29*C29 -> 35700
B30: (d) For 400mm dia. Pile | D30: RM | E30: 495 | F30: =E30*C30 -> 0
A31: A-07 | B31: -do- as per item no. A-06 but for construction of extra bulb in the pile at any level. The size of the bulb will be as per design.
B32: (a) For 250mm dia. Pile | D32: NO | E32: 300
B33: (b) For 300mm dia. Pile | D33: NO | E33: 400
B34: (c) For 350mm dia. Pile | D34: NO | E34: 450
B35: (d) For 400mm dia. Pile | D35: NO | E35: 500
B36: TOTAL OF SECTION `A` | F36: =SUM(F6:F35) -> 57450
B37: SECTION - B CONCRETE
A38: B-01 | B38: Providing and laying Plain cement concrete below all R.C.C. member, floors, ramps, chembers etc. with 20mm nominal size graded stone aggregates of approved quality (black trap only) including leveling, compacting, curing and form work if any, etc. complete.
B39: a) Mix 1: 4: 8 | C39: 2 | D39: CUM | E39: 4100 | F39: =E39*C39 -> 8200
B40: b) Mix 1: 3: 6 | D40: CUM | E40: 4175 | F40: =E40*C40 -> 0
...
