Workbook

Sheet DASHBOARD
A1: SPDC | D1: DAILY PROGRESS REPORT | O1: Report Date | R1: =INPUT!$B$14 -> 46234
O2: Data Date | R2: =INPUT!$B$15 -> 46234
D3: PLUMBING, WATER SUPPLY & DRAINAGE PACKAGE | O3: Report No. / Day | R3: =INPUT!$B$16&" | "&TEXT(INPUT!$B$15,"DDDD") -> DPR/PLB-027 | Friday | Y3: S-CURVE DATA (not printed)
A4: Project Name | C4: =INPUT!$B$4 -> <Client / Project Name> | I4: Contract / PO Ref. | K4: =INPUT!$B$9 -> <Work Order No. & Date> | O4: PROJECT HEALTH | Y4: DATE | Z4: PLANNED CUM % | AA4: ACTUAL CUM % | AB4: NOTE
A5: Project Manager | C5: =INPUT!$B$5 -> <PMC Project Manager> | I5: Contract Completion | K5: =INPUT!$B$10 -> 46295 | O5: Overall Status | S5: =IF($V$28="ON TRACK","ON PROGRAMME","BEHIND PROGRAMME") -> BEHIND PROGRAMME | Y5: =INPUT!$A$125 -> 46204 | Z5: =SUMPRODUCT($I$13:$I$27,(($Y5>=$K$13:$K$27)+($Y5<$K$13:$K$27)*($Y5>=$J$13:$J$27)*(($Y5-$J$13:$J$27+1)/($K$13:$K$27-$J$13:$J$27+1)))) -> 0 | AA5: =IF(INPUT!$B$125="","",INPUT!$B$125) -> 0 | AB5: from INPUT sheet section 14
A6: Contractor / Vendor | C6: =INPUT!$B$6 -> <Executing Agency / PEB Vendor> | I6: Calendar / Weather | K6: =INPUT!$B$11&" | "&INPUT!$B$13 -> 6 Days / Week – 8 hrs | Partly Cloudy, 32 °C | O6: Critical / High issues open | S6: =COUNTIF(INPUT!$E$101:$E$104,"Critical")+COUNTIF(INPUT!$E$101:$E$104,"High") -> 3 | Y6: =INPUT!$A$126 -> 46209 | Z6: =SUMPRODUCT($I$13:$I$27,(($Y6>=$K$13:$K$27)+($Y6<$K$13:$K$27)*($Y6>=$J$13:$J$27)*(($Y6-$J$13:$J$27+1)/($K$13:$K$27-$J$13:$J$27+1)))) -> 0 | AA6: =IF(INPUT!$B$126="","",INPUT!$B$126) -> 0.012004955 | AB6: from INPUT sheet section 14
A7: Location | C7: =INPUT!$B$7 -> <Plot / GIDC / District> | I7: Contract Value (₹ Lakh) | K7: =SUMPRODUCT($G$13:$G$27,$H$13:$H$27)/100000 -> 76.688 | O7: Approvals pending > 7 days | S7: =SUMPRODUCT((INPUT!$B$15-INPUT!$E$94:$E$97>7)*(INPUT!$A$94:$A$97<>"")) -> 3 | Y7: =INPUT!$A$127 -> 46214 | Z7: =SUMPRODUCT($I$13:$I$27,(($Y7>=$K$13:$K$27)+($Y7<$K$13:$K$27)*($Y7>=$J$13:$J$27)*(($Y7-$J$13:$J$27+1)/($K$13:$K$27-$J$13:$J$27+1)))) -> 0.0024148692 | AA7: =IF(INPUT!$B$127="","",INPUT!$B$127) -> 0.030008632 | AB7: from INPUT sheet section 14
A8: 1. KEY PERFORMANCE INDICATORS (all calculated — nothing is typed on this sheet) | Y8: =INPUT!$A$128 -> 46219 | Z8: =SUMPRODUCT($I$13:$I$27,(($Y8>=$K$13:$K$27)+($Y8<$K$13:$K$27)*($Y8>=$J$13:$J$27)*(($Y8-$J$13:$J$27+1)/($K$13:$K$27-$J$13:$J$27+1)))) -> 0.013793884 | AA8: =IF(INPUT!$B$128="","",INPUT!$B$128) -> 0.052016169 | AB8: from INPUT sheet section 14
A9: PLANNED % | D9: ACTUAL % | G9: VARIANCE | J9: SPI | M9: EARNED VALUE ₹ L | P9: VALUE DONE TODAY ₹ | S9: ITEMS DELAYED | U9: HRS LOST TODAY | Y9: =INPUT!$A$129 -> 46224 | Z9: =SUMPRODUCT($I$13:$I$27,(($Y9>=$K$13:$K$27)+($Y9<$K$13:$K$27)*($Y9>=$J$13:$J$27)*(($Y9-$J$13:$J$27+1)/($K$13:$K$27-$J$13:$J$27+1)))) -> 0.034272316 | AA9: =IF(INPUT!$B$129="","",INPUT!$B$129) -> 0.066745775 | AB9: from INPUT sheet section 14
A10: =$T$28 -> 0.085240637 | D10: =$U$28 -> 0.066745775 | G10: =$U$28-$T$28 -> -0.018494862 | J10: =IFERROR($U$28/$T$28,0) -> 0.78302764 | M10: =SUMPRODUCT($G$13:$G$27,$H$13:$H$27,$R$13:$R$27)/100000 -> 5.1186 | P10: =SUM($S$13:$S$27) -> 74760 | S10: =COUNTIF($V$13:$V$27,"Delay") -> 2 | U10: =$U$60 -> 5 | Y10: =INPUT!$A$130 -> 46229 | Z10: =SUMPRODUCT($I$13:$I$27,(($Y10>=$K$13:$K$27)+($Y10<$K$13:$K$27)*($Y10>=$J$13:$J$27)*(($Y10-$J$13:$J$27+1)/($K$13:$K$27-$J$13:$J$27+1)))) -> 0.058309728 | AA10: =IF(INPUT!$B$130="","",INPUT!$B$130) -> 0.066745775 | AB10: from INPUT sheet section 14
A11: 2. QUANTITY / PHYSICAL PROGRESS — ITEM-WISE (basis of the % complete above) | Y11: =INPUT!$A$131 -> 46234 | Z11: =SUMPRODUCT($I$13:$I$27,(($Y11>=$K$13:$K$27)+($Y11<$K$13:$K$27)*($Y11>=$J$13:$J$27)*(($Y11-$J$13:$J$27+1)/($K$13:$K$27-$J$13:$J$27+1)))) -> 0.085240637 | AA11: =$U$28 -> 0.066745775 | AB11: ◄ today – from the quantity table
A12: SL | B12: DESCRIPTION OF ITEM | F12: UNIT | G12: SCOPE QTY | H12: RATE ₹ | I12: WEIGHT-AGE % | J12: START | K12: FINISH | L12: DAYS +/− | M12: PLANNED % | N12: CUM QTY PREV. | O12: QTY TODAY | P12: CUM QTY TO DATE | Q12: BALANCE QTY | R12: % COMPL. | S12: EARNED ₹ TODAY | T12: WTD. PLANNED % | U12: WTD. ACTUAL % | V12: STATUS | Y12: =INPUT!$A$132 -> 46239 | Z12: =SUMPRODUCT($I$13:$I$27,(($Y12>=$K$13:$K$27)+($Y12<$K$13:$K$27)*($Y12>=$J$13:$J$27)*(($Y12-$J$13:$J$27+1)/($K$13:$K$27-$J$13:$J$27+1)))) -> 0.11217155 | AA12: =IF(INPUT!$B$132="","",INPUT!$B$132) | AB12: from INPUT sheet section 14
A13: 1 | B13: =INPUT!$B$24 -> UG HDPE water line 90 mm with fittings | F13: =INPUT!$E$24 -> RM | G13: =INPUT!$F$24 -> 640 | H13: =INPUT!$G$24 -> 680 | I13: =IFERROR(G13*H13/SUMPRODUCT($G$13:$G$27,$H$13:$H$27),0) -> 0.056749426 | J13: =INPUT!$H$24 -> 46213 | K13: =INPUT!$I$24 -> 46259 | L13: =K13-INPUT!$B$15 -> 25 | M13: =IF(INPUT!$B$15>=K13,1,IF(INPUT!$B$15<J13,0,(INPUT!$B$15-J13+1)/(K13-J13+1))) -> 0.46808511 | N13: =INPUT!$J$24 -> 180 | O13: =INPUT!$K$24 -> 22 | P13: =N13+O13 -> 202 | Q13: =G13-P13 -> 438 | R13: =IFERROR(MIN(P13/G13,1),0) -> 0.315625 | S13: =O13*H13 -> 14960 | T13: =I13*M13 -> 0.026563561 | U13: =I13*R13 -> 0.017911538 | V13: =IF(M13=0,"Not Started",IF(R13>=0.999,"Completed",IF(R13>=M13,"On Track",IF(R13>=M13*0.8,"In Progress","Delay")))) -> Delay | X13: =INPUT!$A$24 -> PLB-10 | Y13: =INPUT!$A$133 -> 46244 | Z13: =SUMPRODUCT($I$13:$I$27,(($Y13>=$K$13:$K$27)+($Y13<$K$13:$K$27)*($Y13>=$J$13:$J$27)*(($Y13-$J$13:$J$27+1)/($K$13:$K$27-$J$13:$J$27+1)))) -> 0.13910246 | AA13: =IF(INPUT!$B$133="","",INPUT!$B$133) | AB13: from INPUT sheet section 14
A14: 2 | B14: =INPUT!$B$25 -> UG sump, pump room piping & valves | F14: =INPUT!$E$25 -> LS | G14: =INPUT!$F$25 -> 1 | H14: =INPUT!$G$25 -> 480000 | I14: =IFERROR(G14*H14/SUMPRODUCT($G$13:$G$27,$H$13:$H$27),0) -> 0.062591279 | J14: =INPUT!$H$25 -> 46249 | K14: =INPUT!$I$25 -> 46295 | L14: =K14-INPUT!$B$15 -> 61 | M14: =IF(INPUT!$B$15>=K14,1,IF(INPUT!$B$15<J14,0,(INPUT!$B$15-J14+1)/(K14-J14+1))) -> 0 | N14: =INPUT!$J$25 -> 0 | O14: =INPUT!$K$25 -> 0 | P14: =N14+O14 -> 0 | Q14: =G14-P14 -> 1 | R14: =IFERROR(MIN(P14/G14,1),0) -> 0 | S14: =O14*H14 -> 0 | T14: =I14*M14 -> 0 | U14: =I14*R14 -> 0 | V14: =IF(M14=0,"Not Started",IF(R14>=0.999,"Completed",IF(R14>=M14,"On Track",IF(R14>=M14*0.8,"In Progress","Delay")))) -> Not Started | X14: =INPUT!$A$25 -> PLB-10 | Y14: =INPUT!$A$134 -> 46249 | Z14: =SUMPRODUCT($I$13:$I$27,(($Y14>=$K$13:$K$27)+($Y14<$K$13:$K$27)*($Y14>=$J$13:$J$27)*(($Y14-$J$13:$J$27+1)/($K$13:$K$27-$J$13:$J$27+1)))) -> 0.16736509 | AA14: =IF(INPUT!$B$134="","",INPUT!$B$134) | AB14: from INPUT sheet section 14
A15: 3 | B15: =INPUT!$B$26 -> Water meter, valves & masonry chambers | F15: =INPUT!$E$26 -> NOS | G15: =INPUT!$F$26 -> 16 | H15: =INPUT!$G$26 -> 12500 | I15: =IFERROR(G15*H15/SUMPRODUCT($G$13:$G$27,$H$13:$H$27),0) -> 0.0260797 | J15: =INPUT!$H$26 -> 46223 | K15: =INPUT!$I$26 -> 46270 | L15: =K15-INPUT!$B$15 -> 36 | M15: =IF(INPUT!$B$15>=K15,1,IF(INPUT!$B$15<J15,0,(INPUT!$B$15-J15+1)/(K15-J15+1))) -> 0.25 | N15: =INPUT!$J$26 -> 3 | O15: =INPUT!$K$26 -> 1 | P15: =N15+O15 -> 4 | Q15: =G15-P15 -> 12 | R15: =IFERROR(MIN(P15/G15,1),0) -> 0.25 | S15: =O15*H15 -> 12500 | T15: =I15*M15 -> 0.0065199249 | U15: =I15*R15 -> 0.0065199249 | V15: =IF(M15=0,"Not Started",IF(R15>=0.999,"Completed",IF(R15>=M15,"On Track",IF(R15>=M15*0.8,"In Progress","Delay")))) -> On Track | X15: =INPUT!$A$26 -> PLB-10 | Y15: =INPUT!$A$135 -> 46254 | Z15: =SUMPRODUCT($I$13:$I$27,(($Y15>=$K$13:$K$27)+($Y15<$K$13:$K$27)*($Y15>=$J$13:$J$27)*(($Y15-$J$13:$J$27+1)/($K$13:$K$27-$J$13:$J$27+1)))) -> 0.20352746 | AA15: =IF(INPUT!$B$135="","",INPUT!$B$135) | AB15: from INPUT sheet section 14
A16: 4 | B16: =INPUT!$B$27 -> CPVC piping 25 to 50 mm concealed | F16: =INPUT!$E$27 -> RM | G16: =INPUT!$F$27 -> 1450 | H16: =INPUT!$G$27 -> 420 | I16: =IFERROR(G16*H16/SUMPRODUCT($G$13:$G$27,$H$13:$H$27),0) -> 0.079412685 | J16: =INPUT!$H$27 -> 46254 | K16: =INPUT!$I$27 -> 46310 | L16: =K16-INPUT!$B$15 -> 76 | M16: =IF(INPUT!$B$15>=K16,1,IF(INPUT!$B$15<J16,0,(INPUT!$B$15-J16+1)/(K16-J16+1))) -> 0 | N16: =INPUT!$J$27 -> 0 | O16: =INPUT!$K$27 -> 0 | P16: =N16+O16 -> 0 | Q16: =G16-P16 -> 1450 | R16: =IFERROR(MIN(P16/G16,1),0) -> 0 | S16: =O16*H16 -> 0 | T16: =I16*M16 -> 0 | U16: =I16*R16 -> 0 | V16: =IF(M16=0,"Not Started",IF(R16>=0.999,"Completed",IF(R16>=M16,"On Track",IF(R16>=M16*0.8,"In Progress","Delay")))) -> Not Started | X16: =INPUT!$A$27 -> PLB-20 | Y16: =INPUT!$A$136 -> 46259 | Z16: =SUMPRODUCT($I$13:$I$27,(($Y16>=$K$13:$K$27)+($Y16<$K$13:$K$27)*($Y16>=$J$13:$J$27)*(($Y16-$J$13:$J$27+1)/($K$13:$K$27-$J$13:$J$27+1)))) -> 0.25146039 | AA16: =IF(INPUT!$B$136="","",INPUT!$B$136) | AB16: from INPUT sheet section 14
A17: 5 | B17: =INPUT!$B$28 -> GI piping 40 to 80 mm exposed | F17: =INPUT!$E$28 -> RM | G17: =INPUT!$F$28 -> 620 | H17: =INPUT!$G$28 -> 860 | I17: =IFERROR(G17*H17/SUMPRODUCT($G$13:$G$27,$H$13:$H$27),0) -> 0.069528479 | J17: =INPUT!$H$28 -> 46259 | K17: =INPUT!$I$28 -> 46305 | L17: =K17-INPUT!$B$15 -> 71 | M17: =IF(INPUT!$B$15>=K17,1,IF(INPUT!$B$15<J17,0,(INPUT!$B$15-J17+1)/(K17-J17+1))) -> 0 | N17: =INPUT!$J$28 -> 0 | O17: =INPUT!$K$28 -> 0 | P17: =N17+O17 -> 0 | Q17: =G17-P17 -> 620 | R17: =IFERROR(MIN(P17/G17,1),0) -> 0 | S17: =O17*H17 -> 0 | T17: =I17*M17 -> 0 | U17: =I17*R17 -> 0 | V17: =IF(M17=0,"Not Started",IF(R17>=0.999,"Completed",IF(R17>=M17,"On Track",IF(R17>=M17*0.8,"In Progress","Delay")))) -> Not Started | X17: =INPUT!$A$28 -> PLB-20 | Y17: =INPUT!$A$137 -> 46264 | Z17: =SUMPRODUCT($I$13:$I$27,(($Y17>=$K$13:$K$27)+($Y17<$K$13:$K$27)*($Y17>=$J$13:$J$27)*(($Y17-$J$13:$J$27+1)/($K$13:$K$27-$J$13:$J$27+1)))) -> 0.29927347 | AA17: =IF(INPUT!$B$137="","",INPUT!$B$137) | AB17: from INPUT sheet section 14
A18: 6 | B18: =INPUT!$B$29 -> Overhead tank connections, valves & float | F18: =INPUT!$E$29 -> NOS | G18: =INPUT!$F$29 -> 12 | H18: =INPUT!$G$29 -> 9800 | I18: =IFERROR(G18*H18/SUMPRODUCT($G$13:$G$27,$H$13:$H$27),0) -> 0.015334863 | J18: =INPUT!$H$29 -> 46285 | K18: =INPUT!$I$29 -> 46320 | L18: =K18-INPUT!$B$15 -> 86 | M18: =IF(INPUT!$B$15>=K18,1,IF(INPUT!$B$15<J18,0,(INPUT!$B$15-J18+1)/(K18-J18+1))) -> 0 | N18: =INPUT!$J$29 -> 0 | O18: =INPUT!$K$29 -> 0 | P18: =N18+O18 -> 0 | Q18: =G18-P18 -> 12 | R18: =IFERROR(MIN(P18/G18,1),0) -> 0 | S18: =O18*H18 -> 0 | T18: =I18*M18 -> 0 | U18: =I18*R18 -> 0 | V18: =IF(M18=0,"Not Started",IF(R18>=0.999,"Completed",IF(R18>=M18,"On Track",IF(R18>=M18*0.8,"In Progress","Delay")))) -> Not Started | X18: =INPUT!$A$29 -> PLB-20
A19: 7 | B19: =INPUT!$B$30 -> SWR / PVC soil & waste pipe 110 mm | F19: =INPUT!$E$30 -> RM | G19: =INPUT!$F$30 -> 980 | H19: =INPUT!$G$30 -> 480 | I19: =IFERROR(G19*H19/SUMPRODUCT($G$13:$G$27,$H$13:$H$27),0) -> 0.061339453 | J19: =INPUT!$H$30 -> 46254 | K19: =INPUT!$I$30 -> 46305 | L19: =K19-INPUT!$B$15 -> 71 | M19: =IF(INPUT!$B$15>=K19,1,IF(INPUT!$B$15<J19,0,(INPUT!$B$15-J19+1)/(K19-J19+1))) -> 0 | N19: =INPUT!$J$30 -> 0 | O19: =INPUT!$K$30 -> 0 | P19: =N19+O19 -> 0 | Q19: =G19-P19 -> 980 | R19: =IFERROR(MIN(P19/G19,1),0) -> 0 | S19: =O19*H19 -> 0 | T19: =I19*M19 -> 0 | U19: =I19*R19 -> 0 | V19: =IF(M19=0,"Not Started",IF(R19>=0.999,"Completed",IF(R19>=M19,"On Track",IF(R19>=M19*0.8,"In Progress","Delay")))) -> Not Started | X19: =INPUT!$A$30 -> PLB-30
A20: 8 | B20: =INPUT!$B$31 -> Rainwater downtake pipe 160 mm | F20: =INPUT!$E$31 -> RM | G20: =INPUT!$F$31 -> 720 | H20: =INPUT!$G$31 -> 620 | I20: =IFERROR(G20*H20/SUMPRODUCT($G$13:$G$27,$H$13:$H$27),0) -> 0.058209889 | J20: =INPUT!$H$31 -> 46266 | K20: =INPUT!$I$31 -> 46315 | L20: =K20-INPUT!$B$15 -> 81 | M20: =IF(INPUT!$B$15>=K20,1,IF(INPUT!$B$15<J20,0,(INPUT!$B$15-J20+1)/(K20-J20+1))) -> 0 | N20: =INPUT!$J$31 -> 0 | O20: =INPUT!$K$31 -> 0 | P20: =N20+O20 -> 0 | Q20: =G20-P20 -> 720 | R20: =IFERROR(MIN(P20/G20,1),0) -> 0 | S20: =O20*H20 -> 0 | T20: =I20*M20 -> 0 | U20: =I20*R20 -> 0 | V20: =IF(M20=0,"Not Started",IF(R20>=0.999,"Completed",IF(R20>=M20,"On Track",IF(R20>=M20*0.8,"In Progress","Delay")))) -> Not Started | X20: =INPUT!$A$31 -> PLB-30
A21: 9 | B21: =INPUT!$B$32 -> UG drainage line with inspection chambers | F21: =INPUT!$E$32 -> RM | G21: =INPUT!$F$32 -> 540 | H21: =INPUT!$G$32 -> 2200 | I21: =IFERROR(G21*H21/SUMPRODUCT($G$13:$G$27,$H$13:$H$27),0) -> 0.15491342 | J21: =INPUT!$H$32 -> 46218 | K21: =INPUT!$I$32 -> 46275 | L21: =K21-INPUT!$B$15 -> 41 | M21: =IF(INPUT!$B$15>=K21,1,IF(INPUT!$B$15<J21,0,(INPUT!$B$15-J21+1)/(K21-J21+1))) -> 0.29310345 | N21: =INPUT!$J$32 -> 96 | O21: =INPUT!$K$32 -> 14 | P21: =N21+O21 -> 110 | Q21: =G21-P21 -> 430 | R21: =IFERROR(MIN(P21/G21,1),0) -> 0.2037037 | S21: =O21*H21 -> 30800 | T21: =I21*M21 -> 0.045405656 | U21: =I21*R21 -> 0.031556436 | V21: =IF(M21=0,"Not Started",IF(R21>=0.999,"Completed",IF(R21>=M21,"On Track",IF(R21>=M21*0.8,"In Progress","Delay")))) -> Delay | X21: =INPUT!$A$32 -> PLB-30
A22: 10 | B22: =INPUT!$B$33 -> Manholes, gully traps & covers | F22: =INPUT!$E$33 -> NOS | G22: =INPUT!$F$33 -> 26 | H22: =INPUT!$G$33 -> 16500 | I22: =IFERROR(G22*H22/SUMPRODUCT($G$13:$G$27,$H$13:$H$27),0) -> 0.055940956 | J22: =INPUT!$H$33 -> 46228 | K22: =INPUT!$I$33 -> 46285 | L22: =K22-INPUT!$B$15 -> 51 | M22: =IF(INPUT!$B$15>=K22,1,IF(INPUT!$B$15<J22,0,(INPUT!$B$15-J22+1)/(K22-J22+1))) -> 0.12068966 | N22: =INPUT!$J$33 -> 4 | O22: =INPUT!$K$33 -> 1 | P22: =N22+O22 -> 5 | Q22: =G22-P22 -> 21 | R22: =IFERROR(MIN(P22/G22,1),0) -> 0.19230769 | S22: =O22*H22 -> 16500 | T22: =I22*M22 -> 0.0067514946 | U22: =I22*R22 -> 0.010757876 | V22: =IF(M22=0,"Not Started",IF(R22>=0.999,"Completed",IF(R22>=M22,"On Track",IF(R22>=M22*0.8,"In Progress","Delay")))) -> On Track | X22: =INPUT!$A$33 -> PLB-30
A23: 11 | B23: =INPUT!$B$34 -> WC, wash basin & urinal with fittings | F23: =INPUT!$E$34 -> NOS | G23: =INPUT!$F$34 -> 68 | H23: =INPUT!$G$34 -> 14500 | I23: =IFERROR(G23*H23/SUMPRODUCT($G$13:$G$27,$H$13:$H$27),0) -> 0.12857292 | J23: =INPUT!$H$34 -> 46296 | K23: =INPUT!$I$34 -> 46341 | L23: =K23-INPUT!$B$15 -> 107 | M23: =IF(INPUT!$B$15>=K23,1,IF(INPUT!$B$15<J23,0,(INPUT!$B$15-J23+1)/(K23-J23+1))) -> 0 | N23: =INPUT!$J$34 -> 0 | O23: =INPUT!$K$34 -> 0 | P23: =N23+O23 -> 0 | Q23: =G23-P23 -> 68 | R23: =IFERROR(MIN(P23/G23,1),0) -> 0 | S23: =O23*H23 -> 0 | T23: =I23*M23 -> 0 | U23: =I23*R23 -> 0 | V23: =IF(M23=0,"Not Started",IF(R23>=0.999,"Completed",IF(R23>=M23,"On Track",IF(R23>=M23*0.8,"In Progress","Delay")))) -> Not Started | X23: =INPUT!$A$34 -> PLB-40
A24: 12 | B24: =INPUT!$B$35 -> CP fittings, taps & health faucets | F24: =INPUT!$E$35 -> NOS | G24: =INPUT!$F$35 -> 120 | H24: =INPUT!$G$35 -> 3200 | I24: =IFERROR(G24*H24/SUMPRODUCT($G$13:$G$27,$H$13:$H$27),0) -> 0.050073023 | J24: =INPUT!$H$35 -> 46305 | K24: =INPUT!$I$35 -> 46346 | L24: =K24-INPUT!$B$15 -> 112 | M24: =IF(INPUT!$B$15>=K24,1,IF(INPUT!$B$15<J24,0,(INPUT!$B$15-J24+1)/(K24-J24+1))) -> 0 | N24: =INPUT!$J$35 -> 0 | O24: =INPUT!$K$35 -> 0 | P24: =N24+O24 -> 0 | Q24: =G24-P24 -> 120 | R24: =IFERROR(MIN(P24/G24,1),0) -> 0 | S24: =O24*H24 -> 0 | T24: =I24*M24 -> 0 | U24: =I24*R24 -> 0 | V24: =IF(M24=0,"Not Started",IF(R24>=0.999,"Completed",IF(R24>=M24,"On Track",IF(R24>=M24*0.8,"In Progress","Delay")))) -> Not Started | X24: =INPUT!$A$35 -> PLB-40
A25: 13 | B25: =INPUT!$B$36 -> Water cooler & drinking water stations | F25: =INPUT!$E$36 -> NOS | G25: =INPUT!$F$36 -> 8 | H25: =INPUT!$G$36 -> 42000 | I25: =IFERROR(G25*H25/SUMPRODUCT($G$13:$G$27,$H$13:$H$27),0) -> 0.043813895 | J25: =INPUT!$H$36 -> 46327 | K25: =INPUT!$I$36 -> 46351 | L25: =K25-INPUT!$B$15 -> 117 | M25: =IF(INPUT!$B$15>=K25,1,IF(INPUT!$B$15<J25,0,(INPUT!$B$15-J25+1)/(K25-J25+1))) -> 0 | N25: =INPUT!$J$36 -> 0 | O25: =INPUT!$K$36 -> 0 | P25: =N25+O25 -> 0 | Q25: =G25-P25 -> 8 | R25: =IFERROR(MIN(P25/G25,1),0) -> 0 | S25: =O25*H25 -> 0 | T25: =I25*M25 -> 0 | U25: =I25*R25 -> 0 | V25: =IF(M25=0,"Not Started",IF(R25>=0.999,"Completed",IF(R25>=M25,"On Track",IF(R25>=M25*0.8,"In Progress","Delay")))) -> Not Started | X25: =INPUT!$A$36 -> PLB-40
A26: 14 | B26: =INPUT!$B$37 -> Pressure testing & flushing of lines | F26: =INPUT!$E$37 -> RM | G26: =INPUT!$F$37 -> 3200 | H26: =INPUT!$G$37 -> 95 | I26: =IFERROR(G26*H26/SUMPRODUCT($G$13:$G$27,$H$13:$H$27),0) -> 0.039641143 | J26: =INPUT!$H$37 -> 46310 | K26: =INPUT!$I$37 -> 46356 | L26: =K26-INPUT!$B$15 -> 122 | M26: =IF(INPUT!$B$15>=K26,1,IF(INPUT!$B$15<J26,0,(INPUT!$B$15-J26+1)/(K26-J26+1))) -> 0 | N26: =INPUT!$J$37 -> 0 | O26: =INPUT!$K$37 -> 0 | P26: =N26+O26 -> 0 | Q26: =G26-P26 -> 3200 | R26: =IFERROR(MIN(P26/G26,1),0) -> 0 | S26: =O26*H26 -> 0 | T26: =I26*M26 -> 0 | U26: =I26*R26 -> 0 | V26: =IF(M26=0,"Not Started",IF(R26>=0.999,"Completed",IF(R26>=M26,"On Track",IF(R26>=M26*0.8,"In Progress","Delay")))) -> Not Started | X26: =INPUT!$A$37 -> PLB-50
A27: 15 | B27: =INPUT!$B$38 -> STP tie-in, trial run & commissioning | F27: =INPUT!$E$38 -> LS | G27: =INPUT!$F$38 -> 1 | H27: =INPUT!$G$38 -> 750000 | I27: =IFERROR(G27*H27/SUMPRODUCT($G$13:$G$27,$H$13:$H$27),0) -> 0.097798873 | J27: =INPUT!$H$38 -> 46341 | K27: =INPUT!$I$38 -> 46366 | L27: =K27-INPUT!$B$15 -> 132 | M27: =IF(INPUT!$B$15>=K27,1,IF(INPUT!$B$15<J27,0,(INPUT!$B$15-J27+1)/(K27-J27+1))) -> 0 | N27: =INPUT!$J$38 -> 0 | O27: =INPUT!$K$38 -> 0 | P27: =N27+O27 -> 0 | Q27: =G27-P27 -> 1 | R27: =IFERROR(MIN(P27/G27,1),0) -> 0 | S27: =O27*H27 -> 0 | T27: =I27*M27 -> 0 | U27: =I27*R27 -> 0 | V27: =IF(M27=0,"Not Started",IF(R27>=0.999,"Completed",IF(R27>=M27,"On Track",IF(R27>=M27*0.8,"In Progress","Delay")))) -> Not Started | X27: =INPUT!$A$38 -> PLB-50
A28: TOTAL / OVERALL PACKAGE PROGRESS | F28: ="₹ "&TEXT(SUMPRODUCT($G$13:$G$27,$H$13:$H$27)/100000,"#,##0.0")&" Lakh" -> ₹ 76.7 Lakh | I28: =SUM(I13:I27) -> 1 | J28: PROGRAMME | M28: =T28 -> 0.085240637 | R28: =U28 -> 0.066745775 | S28: =SUM(S13:S27) -> 74760 | T28: =SUM(T13:T27) -> 0.085240637 | U28: =SUM(U13:U27) -> 0.066745775 | V28: =IF(U28>=T28,"ON TRACK","BEHIND") -> BEHIND
A29: 3. PROGRESS SUMMARY BY GROUP (value weighted) | K29: 4. PROGRESS S-CURVE (PLANNED vs ACTUAL)
A30: GROUP | C30: DESCRIPTION | F30: WEIGHTAGE | H30: PLANNED % | I30: ACTUAL % | J30: SPI
A31: PLB-10 | C31: Underground Water Supply & Sump | F31: =SUMIFS($I$13:$I$27,$X$13:$X$27,$A31) -> 0.1454204 | H31: =IFERROR(SUMIFS($T$13:$T$27,$X$13:$X$27,$A31)/F31,0) -> 0.22750237 | I31: =IFERROR(SUMIFS($U$13:$U$27,$X$13:$X$27,$A31)/F31,0) -> 0.16800574 | J31: =IFERROR(I31/H31,"") -> 0.73847908
A32: PLB-20 | C32: Internal Water Supply Piping | F32: =SUMIFS($I$13:$I$27,$X$13:$X$27,$A32) -> 0.16427603 | H32: =IFERROR(SUMIFS($T$13:$T$27,$X$13:$X$27,$A32)/F32,0) -> 0 | I32: =IFERROR(SUMIFS($U$13:$U$27,$X$13:$X$27,$A32)/F32,0) -> 0 | J32: =IFERROR(I32/H32,"")
A33: PLB-30 | C33: Soil, Waste, Rainwater & UG Drainage | F33: =SUMIFS($I$13:$I$27,$X$13:$X$27,$A33) -> 0.33040371 | H33: =IFERROR(SUMIFS($T$13:$T$27,$X$13:$X$27,$A33)/F33,0) -> 0.15785885 | I33: =IFERROR(SUMIFS($U$13:$U$27,$X$13:$X$27,$A33)/F33,0) -> 0.12806851 | J33: =IFERROR(I33/H33,"") -> 0.81128497
A34: PLB-40 | C34: Sanitary Fixtures & CP Fittings | F34: =SUMIFS($I$13:$I$27,$X$13:$X$27,$A34) -> 0.22245984 | H34: =IFERROR(SUMIFS($T$13:$T$27,$X$13:$X$27,$A34)/F34,0) -> 0 | I34: =IFERROR(SUMIFS($U$13:$U$27,$X$13:$X$27,$A34)/F34,0) -> 0 | J34: =IFERROR(I34/H34,"")
A35: PLB-50 | C35: Testing, STP Tie-in & Commissioning | F35: =SUMIFS($I$13:$I$27,$X$13:$X$27,$A35) -> 0.13744002 | H35: =IFERROR(SUMIFS($T$13:$T$27,$X$13:$X$27,$A35)/F35,0) -> 0 | I35: =IFERROR(SUMIFS($U$13:$U$27,$X$13:$X$27,$A35)/F35,0) -> 0 | J35: =IFERROR(I35/H35,"")
A36: TOTAL | F36: =SUM(F31:F35) -> 1 | H36: =$T$28 -> 0.085240637 | I36: =$U$28 -> 0.066745775 | J36: =IFERROR(I36/H36,"") -> 0.78302764
A37: 5. EARNED VALUE / COMMERCIAL SNAPSHOT (₹ in Lakh)
A38: BAC – Contract value of package | H38: =SUMPRODUCT($G$13:$G$27,$H$13:$H$27)/100000 -> 76.688
A39: PV – Planned Value (BAC × Planned %) | H39: =$H$38*$T$28 -> 6.536934
A40: EV – Earned Value (BAC × Actual %) | H40: =$H$38*$U$28 -> 5.1186
...

Sheet INPUT
A1: DAILY INPUT SHEET — PLUMBING, WATER SUPPLY & DRAINAGE PACKAGE
A2: TYPE ONLY IN THE YELLOW CELLS ON THIS SHEET. The DASHBOARD sheet is the printed DPR — it is all formulas and must not be typed over. Fill top to bottom, then print the DASHBOARD to PDF.
A3: 1. PROJECT HEADER (change once at the start, then only the dates each day)
A4: Project name | B4: <Client / Project Name>
A5: Project manager | B5: <PMC Project Manager>
A6: Contractor / vendor | B6: <Executing Agency / PEB Vendor>
A7: Location | B7: <Plot / GIDC / District>
A8: Prepared by | B8: Site Engineer – SPDC (PMC)
A9: Contract / PO reference | B9: <Work Order No. & Date>
A10: Contract completion date | B10: 46295
A11: Calendar / working hours | B11: 6 Days / Week – 8 hrs | F11: Shift hours drive man-days & utilization
A12: Shift hours per day | B12: 8 | F12: Used for man-days and equipment utilization
A13: Weather | B13: Partly Cloudy, 32 °C
A14: REPORT DATE | B14: 46234
A15: DATA DATE (cut-off) | B15: 46234 | F15: Every planned % is measured to this date
A16: Report number | B16: DPR/PLB-027
A17: AC – certified / paid to date (₹ Lakh) | B17: 5.4 | F17: From the RA bill / cost report
A18: Cumulative man-days upto previous day | B18: 1180
A19: Cumulative safe man-hours upto prev. day | B19: 42150
A20: Date of last LTI | B20: 46112 | F20: Days without LTI counts from here
A22: 2. QUANTITY PROGRESS (one row per BOQ / scope item — type today's quantity in the last column)
A23: GROUP | B23: DESCRIPTION OF ITEM | E23: UNIT | F23: SCOPE / BOQ QTY | G23: RATE ₹ | H23: START | I23: FINISH | J23: CUM QTY UPTO PREV. | K23: QTY TODAY
A24: PLB-10 | B24: UG HDPE water line 90 mm with fittings | E24: RM | F24: 640 | G24: 680 | H24: 46213 | I24: 46259 | J24: 180 | K24: 22
A25: PLB-10 | B25: UG sump, pump room piping & valves | E25: LS | F25: 1 | G25: 480000 | H25: 46249 | I25: 46295 | J25: 0 | K25: 0
A26: PLB-10 | B26: Water meter, valves & masonry chambers | E26: NOS | F26: 16 | G26: 12500 | H26: 46223 | I26: 46270 | J26: 3 | K26: 1
A27: PLB-20 | B27: CPVC piping 25 to 50 mm concealed | E27: RM | F27: 1450 | G27: 420 | H27: 46254 | I27: 46310 | J27: 0 | K27: 0
A28: PLB-20 | B28: GI piping 40 to 80 mm exposed | E28: RM | F28: 620 | G28: 860 | H28: 46259 | I28: 46305 | J28: 0 | K28: 0
A29: PLB-20 | B29: Overhead tank connections, valves & float | E29: NOS | F29: 12 | G29: 9800 | H29: 46285 | I29: 46320 | J29: 0 | K29: 0
A30: PLB-30 | B30: SWR / PVC soil & waste pipe 110 mm | E30: RM | F30: 980 | G30: 480 | H30: 46254 | I30: 46305 | J30: 0 | K30: 0
A31: PLB-30 | B31: Rainwater downtake pipe 160 mm | E31: RM | F31: 720 | G31: 620 | H31: 46266 | I31: 46315 | J31: 0 | K31: 0
A32: PLB-30 | B32: UG drainage line with inspection chambers | E32: RM | F32: 540 | G32: 2200 | H32: 46218 | I32: 46275 | J32: 96 | K32: 14
A33: PLB-30 | B33: Manholes, gully traps & covers | E33: NOS | F33: 26 | G33: 16500 | H33: 46228 | I33: 46285 | J33: 4 | K33: 1
A34: PLB-40 | B34: WC, wash basin & urinal with fittings | E34: NOS | F34: 68 | G34: 14500 | H34: 46296 | I34: 46341 | J34: 0 | K34: 0
A35: PLB-40 | B35: CP fittings, taps & health faucets | E35: NOS | F35: 120 | G35: 3200 | H35: 46305 | I35: 46346 | J35: 0 | K35: 0
... A38: PLB-50 | B38: STP tie-in, trial run & commissioning | E38: LS | F38: 1 | G38: 750000 | H38: 46341 | I38: 46366 | J38: 0 | K38: 0
A40: 3. MANPOWER DEPLOYED TODAY
A41: TRADE / CATEGORY | D41: PLANNED NOS | E41: ACTUAL NOS | F41: HOURS WORKED
A42: Plumber | D42: 10 | E42: 8 | F42: 8.5
A43: Pipe Fitter | D43: 6 | E43: 5 | F43: 8.5
A44: Mason – chambers & manholes | D44: 6 | E44: 6 | F44: 8
...

Sheet S-Curve Calc
A1: S-CURVE CALCULATION — ACTUAL % ON EACH REPORTING DATE (PLUMBING)
A2: Enter the CUMULATIVE quantity of each item as it stood on each reporting date (from that day's measurement book / issued DPR). The bottom row converts them into the weighted actual % for that date and feeds INPUT section 14 and the S-curve. Once a column is filled it never changes again.
A4: SL | B4: DESCRIPTION OF ITEM | C4: UNIT | D4: SCOPE QTY | E4: WEIGHT-AGE % | F4: 46204 | G4: 46209 | H4: 46214 | I4: 46219 | J4: 46224 | K4: 46229 | L4: 46234 | M4: 46239 | N4: 46244 | O4: 46249 | P4: 46254 | Q4: 46259 | R4: 46264
A5: 1 | B5: =INPUT!$B$24 -> UG HDPE water line 90 mm with fittings | C5: =INPUT!$E$24 -> RM | D5: =INPUT!$F$24 -> 640 | E5: =IFERROR(INPUT!$F$24*INPUT!$G$24/SUMPRODUCT(INPUT!$F$24:$F$38,INPUT!$G$24:$G$38),0) -> 0.056749426 | F5: 0 | G5: 36.32 | H5: 90.79 | I5: 157.37 | J5: 202 | K5: 202
A6: 2 | B6: =INPUT!$B$25 -> UG sump, pump room piping & valves | C6: =INPUT!$E$25 -> LS | D6: =INPUT!$F$25 -> 1 | E6: =IFERROR(INPUT!$F$25*INPUT!$G$25/SUMPRODUCT(INPUT!$F$24:$F$38,INPUT!$G$24:$G$38),0) -> 0.062591279 | F6: 0 | G6: 0 | H6: 0 | I6: 0 | J6: 0 | K6: 0
A7: 3 | B7: =INPUT!$B$26 -> Water meter, valves & masonry chambers | C7: =INPUT!$E$26 -> NOS | D7: =INPUT!$F$26 -> 16 | E7: =IFERROR(INPUT!$F$26*INPUT!$G$26/SUMPRODUCT(INPUT!$F$24:$F$38,INPUT!$G$24:$G$38),0) -> 0.0260797 | F7: 0 | G7: 0.72 | H7: 1.8 | I7: 3.12 | J7: 4 | K7: 4
A8: 4 | B8: =INPUT!$B$27 -> CPVC piping 25 to 50 mm concealed | C8: =INPUT!$E$27 -> RM | D8: =INPUT!$F$27 -> 1450 | E8: =IFERROR(INPUT!$F$27*INPUT!$G$27/SUMPRODUCT(INPUT!$F$24:$F$38,INPUT!$G$24:$G$38),0) -> 0.079412685 | F8: 0 | G8: 0 | H8: 0 | I8: 0 | J8: 0 | K8: 0
A9: 5 | B9: =INPUT!$B$28 -> GI piping 40 to 80 mm exposed | C9: =INPUT!$E$28 -> RM | D9: =INPUT!$F$28 -> 620 | E9: =IFERROR(INPUT!$F$28*INPUT!$G$28/SUMPRODUCT(INPUT!$F$24:$F$38,INPUT!$G$24:$G$38),0) -> 0.069528479 | F9: 0 | G9: 0 | H9: 0 | I9: 0 | J9: 0 | K9: 0
A10: 6 | B10: =INPUT!$B$29 -> Overhead tank connections, valves & float | C10: =INPUT!$E$29 -> NOS | D10: =INPUT!$F$29 -> 12 | E10: =IFERROR(INPUT!$F$29*INPUT!$G$29/SUMPRODUCT(INPUT!$F$24:$F$38,INPUT!$G$24:$G$38),0) -> 0.015334863 | F10: 0 | G10: 0 | H10: 0 | I10: 0 | J10: 0 | K10: 0
A11: 7 | B11: =INPUT!$B$30 -> SWR / PVC soil & waste pipe 110 mm | C11: =INPUT!$E$30 -> RM | D11: =INPUT!$F$30 -> 980 | E11: =IFERROR(INPUT!$F$30*INPUT!$G$30/SUMPRODUCT(INPUT!$F$24:$F$38,INPUT!$G$24:$G$38),0) -> 0.061339453 | F11: 0 | G11: 0 | H11: 0 | I11: 0 | J11: 0 | K11: 0
A12: 8 | B12: =INPUT!$B$31 -> Rainwater downtake pipe 160 mm | C12: =INPUT!$E$31 -> RM | D12: =INPUT!$F$31 -> 720 | E12: =IFERROR(INPUT!$F$31*INPUT!$G$31/SUMPRODUCT(INPUT!$F$24:$F$38,INPUT!$G$24:$G$38),0) -> 0.058209889 | F12: 0 | G12: 0 | H12: 0 | I12: 0 | J12: 0 | K12: 0
A13: 9 | B13: =INPUT!$B$32 -> UG drainage line with inspection chambers | C13: =INPUT!$E$32 -> RM | D13: =INPUT!$F$32 -> 540 | E13: =IFERROR(INPUT!$F$32*INPUT!$G$32/SUMPRODUCT(INPUT!$F$24:$F$38,INPUT!$G$24:$G$38),0) -> 0.15491342 | F13: 0 | G13: 19.78 | H13: 49.44 | I13: 85.7 | J13: 110 | K13: 110
A14: 10 | B14: =INPUT!$B$33 -> Manholes, gully traps & covers | C14: =INPUT!$E$33 -> NOS | D14: =INPUT!$F$33 -> 26 | E14: =IFERROR(INPUT!$F$33*INPUT!$G$33/SUMPRODUCT(INPUT!$F$24:$F$38,INPUT!$G$24:$G$38),0) -> 0.055940956 | F14: 0 | G14: 0.9 | H14: 2.25 | I14: 3.9 | J14: 5 | K14: 5
A15: 11 | B15: =INPUT!$B$34 -> WC, wash basin & urinal with fittings | C15: =INPUT!$E$34 -> NOS | D15: =INPUT!$F$34 -> 68 | E15: =IFERROR(INPUT!$F$34*INPUT!$G$34/SUMPRODUCT(INPUT!$F$24:$F$38,INPUT!$G$24:$G$38),0) -> 0.12857292 | F15: 0 | G15: 0 | H15: 0 | I15: 0 | J15: 0 | K15: 0
A16: 12 | B16: =INPUT!$B$35 -> CP fittings, taps & health faucets | C16: =INPUT!$E$35 -> NOS | D16: =INPUT!$F$35 -> 120 | E16: =IFERROR(INPUT!$F$35*INPUT!$G$35/SUMPRODUCT(INPUT!$F$24:$F$38,INPUT!$G$24:$G$38),0) -> 0.050073023 | F16: 0 | G16: 0 | H16: 0 | I16: 0 | J16: 0 | K16: 0
A17: 13 | B17: =INPUT!$B$36 -> Water cooler & drinking water stations | C17: =INPUT!$E$36 -> NOS | D17: =INPUT!$F$36 -> 8 | E17: =IFERROR(INPUT!$F$36*INPUT!$G$36/SUMPRODUCT(INPUT!$F$24:$F$38,INPUT!$G$24:$G$38),0) -> 0.043813895 | F17: 0 | G17: 0 | H17: 0 | I17: 0 | J17: 0 | K17: 0
A18: 14 | B18: =INPUT!$B$37 -> Pressure testing & flushing of lines | C18: =INPUT!$E$37 -> RM | D18: =INPUT!$F$37 -> 3200 | E18: =IFERROR(INPUT!$F$37*INPUT!$G$37/SUMPRODUCT(INPUT!$F$24:$F$38,INPUT!$G$24:$G$38),0) -> 0.039641143 | F18: 0 | G18: 0 | H18: 0 | I18: 0 | J18: 0 | K18: 0
A19: 15 | B19: =INPUT!$B$38 -> STP tie-in, trial run & commissioning | C19: =INPUT!$E$38 -> LS | D19: =INPUT!$F$38 -> 1 | E19: =IFERROR(INPUT!$F$38*INPUT!$G$38/SUMPRODUCT(INPUT!$F$24:$F$38,INPUT!$G$24:$G$38),0) -> 0.097798873 | F19: 0 | G19: 0 | H19: 0 | I19: 0 | J19: 0 | K19: 0
A20: WEIGHTED ACTUAL % ON THAT DATE | E20: =SUM(E5:E19) -> 1 | F20: =IFERROR(SUMPRODUCT($E$5:$E$19,F5:F19,1/$D$5:$D$19),0) -> 0 | G20: =IFERROR(SUMPRODUCT($E$5:$E$19,G5:G19,1/$D$5:$D$19),0) -> 0.012004955 | H20: =IFERROR(SUMPRODUCT($E$5:$E$19,H5:H19,1/$D$5:$D$19),0) -> 0.030008632 | I20: =IFERROR(SUMPRODUCT($E$5:$E$19,I5:I19,1/$D$5:$D$19),0) -> 0.052016169 | J20: =IFERROR(SUMPRODUCT($E$5:$E$19,J5:J19,1/$D$5:$D$19),0) -> 0.066745775 | K20: =IFERROR(SUMPRODUCT($E$5:$E$19,K5:K19,1/$D$5:$D$19),0) -> 0.066745775 | L20: =IFERROR(SUMPRODUCT($E$5:$E$19,L5:L19,1/$D$5:$D$19),0) -> 0 | M20: =IFERROR(SUMPRODUCT($E$5:$E$19,M5:M19,1/$D$5:$D$19),0) -> 0 | ... R20: =IFERROR(SUMPRODUCT($E$5:$E$19,R5:R19,1/$D$5:$D$19),0) -> 0
A22: FORMULA: Actual % on a date = Σ [ item weightage × ( cumulative qty on that date ÷ scope qty ) ] — the same weighted calculation the DASHBOARD does for today, only using the quantities as they stood on that earlier date.
A23: SHORTCUT: if the DPR was already issued on that date, simply type the Actual % printed on it over the green formula in INPUT section 14 — both routes give the same figure. NOTE: weightage is taken from the CURRENT rates, so if a rate is revised later, re-issued history will shift slightly; the figures on the DPRs already signed remain the record.

Sheet Guide
A1: HOW THIS FILE WORKS — PLUMBING DPR
B3: Two sheets only | C3: INPUT — you type here, top to bottom, yellow cells only. DASHBOARD — the printed DPR, 100% formulas, never typed. Guide — this page.
B4: Daily routine | C4: Open INPUT → change Report Date and Data Date → enter today's quantities, manpower, equipment, material, quality, HSE, delays, pending approvals, issues, highlights, next-day plan → open DASHBOARD → print to PDF.
B5: Adding / removing an item | C5: Insert or delete a row inside the quantity block on INPUT and the same row position on DASHBOARD; every formula uses ranges, so totals follow.
B6: Weightage % | C6: Scope Qty × Rate ÷ Σ(Scope Qty × Rate). Value weightage — always totals 100%.
B7: Planned % | C7: IF(Data Date ≥ Finish, 100%, IF(Data Date < Start, 0%, (Data Date − Start + 1) ÷ (Finish − Start + 1))) — the programme prorated to the cut-off date.
B8: Days +/− | C8: Finish − Data Date. Negative and red means the item is already past its programmed finish.
B9: Cum Qty To Date / Balance | C9: Cum upto previous + Qty today · Scope Qty − Cum to date.
B10: % Complete | C10: MIN(Cum Qty To Date ÷ Scope Qty, 1), shown with an in-cell data bar.
B11: Earned ₹ today | C11: Qty today × Rate — the value of work done in the day, totalled in the KPI strip.
B12: Package Planned / Actual % | C12: Σ(Weightage × Planned %) and Σ(Weightage × % Complete). These two totals drive the KPI strip, group summary, earned value block and S-curve.
B13: Status | C13: Not Started / Completed / On Track (actual ≥ planned) / In Progress / Delay — colour coded.
B14: Group summary | C14: SUMIFS of the weighted columns by group code ÷ that group's weightage.
... B22: Roll over to the next day | C22: Save a copy with the new date. On INPUT: move Cum Qty To Date into 'Cum qty upto prev.', move material Balance into Opening, clear Qty Today, update the cumulative man-days and man-hours.
