Workbook

Sheet DASHBOARD
A1: SITE DOCUMENT AUDIT — SCORE
A2: Calculates from FOLDER_SAMPLE and SITE_WALK. Nothing to maintain on this tab.
A3: Project: ______________ Audit ref: __________ Date: __________ Auditor: ______________
A5: FOLDERS | C5: WALK CHECKS | E5: SCORED | G5: NOT MET | I5: OVERALL SCORE | K5: CRITICAL FINDINGS
A6: =66 | C6: =44 | E6: =((COUNTIF(FOLDER_SAMPLE!$K$6:$K$81,"2")+COUNTIF(FOLDER_SAMPLE!$K$6:$K$81,"1")+COUNTIF(FOLDER_SAMPLE!$K$6:$K$81,"0"))+(COUNTIF(SITE_WALK!$E$6:$E$66,"2")+COUNTIF(SITE_WALK!$E$6:$E$66,"1")+COUNTIF(SITE_WALK!$E$6:$E$66,"0"))) | G6: =COUNTIF(FOLDER_SAMPLE!$K$6:$K$81,"0")+COUNTIF(SITE_WALK!$E$6:$E$66,"0") | I6: =IFERROR(((COUNTIF(FOLDER_SAMPLE!$K$6:$K$81,"2")*2+COUNTIF(FOLDER_SAMPLE!$K$6:$K$81,"1"))+(COUNTIF(SITE_WALK!$E$6:$E$66,"2")*2+COUNTIF(SITE_WALK!$E$6:$E$66,"1")))/(((COUNTIF(FOLDER_SAMPLE!$K$6:$K$81,"2")+COUNTIF(FOLDER_SAMPLE!$K$6:$K$81,"1")+COUNTIF(FOLDER_SAMPLE!$K$6:$K$81,"0"))+(COUNTIF(SITE_WALK!$E$6:$E$66,"2")+COUNTIF(SITE_WALK!$E$6:$E$66,"1")+COUNTIF(SITE_WALK!$E$6:$E$66,"0")))*2),0) | K6: =COUNTIF(FINDINGS!$H$7:$H$105,"Critical")
A8: FOLDER SCORE | C8: SITE WALK SCORE | E8: FINDINGS RAISED | G8: FINDINGS OPEN | I8: VERDICT
A9: =IFERROR((COUNTIF(FOLDER_SAMPLE!$K$6:$K$81,"2")*2+COUNTIF(FOLDER_SAMPLE!$K$6:$K$81,"1"))/((COUNTIF(FOLDER_SAMPLE!$K$6:$K$81,"2")+COUNTIF(FOLDER_SAMPLE!$K$6:$K$81,"1")+COUNTIF(FOLDER_SAMPLE!$K$6:$K$81,"0"))*2),0) | C9: =IFERROR((COUNTIF(SITE_WALK!$E$6:$E$66,"2")*2+COUNTIF(SITE_WALK!$E$6:$E$66,"1"))/((COUNTIF(SITE_WALK!$E$6:$E$66,"2")+COUNTIF(SITE_WALK!$E$6:$E$66,"1")+COUNTIF(SITE_WALK!$E$6:$E$66,"0"))*2),0) | E9: =COUNTA(FINDINGS!$B$7:$B$105) | G9: =COUNTIF(FINDINGS!$R$7:$R$105,"Open")+COUNTIF(FINDINGS!$R$7:$R$105,"Under Rectification") | I9: =IF(COUNTIF(FINDINGS!$H$7:$H$105,"Critical")>0,"FAIL",IF(IFERROR(((COUNTIF(FOLDER_SAMPLE!$K$6:$K$81,"2")*2+COUNTIF(FOLDER_SAMPLE!$K$6:$K$81,"1"))+(COUNTIF(SITE_WALK!$E$6:$E$66,"2")*2+COUNTIF(SITE_WALK!$E$6:$E$66,"1")))/(((COUNTIF(FOLDER_SAMPLE!$K$6:$K$81,"2")+COUNTIF(FOLDER_SAMPLE!$K$6:$K$81,"1")+COUNTIF(FOLDER_SAMPLE!$K$6:$K$81,"0"))+(COUNTIF(SITE_WALK!$E$6:$E$66,"2")+COUNTIF(SITE_WALK!$E$6:$E$66,"1")+COUNTIF(SITE_WALK!$E$6:$E$66,"0")))*2),0)>=0.9,"PASS",IF(IFERROR(((COUNTIF(FOLDER_SAMPLE!$K$6:$K$81,"2")*2+COUNTIF(FOLDER_SAMPLE!$K$6:$K$81,"1"))+(COUNTIF(SITE_WALK!$E$6:$E$66,"2")*2+COUNTIF(SITE_WALK!$E$6:$E$66,"1")))/(((COUNTIF(FOLDER_SAMPLE!$K$6:$K$81,"2")+COUNTIF(FOLDER_SAMPLE!$K$6:$K$81,"1")+COUNTIF(FOLDER_SAMPLE!$K$6:$K$81,"0"))+(COUNTIF(SITE_WALK!$E$6:$E$66,"2")+COUNTIF(SITE_WALK!$E$6:$E$66,"1")+COUNTIF(SITE_WALK!$E$6:$E$66,"0")))*2),0)>=0.75,"PASS WITH ACTIONS","FAIL")))
A12: SITE WALK — SCORE BY SECTION
A13: Section | B13: Checks | C13: Met | D13: Not met | E13: Score
A14: 1. SITE OFFICE — DRAWING CONTROL | B14: 5 | C14: =COUNTIF(SITE_WALK!$E$7:$E$11,2) | D14: =COUNTIF(SITE_WALK!$E$7:$E$11,0) | E14: =IFERROR((COUNTIF(SITE_WALK!$E$7:$E$11,2)*2+COUNTIF(SITE_WALK!$E$7:$E$11,1))/((COUNTIF(SITE_WALK!$E$7:$E$11,2)+COUNTIF(SITE_WALK!$E$7:$E$11,1)+COUNTIF(SITE_WALK!$E$7:$E$11,0))*2),0)
A15: 2. WORKFACE — DRAWINGS AND METHOD | B15: 5 | C15: =COUNTIF(SITE_WALK!$E$13:$E$17,2) | D15: =COUNTIF(SITE_WALK!$E$13:$E$17,0) | E15: =IFERROR((COUNTIF(SITE_WALK!$E$13:$E$17,2)*2+COUNTIF(SITE_WALK!$E$13:$E$17,1))/((COUNTIF(SITE_WALK!$E$13:$E$17,2)+COUNTIF(SITE_WALK!$E$13:$E$17,1)+COUNTIF(SITE_WALK!$E$13:$E$17,0))*2),0)
A16: 3. WORKFACE — PERMITS AND SAFETY | B16: 6 | C16: =COUNTIF(SITE_WALK!$E$19:$E$24,2) | D16: =COUNTIF(SITE_WALK!$E$19:$E$24,0) | E16: =IFERROR((COUNTIF(SITE_WALK!$E$19:$E$24,2)*2+COUNTIF(SITE_WALK!$E$19:$E$24,1))/((COUNTIF(SITE_WALK!$E$19:$E$24,2)+COUNTIF(SITE_WALK!$E$19:$E$24,1)+COUNTIF(SITE_WALK!$E$19:$E$24,0))*2),0)
A17: 4. QUALITY AT THE WORKFACE | B17: 6 | C17: =COUNTIF(SITE_WALK!$E$26:$E$31,2) | D17: =COUNTIF(SITE_WALK!$E$26:$E$31,0) | E17: =IFERROR((COUNTIF(SITE_WALK!$E$26:$E$31,2)*2+COUNTIF(SITE_WALK!$E$26:$E$31,1))/((COUNTIF(SITE_WALK!$E$26:$E$31,2)+COUNTIF(SITE_WALK!$E$26:$E$31,1)+COUNTIF(SITE_WALK!$E$26:$E$31,0))*2),0)
A18: 5. INDUSTRIAL WORKFACE | B18: 6 | C18: =COUNTIF(SITE_WALK!$E$33:$E$38,2) | D18: =COUNTIF(SITE_WALK!$E$33:$E$38,0) | E18: =IFERROR((COUNTIF(SITE_WALK!$E$33:$E$38,2)*2+COUNTIF(SITE_WALK!$E$33:$E$38,1))/((COUNTIF(SITE_WALK!$E$33:$E$38,2)+COUNTIF(SITE_WALK!$E$33:$E$38,1)+COUNTIF(SITE_WALK!$E$33:$E$38,0))*2),0)
A19: 6. STORES AND MATERIAL | B19: 6 | C19: =COUNTIF(SITE_WALK!$E$40:$E$45,2) | D19: =COUNTIF(SITE_WALK!$E$40:$E$45,0) | E19: =IFERROR((COUNTIF(SITE_WALK!$E$40:$E$45,2)*2+COUNTIF(SITE_WALK!$E$40:$E$45,1))/((COUNTIF(SITE_WALK!$E$40:$E$45,2)+COUNTIF(SITE_WALK!$E$40:$E$45,1)+COUNTIF(SITE_WALK!$E$40:$E$45,0))*2),0)
A20: 7. HSE AND WELFARE | B20: 5 | C20: =COUNTIF(SITE_WALK!$E$47:$E$51,2) | D20: =COUNTIF(SITE_WALK!$E$47:$E$51,0) | E20: =IFERROR((COUNTIF(SITE_WALK!$E$47:$E$51,2)*2+COUNTIF(SITE_WALK!$E$47:$E$51,1))/((COUNTIF(SITE_WALK!$E$47:$E$51,2)+COUNTIF(SITE_WALK!$E$47:$E$51,1)+COUNTIF(SITE_WALK!$E$47:$E$51,0))*2),0)
A21: 8. DOCUMENT CONTROL PHYSICAL | B21: 5 | C21: =COUNTIF(SITE_WALK!$E$53:$E$57,2) | D21: =COUNTIF(SITE_WALK!$E$53:$E$57,0) | E21: =IFERROR((COUNTIF(SITE_WALK!$E$53:$E$57,2)*2+COUNTIF(SITE_WALK!$E$53:$E$57,1))/((COUNTIF(SITE_WALK!$E$53:$E$57,2)+COUNTIF(SITE_WALK!$E$53:$E$57,1)+COUNTIF(SITE_WALK!$E$53:$E$57,0))*2),0)
A23: VERDICT RULE
A24: PASS | B24: 90% or above, and no Critical finding raised
A25: PASS WITH ACTIONS | B25: 75% to 89%, and no Critical finding raised
A26: FAIL | B26: Below 75%, or any Critical finding raised
A29: A superseded print in use, a pour without written permission, or a permit issued without workface verification is a Critical finding on its own. One of those fails the audit.

Sheet PLAN
A1: SITE DOCUMENT AUDIT — PLAN AND METHOD
A2: SHARANAM PROJECT DEVELOPMENT CONSULTANTS & CO. | One full day on a live industrial site
A4: Audit ref.
A5: Project
A6: Date
A7: Auditor
A8: Independent of this project
A9: Document Controller
A10: Project Manager
A12: BEFORE YOU GO — the desk review
A13: When | B13: Do this | C13: Why it matters | D13: Done | E13: Notes
A14: 7 days before | B14: Notify the audit WINDOW, not the exact day | C14: An announced date produces a tidied site office for one day, not a true picture
A15: 2 days before | B15: Run the KPI refresh yourself on the master workbook | C15: You see the real numbers, not the ones prepared for you
A16: 2 days before | B16: Read the last six weekly reports and the last MPR | C16: Most findings are visible in the data before you reach site
A17: 2 days before | B17: Filter 03_SUBJECT_DATA by RAG = RED and by overdue | C17: This is your priority sampling list — go where the system is already failing
A18: 2 days before | B18: Check the refresh timestamps for the last six weeks | C18: Gaps tell you the weekly routine is not being run
A19: 1 day before | B19: Note which registers are above 80% capacity | C19: A register about to overflow will stop counting silently
A20: 1 day before | B20: Print the SITE_WALK and FOLDER_SAMPLE tabs | C20: Do not audit from a laptop while walking the site
A23: WHAT TO TAKE
A24: • | B24: Printed SITE_WALK and FOLDER_SAMPLE sheets
A25: • | B25: The RED and overdue list from the desk review
A26: • | B26: Camera or phone — every finding needs a photograph
A27: • | B27: Safety boots, helmet, hi-vis, glasses. You will be at the workface, not in the office
A28: • | B28: A copy of the current drawing register, so you can check boards against it independently
A31: THE DAY — timetable
A32: Time | B32: Activity | C32: What you are actually testing | D32: Sheet | E32: Done
A33: 08:30 | B33: Opening meeting with PM and Document Controller | C33: State scope, criteria and finish time. Ask for nothing in advance — you have already pulled the data | D33: PLAN
A34: 08:45 | B34: Document Controller interview | C34: How the system runs in practice, and what slips under pressure. The answers direct your sampling | D34: DC_INTERVIEW
A35: 09:30 | B35: Site office inspection — drawing boards and registers | C35: Superseded prints, uncontrolled copies, registers maintained daily or in bursts | D35: SITE_WALK 1, 8
A36: 10:15 | B36: Workface walk — drawings, method, permits | C36: Current revisions at the workface, live permits verified, method briefed | D36: SITE_WALK 2, 3
A37: 11:15 | B37: Workface walk — quality and industrial controls | C37: Pour cards signed before pour, weld IDs against the log, NDT markings, permits to load | D37: SITE_WALK 4, 5
A38: 12:15 | B38: Stores and material | C38: Approved brands, GRNs, test certificates, segregation of rejected material | D38: SITE_WALK 6
A39: 12:45 | B39: HSE and welfare walk | C39: Assembly points, first aid, welfare actually functioning, statutory display | D39: SITE_WALK 7
A40: 13:15 | B40: Break
A41: 14:00 | B41: Folder sampling — the RED and overdue list first | C41: Go where the data already says the system is failing | D41: FOLDER_SAMPLE
A42: 15:00 | B42: Folder sampling — the rest, by area | C42: Work down the sheet. Choose the sample yourself, never let it be selected for you | D42: FOLDER_SAMPLE
A43: 16:30 | B43: Draft findings and agree corrective actions | C43: Agree owner and date with the project before you leave. Findings agreed later are resisted | D43: FINDINGS
A44: 17:15 | B44: Closing meeting — verbal score and critical findings | C44: No surprises in the written report | D44: DASHBOARD
A47: AFTER THE AUDIT
A48: When | B48: Do this | C48: Why | D48: Done | E48: Notes
...

Sheet DC_INTERVIEW
A1: DOCUMENT CONTROLLER INTERVIEW
A2: Ask these before sampling. The answers tell you where to look. Ask for evidence on every answer — 'we always do that' is not evidence. Record what they actually said.
A3: Interviewee: ______________ Role: ______________ Date: __________ Interviewer: ____________
A5: # | B5: Question | C5: Answer given | D5: Evidence shown | E5: Follow up
A6: Set-up and authority
A7: 1 | B7: Who nominated you as Document Controller, and can you show me that in writing?
A8: 2 | B8: When was the numbering protocol issued to the contractors, and can you show me the transmittal?
A9: 3 | B9: Who else can edit the registers?
A10: 4 | B10: What do you do when a document arrives with a non-compliant number?
A12: Daily working
A13: 5 | B13: Walk me through what happens between a drawing arriving and it reaching the workface.
A14: 6 | B14: How long does registration usually take? Show me the last five entries and their receipt dates.
A15: 7 | B15: When did you last return a submission for a bad number?
A16: 8 | B16: How do you know a reviewer has not overrun the SLA?
A18: Revision control
A19: 9 | B19: Show me the last revision that superseded a drawing. Where is the old one now?
A20: 10 | B20: How do you get prints back from the workface, and what happens if one is missing?
A21: 11 | B21: When did you last audit the drawing boards?
A23: Under pressure
A24: 12 | B24: In the busiest week of this project, what slipped?
A25: 13 | B25: Has anyone ever asked you to backdate or amend a record? What did you do?
A26: 14 | B26: Has a pour ever gone ahead without written permission? What happened?
A28: KPI and reporting
A29: 15 | B29: Show me the last KPI refresh timestamp.
A30: 16 | B30: Which subjects were red last month, and what was done about them?
A31: 17 | B31: Which register is closest to its capacity?
A33: Support and resource
A34: 18 | B34: Do you have enough time to do this properly? If not, what gets dropped first?
A35: 19 | B35: What would you change about the system if you could?
A36: 20 | B36: What do people most often get wrong when filing?

Sheet SITE_WALK
A1: SITE WALK INSPECTION SHEET
A2: Physical inspection. Roughly half the critical findings on any document audit are found here, not in a folder. Do this before you sit down with the registers.
A3: Project: ______________ Date: __________ Areas walked: ______________________ Accompanied by: ____________
A5: # | B5: What to look at | C5: Location checked | D5: Observed | E5: Score | F5: Photo ref. | G5: Finding ref.
A6: 1. SITE OFFICE — DRAWING CONTROL
A7: 1 | B7: Every drawing on the board carries an A-code suitability
A8: 2 | B8: No superseded revision anywhere in the site office
A9: 3 | B9: Drawing register on display matches what is on the board
A10: 4 | B10: Superseded prints held for withdrawal are stamped and segregated
A11: 5 | B11: No uncontrolled photocopies or marked-up prints in use
A13: 2. WORKFACE — DRAWINGS AND METHOD
A14: 6 | B14: Prints held by foremen are current revision
A15: 7 | B15: Approved method statement available at the activity
A16: 8 | B16: Workforce can describe the method they were briefed on
A17: 9 | B17: Approved mock-up or benchmark accessible for the finishing trade
A18: 10 | B18: No work proceeding on a drawing marked for review or information
A20: 3. WORKFACE — PERMITS AND SAFETY
A21: 11 | B21: Live permits displayed at the activity, not held in the office
A22: 12 | B22: Permit precautions actually in place as described on the permit
A23: 13 | B23: Permit within its stated validity period and location
A24: 14 | B24: Gas test and isolation records attached where applicable
A25: 15 | B25: Today's toolbox talk topic matches today's actual work
A26: 16 | B26: Everyone at the workface has a valid induction and gate pass
A28: 4. QUALITY AT THE WORKFACE
A29: 17 | B29: Pour card signed before the pour, with permission time recorded
A30: 18 | B30: Cover blocks, spacers and reinforcement match the checklist entry
A31: 19 | B31: Concealed work photographed before covering
A32: 20 | B32: Test cubes marked and stored correctly
A33: 21 | B33: Open NCR areas are physically quarantined or marked
A34: 22 | B34: Calibration stickers current on instruments in use
A36: 5. INDUSTRIAL WORKFACE
A37: 23 | B37: Welder ID on the weld matches the weld log and a current WPQ
A38: 24 | B38: NDT markings present at the specified frequency
A39: 25 | B39: Hydrotested lines tagged and reinstatement recorded
A40: 26 | B40: Equipment alignment records available at the machine
A41: 27 | B41: Temporary works carry a valid permit to load
A42: 28 | B42: Coating DFT gauge readings available for the area inspected
A44: 6. STORES AND MATERIAL
A45: 29 | B45: Material received matches the approved submittal brand and grade
A46: 30 | B46: GRN raised for everything on the rack
...

Sheet FOLDER_SAMPLE
A1: FOLDER-BY-FOLDER SAMPLING SHEET
A2: 55 folders held at site or mirrored. Work down the list with the Document Controller. Score 2 fully met, 1 partly, 0 not met, N/A not applicable.
A3: Project: ______________ Audit ref: __________ Date: __________ Auditor: ______________
A5: # | B5: Area | C5: Folder | D5: Cust. | E5: Subject | F5: Sample to take | G5: What must be true | H5: Records in LOG | I5: Sampled | J5: Defects found | K5: Score | L5: Finding ref.
A6: 01_CONTEXT_AND_GOVERNANCE
A7: 1 | B7: 01 | C7: 01.02_Stakeholders_and_Communication | D7: BOTH | E7: Stakeholder Register and Communication Plan | F7: Stakeholder register | G7: Statutory and neighbouring stakeholders identified · each has a named owner and frequency · none overdue for engagement
A8: 02_PLANNING
A9: 2 | B9: 02 | C9: 02.02_Project_Programme_Schedule_Control | D9: BOTH | E9: Project Programme and Schedule Control | F9: Current programme | G9: Logic-linked with no open ends · resource assumptions verified · baseline frozen with recorded approval · re-baselines justified
A10: 3 | B10: 02 | C10: 02.03_Milestone_Register_Payment_Linkage | D10: BOTH | E10: Milestone Register and Payment Linkage | F10: Milestone register | G10: Each milestone defined by verifiable criteria · payment certified only on demonstrated achievement · LD position assessed on every miss
A11: 4 | B11: 02 | C11: 02.04_LookAhead_Planning_Constraint_Management | D11: BOTH | E11: Look-Ahead Planning and Constraint Management | F11: Last 4 look-aheads | G11: Submitted weekly and derived from the approved programme · every constraint has a named owner and a date · PPC measured and trended
A12: 03_SUPPORT_AND_RESOURCES
A13: 5 | B13: 03 | C13: 03.01_Competence_and_Training | D13: SITE | E13: Induction, Training and Competency | F13: 10 names from today's gate register | G13: Induction recorded before first entry · competence certificates current for high-risk tasks · validity tracked with refresher before expiry
A14: 6 | B14: 03 | C14: 03.02_Resources_and_Productivity | D14: SITE | E14: Resource Deployment and Productivity | F14: Last 4 weeks of returns | G14: Deployment verified by physical count · compared against the histogram weekly · shortfall notified in writing when it occurred
A15: 7 | B15: 03 | C15: 03.06_Correspondence_Control | D15: BOTH | E15: Correspondence Control | F15: 15 inward letters | G15: Registered day of receipt · contractual ones flagged with a reply deadline · none overdue · reply reference recorded
A16: 8 | B16: 03 | C16: 03.07_Transmittal_Control | D16: BOTH | E16: Transmittal Control | F16: 10 transmittals out | G16: Numbered sequentially without gaps · purpose of issue stated · acknowledgement obtained or chased within 2 days · supersession recorded
A17: 9 | B17: 03 | C17: 03.08_Meetings_Minutes_Action_Tracking | D17: BOTH | E17: Meetings, Minutes and Action Tracking | F17: 5 MOMs | G17: Issued within 2 working days · actions numbered · single named owner each · open actions carried forward
A18: 10 | B18: 03 | C18: 03.09_Monitoring_and_Measuring_Equipment | D18: SITE | E18: Instrument Calibration Control | F18: All instruments in use | G18: Every acceptance instrument registered · calibration valid at the date of use · out-of-calibration triggers review of past measurements
A19: 04_DESIGN_AND_INFORMATION_MANAGEMENT
A20: 11 | B20: 04 | C20: 04.02_Drawings_and_Specifications | D20: BOTH | E20: Drawing Control and Issue | F20: 15 drawings from the live GFC folder | G20: Suitability is an A-code · registered within 24 hrs of receipt · transmittal exists for issue · superseded revision archived same day · withdrawal receipt on file
A21: 12 | B21: 04 | C21: 04.02_Drawings_and_Specifications | D21: BOTH | E21: Specifications and Technical Datasheets | F21: 5 sections | G21: Requirements measurable or testable · cited standards current · reconciled against BOQ
A22: 13 | B22: 04 | C22: 04.08_Shop_Drawings_and_Material_Submittals | D22: BOTH | E22: Material and Vendor Approval | F22: 10 submittals | G22: Reviewed within 7 days · checked against every specified parameter · sample retained at site · deviations formally accepted
A23: 14 | B23: 04 | C23: 04.08_Shop_Drawings_and_Material_Submittals | D23: BOTH | E23: Shop Drawing Review and Approval | F23: 10 submissions | G23: Reviewed within 7 working days · single clear status returned · no fabrication started before approval · resubmission count tracked
A24: 05_PROCUREMENT_AND_CONTRACTS
A25: 15 | B25: 05 | C25: 05.10_Customer_Supplied_Property | D25: BOTH | E25: Client Direct Purchase and FFE | F25: 5 client-supplied items | G25: Supply dates in the contract · inspected on delivery · custody transferred in writing · quantities reconciled
A26: 06_STATUTORY_AND_LAND
A27: 16 | B27: 06 | C27: 06.02_Statutory_Approvals_and_Permits | D27: BOTH | E27: Statutory Approvals and Permits | F27: All approvals | G27: All identified at inception and on the programme · queries answered within the authority's limit · nothing expiring within 60 days unactioned · conditions verified in the works
A28: 17 | B28: 06 | C28: 06.03_Labour_and_Statutory_Compliance | D28: SITE | E28: Labour Welfare and Statutory Compliance | F28: All contractors on site | G28: Registrations valid and re-checked not just verified once · PF and ESIC verified as remitted not merely deducted · welfare facilities physically inspected
A29: 18 | B29: 06 | C29: 06.04_Industrial_Statutory_Approvals | D29: BOTH | E29: Industrial Statutory Approvals and Licences | F29: All industrial approvals | G29: Factory plan approval BEFORE construction started · electrical inspectorate approval BEFORE energisation · conditions assigned and verified · full set before trial production
A30: 07_EXECUTION_AND_DELIVERY
A31: 19 | B31: 07 | C31: 07.01_Mobilisation_and_Site_Logistics | D31: SITE | E31: Site Logistics and Traffic Management | F31: Current logistics plan | G31: Planned by phase · lifting capacity verified against the heaviest lift · oversail consent in writing before erection
A32: 20 | B32: 07 | C32: 07.01_Mobilisation_and_Site_Logistics | D32: SITE | E32: Site Mobilisation and Establishment | F32: Mobilisation records | G32: Conditions precedent satisfied before entry · site layout approved before establishment · handover date formally recorded
A33: 21 | B33: 07 | C33: 07.02_Daily_Site_Records | D33: SITE | E33: Daily Progress Report | F33: 20 days across the period, including the busiest week | G33: Submitted by 10:00 next morning · labour verified by PMC not transcribed · quantities tied to WBS or BOQ · stoppages recorded with times · both signatures · no gaps in the date sequence
A34: 22 | B34: 07 | C34: 07.02_Daily_Site_Records | D34: SITE | E34: Progress Photography and Visual Record | F34: Photo archive | G34: Fixed vantage points at a set frequency · every image dated, located and labelled · all concealed work photographed before covering · backed up off-site
A35: 23 | B35: 07 | C35: 07.03_Site_Instructions_Client_Instructions | D35: SITE | E35: Site Instructions and Client Instructions | F35: 10 instructions | G35: Numbered · contract clause cited · cost and time impact recorded or expressly reserved · acknowledged · linked to a VO or CCR
A36: 24 | B36: 07 | C36: 07.04_Interface_Management_Between_Packages | D36: SITE | E36: Interface Management Between Packages | F36: 5 interfaces | G36: Identified at procurement not at site · single named owner · agreement converted to a drawing or schedule · verified physically before concealment
A37: 25 | B37: 07 | C37: 07.05_Work_Front_Release_Between_Trades | D37: SITE | E37: Work Front Release Between Trades | F37: 5 front releases | G37: Readiness criteria defined in advance · joint inspection with both trades · signed acceptance with snags listed · late release recorded against the handing trade
A38: 26 | B38: 07 | C38: 07.06_Method_Statements_and_Temporary_Works | D38: SITE | E38: Method Statement Review and Approval | F38: 10 method statements | G38: Reviewed within 5 working days · consistent with the JSA and ITP · briefed to the workforce before work started · re-approved on any method change
A39: 27 | B39: 07 | C39: 07.06_Method_Statements_and_Temporary_Works | D39: SITE | E39: Temporary Works Design and Control | F39: 5 temporary works | G39: Design independently checked to its category · permit to load issued after inspection · dismantling authorised in writing after strength verified
A40: 28 | B40: 07 | C40: 07.07_Material_Receipt_and_Traceability | D40: SITE | E40: Material Receipt, Inspection and Inventory | F40: 10 GRNs | G40: Checked against the approved submittal before acceptance · shortfall or damage noted on the challan at receipt · test certificate collected at receipt not at bill stage
A41: 29 | B41: 07 | C41: 07.08_Progress_Measurement_SCurve | D41: BOTH | E41: Progress Measurement and S-Curve | F41: Last 3 measurement rounds | G41: Measured physically against defined weightages · consistent rules of credit · same cut-off date each period · reconciled against certified value
...

Sheet FINDINGS
A1: SITE AUDIT FINDINGS AND CORRECTIVE ACTION
A2: One finding for every score below 2, from either the folder sampling or the site walk.
A5: # | B5: Finding ref. | C5: Source | D5: Ref. no. | E5: Folder / location | F5: Finding — what was actually found | G5: Photo ref. | H5: Severity | I5: Root cause | J5: Corrective action | K5: Preventive action | L5: Owner | M5: Target date | N5: Closed on | O5: Days open | P5: Overdue? | Q5: Verified by | R5: Status
A6: 1 | B6: SF-001 | C6: Site walk | D6: W-07 | E6: L3 workface, grid D4 | F6: Two prints of DR-ST-0142 rev C01 in use by the shuttering foreman. C02 issued 11 days earlier | G6: IMG-0412 | H6: Critical | I6: Withdrawal not enforced when C02 issued; no receipt taken | J6: All C01 prints recovered against receipt same day; boards audited | K6: Withdrawal receipt made a precondition of issuing the next revision | L6: Document Controller | M6: 2027-08-15 | R6: Open
O7: =IFERROR(IF(M7="","",IF(N7="",TODAY()-M7,N7-M7)),"") | P7: =IFERROR(IF(OR(M7="",R7="Closed"),"",IF(TODAY()>M7,"Yes","No")),"")
O8: =IFERROR(IF(M8="","",IF(N8="",TODAY()-M8,N8-M8)),"") | P8: =IFERROR(IF(OR(M8="",R8="Closed"),"",IF(TODAY()>M8,"Yes","No")),"")
O9: =IFERROR(IF(M9="","",IF(N9="",TODAY()-M9,N9-M9)),"") | P9: =IFERROR(IF(OR(M9="",R9="Closed"),"",IF(TODAY()>M9,"Yes","No")),"")
O10: =IFERROR(IF(M10="","",IF(N10="",TODAY()-M10,N10-M10)),"") | P10: =IFERROR(IF(OR(M10="",R10="Closed"),"",IF(TODAY()>M10,"Yes","No")),"")
O11: =IFERROR(IF(M11="","",IF(N11="",TODAY()-M11,N11-M11)),"") | P11: =IFERROR(IF(OR(M11="",R11="Closed"),"",IF(TODAY()>M11,"Yes","No")),"")
O12: =IFERROR(IF(M12="","",IF(N12="",TODAY()-M12,N12-M12)),"") | P12: =IFERROR(IF(OR(M12="",R12="Closed"),"",IF(TODAY()>M12,"Yes","No")),"")
O13: =IFERROR(IF(M13="","",IF(N13="",TODAY()-M13,N13-M13)),"") | P13: =IFERROR(IF(OR(M13="",R13="Closed"),"",IF(TODAY()>M13,"Yes","No")),"")
O14: =IFERROR(IF(M14="","",IF(N14="",TODAY()-M14,N14-M14)),"") | P14: =IFERROR(IF(OR(M14="",R14="Closed"),"",IF(TODAY()>M14,"Yes","No")),"")
O15: =IFERROR(IF(M15="","",IF(N15="",TODAY()-M15,N15-M15)),"") | P15: =IFERROR(IF(OR(M15="",R15="Closed"),"",IF(TODAY()>M15,"Yes","No")),"")
O16: =IFERROR(IF(M16="","",IF(N16="",TODAY()-M16,N16-M16)),"") | P16: =IFERROR(IF(OR(M16="",R16="Closed"),"",IF(TODAY()>M16,"Yes","No")),"")
O17: =IFERROR(IF(M17="","",IF(N17="",TODAY()-M17,N17-M17)),"") | P17: =IFERROR(IF(OR(M17="",R17="Closed"),"",IF(TODAY()>M17,"Yes","No")),"")
O18: =IFERROR(IF(M18="","",IF(N18="",TODAY()-M18,N18-M18)),"") | P18: =IFERROR(IF(OR(M18="",R18="Closed"),"",IF(TODAY()>M18,"Yes","No")),"")
... O105: =IFERROR(IF(M105="","",IF(N105="",TODAY()-M105,N105-M105)),"") | P105: =IFERROR(IF(OR(M105="",R105="Closed"),"",IF(TODAY()>M105,"Yes","No")),"")
