Workbook

Sheet Guide
A1: SHARNAM PROJECT DEVELOPMENT CONSULTANTS & CO. (SPDC)
A2: INTERVIEW ASSESSMENT & SCORING SYSTEM — USER GUIDE
A3: Doc No. SPDC/HR/F-INT-01 | Rev R0 | Competency-based, weighted, multi-panel evaluation
B5: PURPOSE
B6: Standardised, bias-controlled evaluation of candidates on role-weighted competencies, so every panel scores against the same anchored scale and hiring decisions are defensible and comparable.
B7: WORKBOOK STRUCTURE
B8: Framework | C8: Master list of 23 parameters in 5 categories, with behavioural anchors (1 / 3 / 5) and the weight of each parameter for each of the 10 positions. Each role column totals 100%.
B9: Rating_Scale | C9: 1–5 rating definitions, grade bands, knock-out & calibration rules and interview round weights. All thresholds are editable here.
B10: Scorecard | C10: One per candidate per round. Select the position; weights load automatically. Up to 3 panelists score independently; the sheet computes average, weighted score, category profile, grade and recommendation.
B11: Selection_Matrix | C11: Register of all candidates. Enter each round's score % from the Scorecard; composite score, rank within position, grade and decision are calculated.
B12: PROCESS
B13: Step 1 | C13: HR screening (Round 1) — use the Scorecard with Round = R1; score Fit, Communication and Integrity at minimum.
B14: Step 2 | C14: Technical interview (Round 2) — panelists score independently BEFORE discussing. Record evidence for every score of 1, 2 or 5.
B15: Step 3 | C15: Calibration — where the sheet flags 'Calibrate' (panel spread ≥ 2 points), the panel discusses the evidence and may revise scores.
B16: Step 4 | C16: Management interview (Round 3) — Leadership, Commercial and Client handling for senior roles; culture fit for all.
B17: Step 5 | C17: Transfer each round's Overall Score % to the Selection_Matrix. Compare candidates within the same position and take the decision.
B18: DECISION RULES
B19: Knock-out | C19: Any CRITICAL parameter (weight ≥ critical threshold for the role, plus Integrity for every role) with panel average below the knock-out threshold makes the candidate Not Recommended, regardless of total score.
B20: Grades | C20: A ≥ 85% Strongly Recommended | B ≥ 75% Recommended | C ≥ 65% Hold / consider for lower grade | D < 65% Not Recommended (bands editable in Rating_Scale).
B21: Fairness | C21: Score only on evidence heard in the interview. Do not score on age, gender, religion, caste, native place, marital status or any personal attribute unrelated to the job.
B22: LEGEND
B23: Input | C23: Yellow cells with blue text — enter or select values here only.
B24: Formula | C24: White cells with black text — calculated; do not overwrite.
B25: Not applicable | C25: Grey rows on the Scorecard have 0% weight for the selected position — leave blank.
B27: Prepared by | C27: HR & Admin | D27: Approved by | E27: Director

Sheet Scorecard
A1: SHARNAM PROJECT DEVELOPMENT CONSULTANTS & CO. (SPDC)
A2: CANDIDATE INTERVIEW SCORECARD
A3: Score each applicable parameter 1–5 against the anchors in Framework. Record evidence for any score of 1, 2 or 5. Grey rows = not applicable to the selected position.
B5: Candidate name | C5: Sample Candidate (example – overwrite) | I5: Panelist 1 (P1) | M5: Panelist name
B6: Position applied | C6: Senior Site Engineer (Civil) | I6: Panelist 2 (P2) | M6: Panelist name
B7: Interview round | C7: R2 – Technical | I7: Panelist 3 (P3) | M7: Panelist name
B8: Interview date | C8: 24-Sep-2026 | I8: Current CTC (₹ LPA) | M8: 7.2
B9: Total experience (yrs) | C9: 8 | I9: Expected CTC (₹ LPA) | M9: 9
B10: Source | C10: LinkedIn | I10: Notice period (days) | M10: 30
F12: SCORE (1–5)
A13: Code | B13: Category | C13: Parameter | D13: What to assess | E13: Weight | F13: P1 | G13: P2 | H13: P3 | I13: Panel avg | J13: Weighted score | K13: Critical | L13: Panel spread | M13: Evidence / remarks
A14: =Framework!A6 -> T1 | B14: =Framework!B6 -> Technical / Functional | C14: =Framework!C6 -> Core domain knowledge (role-specific) | D14: =Framework!D6 -> Codes & standards (IS/NBC/Factory Act/labour law as per role), drawing reading, fundamentals of the discipline | E14: =IF($C$6="",0,IFERROR(INDEX(Framework!$H$6:$Q$28,MATCH(A14,Framework!$A$6:$A$28,0),MATCH($C$6,Framework!$H$5:$Q$5,0)),0)) -> 0.12 | F14: 3 | G14: 3 | H14: 4 | I14: =IF(OR(E14=0,COUNT(F14:H14)=0),"",AVERAGE(F14:H14)) -> 3.3333333 | J14: =IF(I14="","",I14/5*E14) -> 0.08 | K14: =IF(E14=0,"",IF(OR(E14>=Rating_Scale!$C$20,A14="B6"),"Critical","")) -> Critical | L14: =IF(COUNT(F14:H14)<2,"",IF(MAX(F14:H14)-MIN(F14:H14)>=Rating_Scale!$C$22,"Calibrate","OK")) -> OK
A15: =Framework!A7 -> T2 | B15: =Framework!B7 -> Technical / Functional | C15: =Framework!C7 -> Planning & scheduling | D15: =Framework!D7 -> WBS, CPM logic, MSP/P6, look-ahead plans, baseline vs actual, S-curve, recovery planning | E15: =IF($C$6="",0,IFERROR(INDEX(Framework!$H$6:$Q$28,MATCH(A15,Framework!$A$6:$A$28,0),MATCH($C$6,Framework!$H$5:$Q$5,0)),0)) -> 0.05 | F15: 4 | G15: 3 | H15: 4 | I15: =IF(OR(E15=0,COUNT(F15:H15)=0),"",AVERAGE(F15:H15)) -> 3.6666667 | J15: =IF(I15="","",I15/5*E15) -> 0.036666667 | K15: =IF(E15=0,"",IF(OR(E15>=Rating_Scale!$C$20,A15="B6"),"Critical","")) | L15: =IF(COUNT(F15:H15)<2,"",IF(MAX(F15:H15)-MIN(F15:H15)>=Rating_Scale!$C$22,"Calibrate","OK")) -> OK
A16: =Framework!A8 -> T3 | B16: =Framework!B8 -> Technical / Functional | C16: =Framework!C8 -> Estimation, measurement & billing | D16: =Framework!D8 -> Quantity take-off, IS 1200 modes of measurement, BBS, RA bill checking, rate analysis | E16: =IF($C$6="",0,IFERROR(INDEX(Framework!$H$6:$Q$28,MATCH(A16,Framework!$A$6:$A$28,0),MATCH($C$6,Framework!$H$5:$Q$5,0)),0)) -> 0.05 | F16: 3 | G16: 3 | H16: 3 | I16: =IF(OR(E16=0,COUNT(F16:H16)=0),"",AVERAGE(F16:H16)) -> 3 | J16: =IF(I16="","",I16/5*E16) -> 0.03 | K16: =IF(E16=0,"",IF(OR(E16>=Rating_Scale!$C$20,A16="B6"),"Critical","")) | L16: =IF(COUNT(F16:H16)<2,"",IF(MAX(F16:H16)-MIN(F16:H16)>=Rating_Scale!$C$22,"Calibrate","OK")) -> OK
A17: =Framework!A9 -> T4 | B17: =Framework!B9 -> Technical / Functional | C17: =Framework!C9 -> Quality assurance & inspection | D17: =Framework!D9 -> ITP, material testing, checklists, NCR closure, method statements, third-party inspection | E17: =IF($C$6="",0,IFERROR(INDEX(Framework!$H$6:$Q$28,MATCH(A17,Framework!$A$6:$A$28,0),MATCH($C$6,Framework!$H$5:$Q$5,0)),0)) -> 0.07 | F17: 4 | G17: 4 | H17: 4 | I17: =IF(OR(E17=0,COUNT(F17:H17)=0),"",AVERAGE(F17:H17)) -> 4 | J17: =IF(I17="","",I17/5*E17) -> 0.056 | K17: =IF(E17=0,"",IF(OR(E17>=Rating_Scale!$C$20,A17="B6"),"Critical","")) | L17: =IF(COUNT(F17:H17)<2,"",IF(MAX(F17:H17)-MIN(F17:H17)>=Rating_Scale!$C$22,"Calibrate","OK")) -> OK
A18: =Framework!A10 -> T5 | B18: =Framework!B10 -> Technical / Functional | C18: =Framework!C10 -> Execution & site management | D18: =Framework!D10 -> Sequencing, method of construction, manpower/material/machinery planning, daily site control | E18: =IF($C$6="",0,IFERROR(INDEX(Framework!$H$6:$Q$28,MATCH(A18,Framework!$A$6:$A$28,0),MATCH($C$6,Framework!$H$5:$Q$5,0)),0)) -> 0.14 | F18: 4 | G18: 4 | H18: 5 | I18: =IF(OR(E18=0,COUNT(F18:H18)=0),"",AVERAGE(F18:H18)) -> 4.3333333 | J18: =IF(I18="","",I18/5*E18) -> 0.12133333 | K18: =IF(E18=0,"",IF(OR(E18>=Rating_Scale!$C$20,A18="B6"),"Critical","")) -> Critical | L18: =IF(COUNT(F18:H18)<2,"",IF(MAX(F18:H18)-MIN(F18:H18)>=Rating_Scale!$C$22,"Calibrate","OK")) -> OK
A19: =Framework!A11 -> T6 | B19: =Framework!B11 -> Technical / Functional | C19: =Framework!C11 -> Health, safety & environment | D19: =Framework!D11 -> HIRA/JSA, work permits, PPE, BOCW/Factory Act compliance, incident reporting & investigation | E19: =IF($C$6="",0,IFERROR(INDEX(Framework!$H$6:$Q$28,MATCH(A19,Framework!$A$6:$A$28,0),MATCH($C$6,Framework!$H$5:$Q$5,0)),0)) -> 0.06 | F19: 3 | G19: 4 | H19: 3 | I19: =IF(OR(E19=0,COUNT(F19:H19)=0),"",AVERAGE(F19:H19)) -> 3.3333333 | J19: =IF(I19="","",I19/5*E19) -> 0.04 | K19: =IF(E19=0,"",IF(OR(E19>=Rating_Scale!$C$20,A19="B6"),"Critical","")) | L19: =IF(COUNT(F19:H19)<2,"",IF(MAX(F19:H19)-MIN(F19:H19)>=Rating_Scale!$C$22,"Calibrate","OK")) -> OK
A20: =Framework!A12 -> T7 | B20: =Framework!B12 -> Technical / Functional | C20: =Framework!C12 -> Software & digital tools | D20: =Framework!D12 -> AutoCAD, MS Project/P6, Excel (advanced), ERP/HRMS, reporting tools as relevant to role | E20: =IF($C$6="",0,IFERROR(INDEX(Framework!$H$6:$Q$28,MATCH(A20,Framework!$A$6:$A$28,0),MATCH($C$6,Framework!$H$5:$Q$5,0)),0)) -> 0.02 | F20: 3 | G20: 3 | H20: 3 | I20: =IF(OR(E20=0,COUNT(F20:H20)=0),"",AVERAGE(F20:H20)) -> 3 | J20: =IF(I20="","",I20/5*E20) -> 0.012 | K20: =IF(E20=0,"",IF(OR(E20>=Rating_Scale!$C$20,A20="B6"),"Critical","")) | L20: =IF(COUNT(F20:H20)<2,"",IF(MAX(F20:H20)-MIN(F20:H20)>=Rating_Scale!$C$22,"Calibrate","OK")) -> OK | M20: Good sequencing logic; weak on permit system – probed twice
A21: =Framework!A13 -> C1 | B21: =Framework!B13 -> Commercial & Contract | C21: =Framework!C13 -> Contract & commercial awareness | D21: =Framework!D13 -> GCC/SCC clauses, scope, variations, extra items, claims, LDs, EOT, notices | E21: =IF($C$6="",0,IFERROR(INDEX(Framework!$H$6:$Q$28,MATCH(A21,Framework!$A$6:$A$28,0),MATCH($C$6,Framework!$H$5:$Q$5,0)),0)) -> 0.03 | F21: 3 | G21: 2 | H21: 3 | I21: =IF(OR(E21=0,COUNT(F21:H21)=0),"",AVERAGE(F21:H21)) -> 2.6666667 | J21: =IF(I21="","",I21/5*E21) -> 0.016 | K21: =IF(E21=0,"",IF(OR(E21>=Rating_Scale!$C$20,A21="B6"),"Critical","")) | L21: =IF(COUNT(F21:H21)<2,"",IF(MAX(F21:H21)-MIN(F21:H21)>=Rating_Scale!$C$22,"Calibrate","OK")) -> OK
A22: =Framework!A14 -> C2 | B22: =Framework!B14 -> Commercial & Contract | C22: =Framework!C14 -> Cost control & value engineering | D22: =Framework!D14 -> Budget vs actual, cost-to-complete, wastage control, alternatives that save cost without loss of quality | E22: =IF($C$6="",0,IFERROR(INDEX(Framework!$H$6:$Q$28,MATCH(A22,Framework!$A$6:$A$28,0),MATCH($C$6,Framework!$H$5:$Q$5,0)),0)) -> 0.03 | F22: 3 | G22: 3 | H22: 3 | I22: =IF(OR(E22=0,COUNT(F22:H22)=0),"",AVERAGE(F22:H22)) -> 3 | J22: =IF(I22="","",I22/5*E22) -> 0.018 | K22: =IF(E22=0,"",IF(OR(E22>=Rating_Scale!$C$20,A22="B6"),"Critical","")) | L22: =IF(COUNT(F22:H22)<2,"",IF(MAX(F22:H22)-MIN(F22:H22)>=Rating_Scale!$C$22,"Calibrate","OK")) -> OK
A23: =Framework!A15 -> C3 | B23: =Framework!B15 -> Commercial & Contract | C23: =Framework!C15 -> Documentation & reporting | D23: =Framework!D15 -> DPR/WPR/MPR, MOM, RFI, submittal logs, registers, record-keeping discipline | E23: =IF($C$6="",0,IFERROR(INDEX(Framework!$H$6:$Q$28,MATCH(A23,Framework!$A$6:$A$28,0),MATCH($C$6,Framework!$H$5:$Q$5,0)),0)) -> 0.04 | F23: 4 | G23: 3 | H23: 3 | I23: =IF(OR(E23=0,COUNT(F23:H23)=0),"",AVERAGE(F23:H23)) -> 3.3333333 | J23: =IF(I23="","",I23/5*E23) -> 0.026666667 | K23: =IF(E23=0,"",IF(OR(E23>=Rating_Scale!$C$20,A23="B6"),"Critical","")) | L23: =IF(COUNT(F23:H23)<2,"",IF(MAX(F23:H23)-MIN(F23:H23)>=Rating_Scale!$C$22,"Calibrate","OK")) -> OK
A24: =Framework!A16 -> C4 | B24: =Framework!B16 -> Commercial & Contract | C24: =Framework!C16 -> Contractor & vendor management | D24: =Framework!D16 -> Contractor coordination, follow-up, submittal/approval chasing, performance review | E24: =IF($C$6="",0,IFERROR(INDEX(Framework!$H$6:$Q$28,MATCH(A24,Framework!$A$6:$A$28,0),MATCH($C$6,Framework!$H$5:$Q$5,0)),0)) -> 0.06 | F24: 4 | G24: 4 | H24: 4 | I24: =IF(OR(E24=0,COUNT(F24:H24)=0),"",AVERAGE(F24:H24)) -> 4 | J24: =IF(I24="","",I24/5*E24) -> 0.048 | K24: =IF(E24=0,"",IF(OR(E24>=Rating_Scale!$C$20,A24="B6"),"Critical","")) | L24: =IF(COUNT(F24:H24)<2,"",IF(MAX(F24:H24)-MIN(F24:H24)>=Rating_Scale!$C$22,"Calibrate","OK")) -> OK
A25: =Framework!A17 -> B1 | B25: =Framework!B17 -> Behavioural | C25: =Framework!C17 -> Problem solving & decision making | D25: =Framework!D17 -> Case-based: structured approach, root cause, options, decision under incomplete data | E25: =IF($C$6="",0,IFERROR(INDEX(Framework!$H$6:$Q$28,MATCH(A25,Framework!$A$6:$A$28,0),MATCH($C$6,Framework!$H$5:$Q$5,0)),0)) -> 0.05 | F25: 4 | G25: 3 | H25: 4 | I25: =IF(OR(E25=0,COUNT(F25:H25)=0),"",AVERAGE(F25:H25)) -> 3.6666667 | J25: =IF(I25="","",I25/5*E25) -> 0.036666667 | K25: =IF(E25=0,"",IF(OR(E25>=Rating_Scale!$C$20,A25="B6"),"Critical","")) | L25: =IF(COUNT(F25:H25)<2,"",IF(MAX(F25:H25)-MIN(F25:H25)>=Rating_Scale!$C$22,"Calibrate","OK")) -> OK
A26: =Framework!A18 -> B2 | B26: =Framework!B18 -> Behavioural | C26: =Framework!C18 -> Communication | D26: =Framework!D18 -> Clarity, listening, written English/Gujarati/Hindi, presentation to client | E26: =IF($C$6="",0,IFERROR(INDEX(Framework!$H$6:$Q$28,MATCH(A26,Framework!$A$6:$A$28,0),MATCH($C$6,Framework!$H$5:$Q$5,0)),0)) -> 0.03 | F26: 3 | G26: 3 | H26: 3 | I26: =IF(OR(E26=0,COUNT(F26:H26)=0),"",AVERAGE(F26:H26)) -> 3 | J26: =IF(I26="","",I26/5*E26) -> 0.018 | K26: =IF(E26=0,"",IF(OR(E26>=Rating_Scale!$C$20,A26="B6"),"Critical","")) | L26: =IF(COUNT(F26:H26)<2,"",IF(MAX(F26:H26)-MIN(F26:H26)>=Rating_Scale!$C$22,"Calibrate","OK")) -> OK
A27: =Framework!A19 -> B3 | B27: =Framework!B19 -> Behavioural | C27: =Framework!C19 -> Client & stakeholder handling | D27: =Framework!D19 -> Managing client expectations, conflicts, escalations, professional conduct | E27: =IF($C$6="",0,IFERROR(INDEX(Framework!$H$6:$Q$28,MATCH(A27,Framework!$A$6:$A$28,0),MATCH($C$6,Framework!$H$5:$Q$5,0)),0)) -> 0.03 | F27: 3 | G27: 4 | H27: 3 | I27: =IF(OR(E27=0,COUNT(F27:H27)=0),"",AVERAGE(F27:H27)) -> 3.3333333 | J27: =IF(I27="","",I27/5*E27) -> 0.02 | K27: =IF(E27=0,"",IF(OR(E27>=Rating_Scale!$C$20,A27="B6"),"Critical","")) | L27: =IF(COUNT(F27:H27)<2,"",IF(MAX(F27:H27)-MIN(F27:H27)>=Rating_Scale!$C$22,"Calibrate","OK")) -> OK
A28: =Framework!A20 -> B4 | B28: =Framework!B20 -> Behavioural | C28: =Framework!C20 -> Ownership & accountability | D28: =Framework!D20 -> Examples of owning outcomes, follow-through, admitting mistakes | E28: =IF($C$6="",0,IFERROR(INDEX(Framework!$H$6:$Q$28,MATCH(A28,Framework!$A$6:$A$28,0),MATCH($C$6,Framework!$H$5:$Q$5,0)),0)) -> 0.04 | F28: 4 | G28: 4 | H28: 4 | I28: =IF(OR(E28=0,COUNT(F28:H28)=0),"",AVERAGE(F28:H28)) -> 4 | J28: =IF(I28="","",I28/5*E28) -> 0.032 | K28: =IF(E28=0,"",IF(OR(E28>=Rating_Scale!$C$20,A28="B6"),"Critical","")) | L28: =IF(COUNT(F28:H28)<2,"",IF(MAX(F28:H28)-MIN(F28:H28)>=Rating_Scale!$C$22,"Calibrate","OK")) -> OK
A29: =Framework!A21 -> B5 | B29: =Framework!B21 -> Behavioural | C29: =Framework!C21 -> Teamwork & collaboration | D29: =Framework!D21 -> Working with other disciplines, sharing information, supporting colleagues | E29: =IF($C$6="",0,IFERROR(INDEX(Framework!$H$6:$Q$28,MATCH(A29,Framework!$A$6:$A$28,0),MATCH($C$6,Framework!$H$5:$Q$5,0)),0)) -> 0.02 | F29: 3 | G29: 3 | H29: 3 | I29: =IF(OR(E29=0,COUNT(F29:H29)=0),"",AVERAGE(F29:H29)) -> 3 | J29: =IF(I29="","",I29/5*E29) -> 0.012 | K29: =IF(E29=0,"",IF(OR(E29>=Rating_Scale!$C$20,A29="B6"),"Critical","")) | L29: =IF(COUNT(F29:H29)<2,"",IF(MAX(F29:H29)-MIN(F29:H29)>=Rating_Scale!$C$22,"Calibrate","OK")) -> OK
A30: =Framework!A22 -> B6 | B30: =Framework!B22 -> Behavioural | C30: =Framework!C22 -> Integrity & ethics | D30: =Framework!D22 -> Honesty in examples, stance on vendor favours, measurement/quality compromise scenarios | E30: =IF($C$6="",0,IFERROR(INDEX(Framework!$H$6:$Q$28,MATCH(A30,Framework!$A$6:$A$28,0),MATCH($C$6,Framework!$H$5:$Q$5,0)),0)) -> 0.05 | F30: 5 | G30: 4 | H30: 4 | I30: =IF(OR(E30=0,COUNT(F30:H30)=0),"",AVERAGE(F30:H30)) -> 4.3333333 | J30: =IF(I30="","",I30/5*E30) -> 0.043333333 | K30: =IF(E30=0,"",IF(OR(E30>=Rating_Scale!$C$20,A30="B6"),"Critical","")) -> Critical | L30: =IF(COUNT(F30:H30)<2,"",IF(MAX(F30:H30)-MIN(F30:H30)>=Rating_Scale!$C$22,"Calibrate","OK")) -> OK
A31: =Framework!A23 -> B7 | B31: =Framework!B23 -> Behavioural | C31: =Framework!C23 -> Pressure handling & adaptability | D31: =Framework!D23 -> Deadlines, changing priorities, site crises, night work, learning new systems | E31: =IF($C$6="",0,IFERROR(INDEX(Framework!$H$6:$Q$28,MATCH(A31,Framework!$A$6:$A$28,0),MATCH($C$6,Framework!$H$5:$Q$5,0)),0)) -> 0.03 | F31: 4 | G31: 4 | H31: 3 | I31: =IF(OR(E31=0,COUNT(F31:H31)=0),"",AVERAGE(F31:H31)) -> 3.6666667 | J31: =IF(I31="","",I31/5*E31) -> 0.022 | K31: =IF(E31=0,"",IF(OR(E31>=Rating_Scale!$C$20,A31="B6"),"Critical","")) | L31: =IF(COUNT(F31:H31)<2,"",IF(MAX(F31:H31)-MIN(F31:H31)>=Rating_Scale!$C$22,"Calibrate","OK")) -> OK
A32: =Framework!A24 -> L1 | B32: =Framework!B24 -> Leadership | C32: =Framework!C24 -> Team leadership & people management | D32: =Framework!D24 -> Leading engineers/supervisors, delegation, mentoring, performance feedback | E32: =IF($C$6="",0,IFERROR(INDEX(Framework!$H$6:$Q$28,MATCH(A32,Framework!$A$6:$A$28,0),MATCH($C$6,Framework!$H$5:$Q$5,0)),0)) -> 0.04 | F32: 3 | G32: 3 | H32: 4 | I32: =IF(OR(E32=0,COUNT(F32:H32)=0),"",AVERAGE(F32:H32)) -> 3.3333333 | J32: =IF(I32="","",I32/5*E32) -> 0.026666667 | K32: =IF(E32=0,"",IF(OR(E32>=Rating_Scale!$C$20,A32="B6"),"Critical","")) | L32: =IF(COUNT(F32:H32)<2,"",IF(MAX(F32:H32)-MIN(F32:H32)>=Rating_Scale!$C$22,"Calibrate","OK")) -> OK
A33: =Framework!A25 -> L2 | B33: =Framework!B25 -> Leadership | C33: =Framework!C25 -> Strategic thinking & foresight | D33: =Framework!D25 -> Project-level view, risk anticipation, planning ahead of client needs | E33: =IF($C$6="",0,IFERROR(INDEX(Framework!$H$6:$Q$28,MATCH(A33,Framework!$A$6:$A$28,0),MATCH($C$6,Framework!$H$5:$Q$5,0)),0)) -> 0 | I33: =IF(OR(E33=0,COUNT(F33:H33)=0),"",AVERAGE(F33:H33)) | J33: =IF(I33="","",I33/5*E33) | K33: =IF(E33=0,"",IF(OR(E33>=Rating_Scale!$C$20,A33="B6"),"Critical","")) | L33: =IF(COUNT(F33:H33)<2,"",IF(MAX(F33:H33)-MIN(F33:H33)>=Rating_Scale!$C$22,"Calibrate","OK"))
A34: =Framework!A26 -> F1 | B34: =Framework!B26 -> Fit & Motivation | C34: =Framework!C26 -> Career stability & motivation | D34: =Framework!D26 -> Tenure pattern, reasons for change, genuine interest in PMC career | E34: =IF($C$6="",0,IFERROR(INDEX(Framework!$H$6:$Q$28,MATCH(A34,Framework!$A$6:$A$28,0),MATCH($C$6,Framework!$H$5:$Q$5,0)),0)) -> 0.01 | F34: 4 | G34: 4 | H34: 4 | I34: =IF(OR(E34=0,COUNT(F34:H34)=0),"",AVERAGE(F34:H34)) -> 4 | J34: =IF(I34="","",I34/5*E34) -> 0.008 | K34: =IF(E34=0,"",IF(OR(E34>=Rating_Scale!$C$20,A34="B6"),"Critical","")) | L34: =IF(COUNT(F34:H34)<2,"",IF(MAX(F34:H34)-MIN(F34:H34)>=Rating_Scale!$C$22,"Calibrate","OK")) -> OK
A35: =Framework!A27 -> F2 | B35: =Framework!B27 -> Fit & Motivation | C35: =Framework!C27 -> Culture fit (SPDC values) | D35: =Framework!D27 -> Discipline, client-first attitude, learning mindset, alignment with SPDC way of working | E35: =IF($C$6="",0,IFERROR(INDEX(Framework!$H$6:$Q$28,MATCH(A35,Framework!$A$6:$A$28,0),MATCH($C$6,Framework!$H$5:$Q$5,0)),0)) -> 0.01 | F35: 4 | G35: 3 | H35: 4 | I35: =IF(OR(E35=0,COUNT(F35:H35)=0),"",AVERAGE(F35:H35)) -> 3.6666667 | J35: =IF(I35="","",I35/5*E35) -> 0.0073333333 | K35: =IF(E35=0,"",IF(OR(E35>=Rating_Scale!$C$20,A35="B6"),"Critical","")) | L35: =IF(COUNT(F35:H35)<2,"",IF(MAX(F35:H35)-MIN(F35:H35)>=Rating_Scale!$C$22,"Calibrate","OK")) -> OK
A36: =Framework!A28 -> F3 | B36: =Framework!B28 -> Fit & Motivation | C36: =Framework!C28 -> Site / travel readiness | D36: =Framework!D28 -> Willingness to relocate, site posting, travel, availability | E36: =IF($C$6="",0,IFERROR(INDEX(Framework!$H$6:$Q$28,MATCH(A36,Framework!$A$6:$A$28,0),MATCH($C$6,Framework!$H$5:$Q$5,0)),0)) -> 0.02 | F36: 5 | G36: 5 | H36: 4 | I36: =IF(OR(E36=0,COUNT(F36:H36)=0),"",AVERAGE(F36:H36)) -> 4.6666667 | J36: =IF(I36="","",I36/5*E36) -> 0.018666667 | K36: =IF(E36=0,"",IF(OR(E36>=Rating_Scale!$C$20,A36="B6"),"Critical","")) | L36: =IF(COUNT(F36:H36)<2,"",IF(MAX(F36:H36)-MIN(F36:H36)>=Rating_Scale!$C$22,"Calibrate","OK")) -> OK
A37: TOTAL | E37: =SUM(E14:E36) -> 1 | J37: =SUM(J14:J36) -> 0.72933333
A39: RESULT SUMMARY | F39: CATEGORY PROFILE
A40: Applicable parameters | C40: =COUNTIF(E14:E36,">0") -> 22 | F40: Category | H40: Weight | I40: Score %
A41: Parameters scored | C41: =COUNT(I14:I36) -> 22 | F41: Technical / Functional | H41: =SUMIF($B$14:$B$36,F41,$E$14:$E$36) -> 0.51 | I41: =IFERROR(SUMIF($B$14:$B$36,F41,$J$14:$J$36)/SUMPRODUCT(($B$14:$B$36=F41)*($I$14:$I$36<>"")*$E$14:$E$36),0) -> 0.7372549
A42: Weight covered by scores | C42: =SUMPRODUCT((I14:I36<>"")*E14:E36) -> 1 | F42: Commercial & Contract | H42: =SUMIF($B$14:$B$36,F42,$E$14:$E$36) -> 0.16 | I42: =IFERROR(SUMIF($B$14:$B$36,F42,$J$14:$J$36)/SUMPRODUCT(($B$14:$B$36=F42)*($I$14:$I$36<>"")*$E$14:$E$36),0) -> 0.67916667
A43: OVERALL SCORE % | C43: =IFERROR(J37/C42,0) -> 0.72933333 | F43: Behavioural | H43: =SUMIF($B$14:$B$36,F43,$E$14:$E$36) -> 0.25 | I43: =IFERROR(SUMIF($B$14:$B$36,F43,$J$14:$J$36)/SUMPRODUCT(($B$14:$B$36=F43)*($I$14:$I$36<>"")*$E$14:$E$36),0) -> 0.736
...

Sheet Framework
A1: SHARNAM PROJECT DEVELOPMENT CONSULTANTS & CO. (SPDC)
A2: COMPETENCY FRAMEWORK & ROLE WEIGHTAGE MATRIX
A3: Weights are editable (blue). Each role column must total 100% — see check row. Anchors describe evidence expected at score 1, 3 and 5.
H4: WEIGHTAGE BY POSITION (%)
A5: Code | B5: Category | C5: Parameter | D5: What to assess / probe | E5: Anchor — Score 1 | F5: Anchor — Score 3 | G5: Anchor — Score 5 | H5: Project Manager (Site) | I5: Planning Engineer | J5: Billing / QS Engineer | K5: Project Coordinator | L5: Senior Site Engineer (Civil) | M5: Junior Engineer | N5: QA/QC Engineer | O5: MEP Engineer | P5: Safety Officer | Q5: HR & Admin Executive
A6: T1 | B6: Technical / Functional | C6: Core domain knowledge (role-specific) | D6: Codes & standards (IS/NBC/Factory Act/labour law as per role), drawing reading, fundamentals of the discipline | E6: Gaps in basics; cannot explain standard practice | F6: Sound working knowledge; answers standard questions correctly | G6: Deep, current knowledge; cites codes/clauses and applies them to unusual cases | H6: 0.1 | I6: 0.06 | J6: 0.08 | K6: 0.05 | L6: 0.12 | M6: 0.14 | N6: 0.12 | O6: 0.18 | P6: 0.08 | Q6: 0.2
A7: T2 | B7: Technical / Functional | C7: Planning & scheduling | D7: WBS, CPM logic, MSP/P6, look-ahead plans, baseline vs actual, S-curve, recovery planning | E7: Cannot build or read a schedule | F7: Builds a logical schedule and tracks progress | G7: Drives CPM, float and recovery plans; forecasts delays before they happen | H7: 0.06 | I7: 0.2 | J7: 0.02 | K7: 0.08 | L7: 0.05 | M7: 0.03 | N7: 0 | O7: 0.04 | P7: 0 | Q7: 0
A8: T3 | B8: Technical / Functional | C8: Estimation, measurement & billing | D8: Quantity take-off, IS 1200 modes of measurement, BBS, RA bill checking, rate analysis | E8: Errors in basic quantities; unaware of measurement rules | F8: Correct quantities & bill checking with minor guidance | G8: Independently certifies bills, spots over-measurement and rate deviations | H8: 0.03 | I8: 0.04 | J8: 0.22 | K8: 0.03 | L8: 0.05 | M8: 0.06 | N8: 0.03 | O8: 0.05 | P8: 0 | Q8: 0
A9: T4 | B9: Technical / Functional | C9: Quality assurance & inspection | D9: ITP, material testing, checklists, NCR closure, method statements, third-party inspection | E9: Treats quality as paperwork only | F9: Follows ITP and raises NCRs correctly | G9: Builds QA systems, root-causes defects, prevents repeat NCRs | H9: 0.04 | I9: 0 | J9: 0.02 | K9: 0.02 | L9: 0.07 | M9: 0.06 | N9: 0.22 | O9: 0.08 | P9: 0.03 | Q9: 0
A10: T5 | B10: Technical / Functional | C10: Execution & site management | D10: Sequencing, method of construction, manpower/material/machinery planning, daily site control | E10: Theoretical only; little site exposure | F10: Manages a work front independently | G10: Runs multiple fronts; anticipates constraints and resolves them on site | H10: 0.08 | I10: 0.06 | J10: 0.03 | K10: 0.04 | L10: 0.14 | M10: 0.12 | N10: 0.05 | O10: 0.1 | P10: 0.05 | Q10: 0
A11: T6 | B11: Technical / Functional | C11: Health, safety & environment | D11: HIRA/JSA, work permits, PPE, BOCW/Factory Act compliance, incident reporting & investigation | E11: Low safety awareness; accepts unsafe acts | F11: Knows and enforces standard safety practice | G11: Leads a safety culture; permit systems, audits, zero-harm mindset | H11: 0.04 | I11: 0 | J11: 0 | K11: 0.02 | L11: 0.06 | M11: 0.05 | N11: 0.03 | O11: 0.05 | P11: 0.25 | Q11: 0
A12: T7 | B12: Technical / Functional | C12: Software & digital tools | D12: AutoCAD, MS Project/P6, Excel (advanced), ERP/HRMS, reporting tools as relevant to role | E12: Basic or no tool use | F12: Uses role tools competently for daily output | G12: Expert user; automates reports and dashboards | H12: 0.02 | I12: 0.1 | J12: 0.06 | K12: 0.06 | L12: 0.02 | M12: 0.04 | N12: 0.03 | O12: 0.03 | P12: 0.02 | Q12: 0.08
A13: C1 | B13: Commercial & Contract | C13: Contract & commercial awareness | D13: GCC/SCC clauses, scope, variations, extra items, claims, LDs, EOT, notices | E13: Unaware of contract implications of site actions | F13: Understands key clauses and variation procedure | G13: Protects client commercially; handles claims and EOT with evidence | H13: 0.08 | I13: 0.05 | J13: 0.12 | K13: 0.05 | L13: 0.03 | M13: 0 | N13: 0.03 | O13: 0.04 | P13: 0.02 | Q13: 0.04
A14: C2 | B14: Commercial & Contract | C14: Cost control & value engineering | D14: Budget vs actual, cost-to-complete, wastage control, alternatives that save cost without loss of quality | E14: No cost sense | F14: Tracks cost of own scope and flags overruns | G14: Proposes value engineering with quantified savings | H14: 0.06 | I14: 0.06 | J14: 0.08 | K14: 0.03 | L14: 0.03 | M14: 0 | N14: 0 | O14: 0.03 | P14: 0 | Q14: 0.03
A15: C3 | B15: Commercial & Contract | C15: Documentation & reporting | D15: DPR/WPR/MPR, MOM, RFI, submittal logs, registers, record-keeping discipline | E15: Poor or delayed records | F15: Timely, accurate reports in standard format | G15: Reports are decision-ready; audit-proof record trail | H15: 0.03 | I15: 0.08 | J15: 0.06 | K15: 0.12 | L15: 0.04 | M15: 0.05 | N15: 0.08 | O15: 0.04 | P15: 0.08 | Q15: 0.1
A16: C4 | B16: Commercial & Contract | C16: Contractor & vendor management | D16: Contractor coordination, follow-up, submittal/approval chasing, performance review | E16: Avoids or mishandles contractors | F16: Coordinates contractors to schedule | G16: Gets performance from contractors firmly and fairly; escalates correctly | H16: 0.05 | I16: 0.02 | J16: 0.04 | K16: 0.06 | L16: 0.06 | M16: 0.02 | N16: 0.05 | O16: 0.06 | P16: 0.05 | Q16: 0
A17: B1 | B17: Behavioural | C17: Problem solving & decision making | D17: Case-based: structured approach, root cause, options, decision under incomplete data | E17: Jumps to conclusions or freezes | F17: Logical approach reaching a workable answer | G17: Structured, fast, practical decisions with clear trade-offs | H17: 0.05 | I17: 0.07 | J17: 0.05 | K17: 0.05 | L17: 0.05 | M17: 0.06 | N17: 0.06 | O17: 0.06 | P17: 0.06 | Q17: 0.06
... A28: F3 | B28: Fit & Motivation | C28: Site / travel readiness | D28: Willingness to relocate, site posting, travel, availability | E28: Not willing for site / travel | F28: Willing with minor constraints | G28: Fully mobile and available | H28: 0 | I28: 0 | J28: 0 | K28: 0 | L28: 0.02 | M28: 0.05 | N28: 0.02 | O28: 0.01 | P28: 0.03 | Q28: 0
A29: TOTAL WEIGHT | H29: =SUM(H6:H28) -> 1 | I29: =SUM(I6:I28) -> 1 | J29: =SUM(J6:J28) -> 1 | K29: =SUM(K6:K28) -> 1 | L29: =SUM(L6:L28) -> 1 | M29: =SUM(M6:M28) -> 1 | N29: =SUM(N6:N28) -> 1 | O29: =SUM(O6:O28) -> 1 | ... Q29: =SUM(Q6:Q28) -> 1
A30: CHECK (must be 100%) | H30: =IF(ABS(H29-1)<0.0001,"OK","ERROR") -> OK | I30: =IF(ABS(I29-1)<0.0001,"OK","ERROR") -> OK | J30: =IF(ABS(J29-1)<0.0001,"OK","ERROR") -> OK | K30: =IF(ABS(K29-1)<0.0001,"OK","ERROR") -> OK | L30: =IF(ABS(L29-1)<0.0001,"OK","ERROR") -> OK | M30: =IF(ABS(M29-1)<0.0001,"OK","ERROR") -> OK | N30: =IF(ABS(N29-1)<0.0001,"OK","ERROR") -> OK | O30: =IF(ABS(O29-1)<0.0001,"OK","ERROR") -> OK | ... Q30: =IF(ABS(Q29-1)<0.0001,"OK","ERROR") -> OK

Sheet Rating_Scale
A1: SHARNAM PROJECT DEVELOPMENT CONSULTANTS & CO. (SPDC)
A2: RATING SCALE, GRADE BANDS & DECISION RULES
A3: All thresholds on this sheet drive the Scorecard and Selection_Matrix. Edit blue cells only.
B5: Score | C5: Level | D5: Definition | E5: Typical evidence
B6: 5 | C6: Exceptional | D6: Consistently exceeds the requirement; role-model level | E6: Multiple specific, verifiable examples; could train others
B7: 4 | C7: Exceeds expectations | D7: Above the requirement in most respects | E7: Clear examples with measurable results
B8: 3 | C8: Meets expectations | D8: Fully meets the requirement of the position | E8: Adequate examples; answers correct with minor prompting
B9: 2 | C9: Below expectations | D9: Partially meets; development needed | E9: Vague examples; answers need significant prompting
B10: 1 | C10: Unsatisfactory | D10: Does not meet the requirement | E10: No relevant evidence or incorrect answers
B12: Grade | C12: Minimum score % | D12: Decision | E12: Action
B13: A | C13: 0.85 | D13: Strongly Recommended – Select | E13: Proceed to offer; negotiate within approved band
B14: B | C14: 0.75 | D14: Recommended | E14: Select if best in pool; reference check mandatory
B15: C | C15: 0.65 | D15: Hold / Consider for lower grade | E15: Keep in pipeline or consider for a junior position
B16: D | C16: 0 | D16: Not Recommended | E16: Regret letter within 7 days
B19: Rule | C19: Value | D19: Meaning
B20: Critical weight | C20: 0.1 | D20: A parameter with weight at or above this for the selected role is CRITICAL (Integrity B6 is always critical).
B21: Knock-out average | C21: 2.5 | D21: Critical parameter with panel average below this value = Not Recommended, irrespective of total score.
B22: Calibration spread | C22: 2 | D22: Difference between highest and lowest panelist score at or above this triggers a 'Calibrate' flag.
B25: Round | C25: Weight | D25: Focus
B26: R1 – HR Screening | C26: 0.2 | D26: Fit, communication, integrity, stability, CTC & notice alignment
B27: R2 – Technical | C27: 0.5 | D27: Technical / functional and commercial parameters, case questions
B28: R3 – Management | C28: 0.3 | D28: Leadership, client handling, judgement, culture fit, final approval
B29: Total | C29: =SUM(C26:C28) -> 1 | D29: =IF(ABS(C29-1)<0.0001,"OK","ERROR – round weights must total 100%") -> OK

Sheet Selection_Matrix
A1: SHARNAM PROJECT DEVELOPMENT CONSULTANTS & CO. (SPDC)
A2: CANDIDATE SELECTION MATRIX
A3: Enter each round's OVERALL SCORE % from the Scorecard. Composite uses round weights on Rating_Scale, re-weighted over the rounds completed.
B5: Candidates evaluated | D5: =COUNTA(B8:B57) -> 4 | E5: Recommended (A/B) | H5: =COUNTIF(K8:K57,"A")+COUNTIF(K8:K57,"B")-COUNTIFS(I8:I57,"Y",K8:K57,"A")-COUNTIFS(I8:I57,"Y",K8:K57,"B") -> 2
A7: S.No | B7: Candidate name | C7: Position | D7: Date | E7: R1 HR % | F7: R2 Tech % | G7: R3 Mgmt % | H7: Composite % | I7: Knock-out (Y/N) | J7: Rank in position | K7: Grade | L7: Decision | M7: Remarks
A8: 1 | B8: Candidate A (example) | C8: Senior Site Engineer (Civil) | D8: 22-Sep-2026 | E8: 0.78 | F8: 0.82 | G8: 0.8 | H8: =IF(COUNT(E8:G8)=0,"",(IF(E8="",0,E8*Rating_Scale!$C$26)+IF(F8="",0,F8*Rating_Scale!$C$27)+IF(G8="",0,G8*Rating_Scale!$C$28))/(IF(E8="",0,Rating_Scale!$C$26)+IF(F8="",0,Rating_Scale!$C$27)+IF(G8="",0,Rating_Scale!$C$28))) -> 0.806 | I8: N | J8: =IF(OR(H8="",C8=""),"",COUNTIFS($C$8:$C$57,C8,$H$8:$H$57,">"&H8)+1) -> 2 | K8: =IF(H8="","",IF(H8>=Rating_Scale!$C$13,"A",IF(H8>=Rating_Scale!$C$14,"B",IF(H8>=Rating_Scale!$C$15,"C","D")))) -> B | L8: =IF(H8="","",IF(I8="Y","Not Recommended – Knock-out",IF(COUNT(E8:G8)<3,"Interim – rounds pending ("&INDEX(Rating_Scale!$D$13:$D$16,MATCH(K8,Rating_Scale!$B$13:$B$16,0))&")",INDEX(Rating_Scale!$D$13:$D$16,MATCH(K8,Rating_Scale!$B$13:$B$16,0))))) -> Recommended
A9: 2 | B9: Candidate B (example) | C9: Senior Site Engineer (Civil) | D9: 23-Sep-2026 | E9: 0.72 | F9: 0.88 | H9: =IF(COUNT(E9:G9)=0,"",(IF(E9="",0,E9*Rating_Scale!$C$26)+IF(F9="",0,F9*Rating_Scale!$C$27)+IF(G9="",0,G9*Rating_Scale!$C$28))/(IF(E9="",0,Rating_Scale!$C$26)+IF(F9="",0,Rating_Scale!$C$27)+IF(G9="",0,Rating_Scale!$C$28))) -> 0.83428571 | I9: N | J9: =IF(OR(H9="",C9=""),"",COUNTIFS($C$8:$C$57,C9,$H$8:$H$57,">"&H9)+1) -> 1 | K9: =IF(H9="","",IF(H9>=Rating_Scale!$C$13,"A",IF(H9>=Rating_Scale!$C$14,"B",IF(H9>=Rating_Scale!$C$15,"C","D")))) -> B | L9: =IF(H9="","",IF(I9="Y","Not Recommended – Knock-out",IF(COUNT(E9:G9)<3,"Interim – rounds pending ("&INDEX(Rating_Scale!$D$13:$D$16,MATCH(K9,Rating_Scale!$B$13:$B$16,0))&")",INDEX(Rating_Scale!$D$13:$D$16,MATCH(K9,Rating_Scale!$B$13:$B$16,0))))) -> Interim – rounds pending (Recommended)
A10: 3 | B10: Candidate C (example) | C10: Senior Site Engineer (Civil) | D10: 23-Sep-2026 | E10: 0.8 | F10: 0.74 | G10: 0.7 | H10: =IF(COUNT(E10:G10)=0,"",(IF(E10="",0,E10*Rating_Scale!$C$26)+IF(F10="",0,F10*Rating_Scale!$C$27)+IF(G10="",0,G10*Rating_Scale!$C$28))/(IF(E10="",0,Rating_Scale!$C$26)+IF(F10="",0,Rating_Scale!$C$27)+IF(G10="",0,Rating_Scale!$C$28))) -> 0.74 | I10: Y | J10: =IF(OR(H10="",C10=""),"",COUNTIFS($C$8:$C$57,C10,$H$8:$H$57,">"&H10)+1) -> 3 | K10: =IF(H10="","",IF(H10>=Rating_Scale!$C$13,"A",IF(H10>=Rating_Scale!$C$14,"B",IF(H10>=Rating_Scale!$C$15,"C","D")))) -> C | L10: =IF(H10="","",IF(I10="Y","Not Recommended – Knock-out",IF(COUNT(E10:G10)<3,"Interim – rounds pending ("&INDEX(Rating_Scale!$D$13:$D$16,MATCH(K10,Rating_Scale!$B$13:$B$16,0))&")",INDEX(Rating_Scale!$D$13:$D$16,MATCH(K10,Rating_Scale!$B$13:$B$16,0))))) -> Not Recommended – Knock-out
A11: 4 | B11: Candidate D (example) | C11: Planning Engineer | D11: 24-Sep-2026 | E11: 0.7 | F11: 0.76 | H11: =IF(COUNT(E11:G11)=0,"",(IF(E11="",0,E11*Rating_Scale!$C$26)+IF(F11="",0,F11*Rating_Scale!$C$27)+IF(G11="",0,G11*Rating_Scale!$C$28))/(IF(E11="",0,Rating_Scale!$C$26)+IF(F11="",0,Rating_Scale!$C$27)+IF(G11="",0,Rating_Scale!$C$28))) -> 0.74285714 | I11: N | J11: =IF(OR(H11="",C11=""),"",COUNTIFS($C$8:$C$57,C11,$H$8:$H$57,">"&H11)+1) -> 1 | K11: =IF(H11="","",IF(H11>=Rating_Scale!$C$13,"A",IF(H11>=Rating_Scale!$C$14,"B",IF(H11>=Rating_Scale!$C$15,"C","D")))) -> C | L11: =IF(H11="","",IF(I11="Y","Not Recommended – Knock-out",IF(COUNT(E11:G11)<3,"Interim – rounds pending ("&INDEX(Rating_Scale!$D$13:$D$16,MATCH(K11,Rating_Scale!$B$13:$B$16,0))&")",INDEX(Rating_Scale!$D$13:$D$16,MATCH(K11,Rating_Scale!$B$13:$B$16,0))))) -> Interim – rounds pending (Hold / Consider for lower grade)
A12: 5 | H12: =IF(COUNT(E12:G12)=0,"",(IF(E12="",0,E12*Rating_Scale!$C$26)+IF(F12="",0,F12*Rating_Scale!$C$27)+IF(G12="",0,G12*Rating_Scale!$C$28))/(IF(E12="",0,Rating_Scale!$C$26)+IF(F12="",0,Rating_Scale!$C$27)+IF(G12="",0,Rating_Scale!$C$28))) | J12: =IF(OR(H12="",C12=""),"",COUNTIFS($C$8:$C$57,C12,$H$8:$H$57,">"&H12)+1) | K12: =IF(H12="","",IF(H12>=Rating_Scale!$C$13,"A",IF(H12>=Rating_Scale!$C$14,"B",IF(H12>=Rating_Scale!$C$15,"C","D")))) | L12: =IF(H12="","",IF(I12="Y","Not Recommended – Knock-out",IF(COUNT(E12:G12)<3,"Interim – rounds pending ("&INDEX(Rating_Scale!$D$13:$D$16,MATCH(K12,Rating_Scale!$B$13:$B$16,0))&")",INDEX(Rating_Scale!$D$13:$D$16,MATCH(K12,Rating_Scale!$B$13:$B$16,0)))))
A13: 6 | H13: =IF(COUNT(E13:G13)=0,"",(IF(E13="",0,E13*Rating_Scale!$C$26)+IF(F13="",0,F13*Rating_Scale!$C$27)+IF(G13="",0,G13*Rating_Scale!$C$28))/(IF(E13="",0,Rating_Scale!$C$26)+IF(F13="",0,Rating_Scale!$C$27)+IF(G13="",0,Rating_Scale!$C$28))) | J13: =IF(OR(H13="",C13=""),"",COUNTIFS($C$8:$C$57,C13,$H$8:$H$57,">"&H13)+1) | K13: =IF(H13="","",IF(H13>=Rating_Scale!$C$13,"A",IF(H13>=Rating_Scale!$C$14,"B",IF(H13>=Rating_Scale!$C$15,"C","D")))) | L13: =IF(H13="","",IF(I13="Y","Not Recommended – Knock-out",IF(COUNT(E13:G13)<3,"Interim – rounds pending ("&INDEX(Rating_Scale!$D$13:$D$16,MATCH(K13,Rating_Scale!$B$13:$B$16,0))&")",INDEX(Rating_Scale!$D$13:$D$16,MATCH(K13,Rating_Scale!$B$13:$B$16,0)))))
A14: 7 | H14: =IF(COUNT(E14:G14)=0,"",(IF(E14="",0,E14*Rating_Scale!$C$26)+IF(F14="",0,F14*Rating_Scale!$C$27)+IF(G14="",0,G14*Rating_Scale!$C$28))/(IF(E14="",0,Rating_Scale!$C$26)+IF(F14="",0,Rating_Scale!$C$27)+IF(G14="",0,Rating_Scale!$C$28))) | J14: =IF(OR(H14="",C14=""),"",COUNTIFS($C$8:$C$57,C14,$H$8:$H$57,">"&H14)+1) | K14: =IF(H14="","",IF(H14>=Rating_Scale!$C$13,"A",IF(H14>=Rating_Scale!$C$14,"B",IF(H14>=Rating_Scale!$C$15,"C","D")))) | L14: =IF(H14="","",IF(I14="Y","Not Recommended – Knock-out",IF(COUNT(E14:G14)<3,"Interim – rounds pending ("&INDEX(Rating_Scale!$D$13:$D$16,MATCH(K14,Rating_Scale!$B$13:$B$16,0))&")",INDEX(Rating_Scale!$D$13:$D$16,MATCH(K14,Rating_Scale!$B$13:$B$16,0)))))
A15: 8 | H15: =IF(COUNT(E15:G15)=0,"",(IF(E15="",0,E15*Rating_Scale!$C$26)+IF(F15="",0,F15*Rating_Scale!$C$27)+IF(G15="",0,G15*Rating_Scale!$C$28))/(IF(E15="",0,Rating_Scale!$C$26)+IF(F15="",0,Rating_Scale!$C$27)+IF(G15="",0,Rating_Scale!$C$28))) | J15: =IF(OR(H15="",C15=""),"",COUNTIFS($C$8:$C$57,C15,$H$8:$H$57,">"&H15)+1) | K15: =IF(H15="","",IF(H15>=Rating_Scale!$C$13,"A",IF(H15>=Rating_Scale!$C$14,"B",IF(H15>=Rating_Scale!$C$15,"C","D")))) | L15: =IF(H15="","",IF(I15="Y","Not Recommended – Knock-out",IF(COUNT(E15:G15)<3,"Interim – rounds pending ("&INDEX(Rating_Scale!$D$13:$D$16,MATCH(K15,Rating_Scale!$B$13:$B$16,0))&")",INDEX(Rating_Scale!$D$13:$D$16,MATCH(K15,Rating_Scale!$B$13:$B$16,0)))))
A16: 9 | H16: =IF(COUNT(E16:G16)=0,"",(IF(E16="",0,E16*Rating_Scale!$C$26)+IF(F16="",0,F16*Rating_Scale!$C$27)+IF(G16="",0,G16*Rating_Scale!$C$28))/(IF(E16="",0,Rating_Scale!$C$26)+IF(F16="",0,Rating_Scale!$C$27)+IF(G16="",0,Rating_Scale!$C$28))) | J16: =IF(OR(H16="",C16=""),"",COUNTIFS($C$8:$C$57,C16,$H$8:$H$57,">"&H16)+1) | K16: =IF(H16="","",IF(H16>=Rating_Scale!$C$13,"A",IF(H16>=Rating_Scale!$C$14,"B",IF(H16>=Rating_Scale!$C$15,"C","D")))) | L16: =IF(H16="","",IF(I16="Y","Not Recommended – Knock-out",IF(COUNT(E16:G16)<3,"Interim – rounds pending ("&INDEX(Rating_Scale!$D$13:$D$16,MATCH(K16,Rating_Scale!$B$13:$B$16,0))&")",INDEX(Rating_Scale!$D$13:$D$16,MATCH(K16,Rating_Scale!$B$13:$B$16,0)))))
A17: 10 | H17: =IF(COUNT(E17:G17)=0,"",(IF(E17="",0,E17*Rating_Scale!$C$26)+IF(F17="",0,F17*Rating_Scale!$C$27)+IF(G17="",0,G17*Rating_Scale!$C$28))/(IF(E17="",0,Rating_Scale!$C$26)+IF(F17="",0,Rating_Scale!$C$27)+IF(G17="",0,Rating_Scale!$C$28))) | J17: =IF(OR(H17="",C17=""),"",COUNTIFS($C$8:$C$57,C17,$H$8:$H$57,">"&H17)+1) | K17: =IF(H17="","",IF(H17>=Rating_Scale!$C$13,"A",IF(H17>=Rating_Scale!$C$14,"B",IF(H17>=Rating_Scale!$C$15,"C","D")))) | L17: =IF(H17="","",IF(I17="Y","Not Recommended – Knock-out",IF(COUNT(E17:G17)<3,"Interim – rounds pending ("&INDEX(Rating_Scale!$D$13:$D$16,MATCH(K17,Rating_Scale!$B$13:$B$16,0))&")",INDEX(Rating_Scale!$D$13:$D$16,MATCH(K17,Rating_Scale!$B$13:$B$16,0)))))
A18: 11 | H18: =IF(COUNT(E18:G18)=0,"",(IF(E18="",0,E18*Rating_Scale!$C$26)+IF(F18="",0,F18*Rating_Scale!$C$27)+IF(G18="",0,G18*Rating_Scale!$C$28))/(IF(E18="",0,Rating_Scale!$C$26)+IF(F18="",0,Rating_Scale!$C$27)+IF(G18="",0,Rating_Scale!$C$28))) | J18: =IF(OR(H18="",C18=""),"",COUNTIFS($C$8:$C$57,C18,$H$8:$H$57,">"&H18)+1) | K18: =IF(H18="","",IF(H18>=Rating_Scale!$C$13,"A",IF(H18>=Rating_Scale!$C$14,"B",IF(H18>=Rating_Scale!$C$15,"C","D")))) | L18: =IF(H18="","",IF(I18="Y","Not Recommended – Knock-out",IF(COUNT(E18:G18)<3,"Interim – rounds pending ("&INDEX(Rating_Scale!$D$13:$D$16,MATCH(K18,Rating_Scale!$B$13:$B$16,0))&")",INDEX(Rating_Scale!$D$13:$D$16,MATCH(K18,Rating_Scale!$B$13:$B$16,0)))))
A19: 12 | H19: =IF(COUNT(E19:G19)=0,"",(IF(E19="",0,E19*Rating_Scale!$C$26)+IF(F19="",0,F19*Rating_Scale!$C$27)+IF(G19="",0,G19*Rating_Scale!$C$28))/(IF(E19="",0,Rating_Scale!$C$26)+IF(F19="",0,Rating_Scale!$C$27)+IF(G19="",0,Rating_Scale!$C$28))) | J19: =IF(OR(H19="",C19=""),"",COUNTIFS($C$8:$C$57,C19,$H$8:$H$57,">"&H19)+1) | K19: =IF(H19="","",IF(H19>=Rating_Scale!$C$13,"A",IF(H19>=Rating_Scale!$C$14,"B",IF(H19>=Rating_Scale!$C$15,"C","D")))) | L19: =IF(H19="","",IF(I19="Y","Not Recommended – Knock-out",IF(COUNT(E19:G19)<3,"Interim – rounds pending ("&INDEX(Rating_Scale!$D$13:$D$16,MATCH(K19,Rating_Scale!$B$13:$B$16,0))&")",INDEX(Rating_Scale!$D$13:$D$16,MATCH(K19,Rating_Scale!$B$13:$B$16,0)))))
A20: 13 | H20: =IF(COUNT(E20:G20)=0,"",(IF(E20="",0,E20*Rating_Scale!$C$26)+IF(F20="",0,F20*Rating_Scale!$C$27)+IF(G20="",0,G20*Rating_Scale!$C$28))/(IF(E20="",0,Rating_Scale!$C$26)+IF(F20="",0,Rating_Scale!$C$27)+IF(G20="",0,Rating_Scale!$C$28))) | J20: =IF(OR(H20="",C20=""),"",COUNTIFS($C$8:$C$57,C20,$H$8:$H$57,">"&H20)+1) | K20: =IF(H20="","",IF(H20>=Rating_Scale!$C$13,"A",IF(H20>=Rating_Scale!$C$14,"B",IF(H20>=Rating_Scale!$C$15,"C","D")))) | L20: =IF(H20="","",IF(I20="Y","Not Recommended – Knock-out",IF(COUNT(E20:G20)<3,"Interim – rounds pending ("&INDEX(Rating_Scale!$D$13:$D$16,MATCH(K20,Rating_Scale!$B$13:$B$16,0))&")",INDEX(Rating_Scale!$D$13:$D$16,MATCH(K20,Rating_Scale!$B$13:$B$16,0)))))
A21: 14 | H21: =IF(COUNT(E21:G21)=0,"",(IF(E21="",0,E21*Rating_Scale!$C$26)+IF(F21="",0,F21*Rating_Scale!$C$27)+IF(G21="",0,G21*Rating_Scale!$C$28))/(IF(E21="",0,Rating_Scale!$C$26)+IF(F21="",0,Rating_Scale!$C$27)+IF(G21="",0,Rating_Scale!$C$28))) | J21: =IF(OR(H21="",C21=""),"",COUNTIFS($C$8:$C$57,C21,$H$8:$H$57,">"&H21)+1) | K21: =IF(H21="","",IF(H21>=Rating_Scale!$C$13,"A",IF(H21>=Rating_Scale!$C$14,"B",IF(H21>=Rating_Scale!$C$15,"C","D")))) | L21: =IF(H21="","",IF(I21="Y","Not Recommended – Knock-out",IF(COUNT(E21:G21)<3,"Interim – rounds pending ("&INDEX(Rating_Scale!$D$13:$D$16,MATCH(K21,Rating_Scale!$B$13:$B$16,0))&")",INDEX(Rating_Scale!$D$13:$D$16,MATCH(K21,Rating_Scale!$B$13:$B$16,0)))))
A22: 15 | H22: =IF(COUNT(E22:G22)=0,"",(IF(E22="",0,E22*Rating_Scale!$C$26)+IF(F22="",0,F22*Rating_Scale!$C$27)+IF(G22="",0,G22*Rating_Scale!$C$28))/(IF(E22="",0,Rating_Scale!$C$26)+IF(F22="",0,Rating_Scale!$C$27)+IF(G22="",0,Rating_Scale!$C$28))) | J22: =IF(OR(H22="",C22=""),"",COUNTIFS($C$8:$C$57,C22,$H$8:$H$57,">"&H22)+1) | K22: =IF(H22="","",IF(H22>=Rating_Scale!$C$13,"A",IF(H22>=Rating_Scale!$C$14,"B",IF(H22>=Rating_Scale!$C$15,"C","D")))) | L22: =IF(H22="","",IF(I22="Y","Not Recommended – Knock-out",IF(COUNT(E22:G22)<3,"Interim – rounds pending ("&INDEX(Rating_Scale!$D$13:$D$16,MATCH(K22,Rating_Scale!$B$13:$B$16,0))&")",INDEX(Rating_Scale!$D$13:$D$16,MATCH(K22,Rating_Scale!$B$13:$B$16,0)))))
A23: 16 | H23: =IF(COUNT(E23:G23)=0,"",(IF(E23="",0,E23*Rating_Scale!$C$26)+IF(F23="",0,F23*Rating_Scale!$C$27)+IF(G23="",0,G23*Rating_Scale!$C$28))/(IF(E23="",0,Rating_Scale!$C$26)+IF(F23="",0,Rating_Scale!$C$27)+IF(G23="",0,Rating_Scale!$C$28))) | J23: =IF(OR(H23="",C23=""),"",COUNTIFS($C$8:$C$57,C23,$H$8:$H$57,">"&H23)+1) | K23: =IF(H23="","",IF(H23>=Rating_Scale!$C$13,"A",IF(H23>=Rating_Scale!$C$14,"B",IF(H23>=Rating_Scale!$C$15,"C","D")))) | L23: =IF(H23="","",IF(I23="Y","Not Recommended – Knock-out",IF(COUNT(E23:G23)<3,"Interim – rounds pending ("&INDEX(Rating_Scale!$D$13:$D$16,MATCH(K23,Rating_Scale!$B$13:$B$16,0))&")",INDEX(Rating_Scale!$D$13:$D$16,MATCH(K23,Rating_Scale!$B$13:$B$16,0)))))
... A57: 50 | H57: =IF(COUNT(E57:G57)=0,"",(IF(E57="",0,E57*Rating_Scale!$C$26)+IF(F57="",0,F57*Rating_Scale!$C$27)+IF(G57="",0,G57*Rating_Scale!$C$28))/(IF(E57="",0,Rating_Scale!$C$26)+IF(F57="",0,Rating_Scale!$C$27)+IF(G57="",0,Rating_Scale!$C$28))) | J57: =IF(OR(H57="",C57=""),"",COUNTIFS($C$8:$C$57,C57,$H$8:$H$57,">"&H57)+1) | K57: =IF(H57="","",IF(H57>=Rating_Scale!$C$13,"A",IF(H57>=Rating_Scale!$C$14,"B",IF(H57>=Rating_Scale!$C$15,"C","D")))) | L57: =IF(H57="","",IF(I57="Y","Not Recommended – Knock-out",IF(COUNT(E57:G57)<3,"Interim – rounds pending ("&INDEX(Rating_Scale!$D$13:$D$16,MATCH(K57,Rating_Scale!$B$13:$B$16,0))&")",INDEX(Rating_Scale!$D$13:$D$16,MATCH(K57,Rating_Scale!$B$13:$B$16,0)))))
